Workbook

Sheet dlr-shepard-shepard_arcan_combi
A1: model | B1: strategy | C1: encoding | D1: cv_folds | E1: accuracy_mean | F1: accuracy_std | G1: precision_mean | H1: precision_std | I1: recall_mean | J1: recall_std | K1: f1_mean | L1: f1_std | M1: positive_smell_recall_mean | N1: positive_smell_recall_std | O1: top_1_positive_count_mean | P1: top_1_positive_count_std | Q1: top_5_positive_count_mean | R1: top_5_positive_count_std | S1: top_10_positive_count_mean | T1: top_10_positive_count_std | U1: recall
A2: logistic_regression | B2: none | C2: openai | D2: 7 | E2: 0.69027611 | F2: 0.059576483 | G2: 0.64494644 | H2: 0.071637431 | I2: 0.64761905 | J2: 0.077371794 | K2: 0.64439939 | L2: 0.066875316 | M2: 0.64761905 | N2: 0.077371794 | O2: 9.7142857 | P2: 1.1605769 | Q2: 15 | R2: 0 | S2: 15 | T2: 0 | U2: 0.64761905
A3: logistic_regression | B3: class_weight | C3: openai | D3: 7 | E3: 0.69447779 | F3: 0.063510508 | G3: 0.64722525 | H3: 0.075229533 | I3: 0.66666667 | J3: 0.079681907 | K3: 0.6543156 | L3: 0.068583518 | M3: 0.66666667 | N3: 0.079681907 | O3: 10 | P3: 1.1952286 | Q3: 15 | R3: 0 | S3: 15 | T3: 0 | U3: 0.66666667
A4: logistic_regression | B4: random_undersample | C4: openai | D4: 7 | E4: 0.69855942 | F4: 0.049288448 | G4: 0.64630468 | H4: 0.073765641 | I4: 0.7047619 | J4: 0.048562091 | K4: 0.6711039 | L4: 0.04199696 | M4: 0.7047619 | N4: 0.048562091 | O4: 10.571429 | P4: 0.72843136 | Q4: 15 | R4: 0 | S4: 15 | T4: 0 | U4: 0.7047619
A5: random_forest | B5: none | C5: openai | D5: 7 | E5: 0.71152461 | F5: 0.06608379 | G5: 0.71568432 | H5: 0.087277259 | I5: 0.54285714 | J5: 0.10942024 | K5: 0.61612768 | L5: 0.10180905 | M5: 0.54285714 | N5: 0.10942024 | O5: 8.1428571 | P5: 1.6413036 | Q5: 15 | R5: 0 | S5: 15 | T5: 0 | U5: 0.54285714
A6: random_forest | B6: class_weight | C6: openai | D6: 7 | E6: 0.70732293 | F6: 0.059428741 | G6: 0.71123876 | H6: 0.086512804 | I6: 0.54285714 | J6: 0.09035079 | K6: 0.6144741 | L6: 0.087515194 | M6: 0.54285714 | N6: 0.09035079 | O6: 8.1428571 | P6: 1.3552619 | Q6: 15 | R6: 0 | S6: 15 | T6: 0 | U6: 0.54285714
A7: random_forest | B7: random_undersample | C7: openai | D7: 7 | E7: 0.7120048 | F7: 0.10049331 | G7: 0.66163658 | H7: 0.11884157 | I7: 0.67619048 | J7: 0.15707069 | K7: 0.66574652 | L7: 0.12975784 | M7: 0.67619048 | N7: 0.15707069 | O7: 10.142857 | P7: 2.3560604 | Q7: 15 | R7: 0 | S7: 15 | T7: 0 | U7: 0.67619048
A8: knn | B8: none | C8: openai | D8: 7 | E8: 0.67815126 | F8: 0.06012117 | G8: 0.62158386 | H8: 0.076466534 | I8: 0.68571429 | J8: 0.092336759 | K8: 0.64819526 | L8: 0.065936786 | M8: 0.68571429 | N8: 0.092336759 | O8: 10.285714 | P8: 1.3850514 | Q8: 15 | R8: 0 | S8: 15 | T8: 0 | U8: 0.68571429
A9: knn | B9: class_weight | C9: openai | D9: 7 | E9: 0.67815126 | F9: 0.06012117 | G9: 0.62158386 | H9: 0.076466534 | I9: 0.68571429 | J9: 0.092336759 | K9: 0.64819526 | L9: 0.065936786 | M9: 0.68571429 | N9: 0.092336759 | O9: 10.285714 | P9: 1.3850514 | Q9: 15 | R9: 0 | S9: 15 | T9: 0 | U9: 0.68571429
A10: knn | B10: random_undersample | C10: openai | D10: 7 | E10: 0.66158463 | F10: 0.069238677 | G10: 0.58487668 | H10: 0.06347264 | I10: 0.77142857 | J10: 0.1227057 | K10: 0.66187795 | L10: 0.075122148 | M10: 0.77142857 | N10: 0.1227057 | O10: 11.571429 | P10: 1.8405855 | Q10: 15 | R10: 0 | S10: 15 | T10: 0 | U10: 0.77142857
A11: naive_bayes | B11: none | C11: openai | D11: 7 | E11: 0.72004802 | F11: 0.08077528 | G11: 0.6879993 | H11: 0.11168146 | I11: 0.65714286 | J11: 0.10942024 | K11: 0.66953537 | L11: 0.098123482 | M11: 0.65714286 | N11: 0.10942024 | O11: 9.8571429 | P11: 1.6413036 | Q11: 15 | R11: 0 | S11: 15 | T11: 0 | U11: 0.65714286
A12: naive_bayes | B12: class_weight | C12: openai | D12: 7 | E12: 0.72004802 | F12: 0.08077528 | G12: 0.6879993 | H12: 0.11168146 | I12: 0.65714286 | J12: 0.10942024 | K12: 0.66953537 | L12: 0.098123482 | M12: 0.65714286 | N12: 0.10942024 | O12: 9.8571429 | P12: 1.6413036 | Q12: 15 | R12: 0 | S12: 15 | T12: 0 | U12: 0.65714286
A13: naive_bayes | B13: random_undersample | C13: openai | D13: 7 | E13: 0.69555822 | F13: 0.10538069 | G13: 0.65187716 | H13: 0.13126004 | I13: 0.64761905 | J13: 0.13196578 | K13: 0.64745911 | L13: 0.12425267 | M13: 0.64761905 | N13: 0.13196578 | O13: 9.7142857 | P13: 1.9794866 | Q13: 15 | R13: 0 | S13: 15 | T13: 0 | U13: 0.64761905
... A61: naive_bayes | B61: random_undersample | C61: sbert_tfidf_weighted | D61: 7 | E61: 0.66662665 | F61: 0.10169279 | G61: 0.59495465 | H61: 0.10443252 | I61: 0.68571429 | J61: 0.15822141 | K61: 0.6356489 | L61: 0.12769264 | M61: 0.68571429 | N61: 0.15822141 | O61: 10.285714 | P61: 2.3733211 | Q61: 15 | R61: 0 | S61: 15 | T61: 0 | U61: 0.68571429

Sheet ongresinc-stackgres_arcan_combi
A1: model | B1: strategy | C1: encoding | D1: cv_folds | E1: accuracy_mean | F1: accuracy_std | G1: precision_mean | H1: precision_std | I1: recall_mean | J1: recall_std | K1: f1_mean | L1: f1_std | M1: positive_smell_recall_mean | N1: positive_smell_recall_std | O1: top_1_positive_count_mean | P1: top_1_positive_count_std | Q1: top_5_positive_count_mean | R1: top_5_positive_count_std | S1: top_10_positive_count_mean | T1: top_10_positive_count_std | U1: recall
A2: random_forest | B2: random_undersample | C2: openai | D2: 7 | E2: 0.75045208 | F2: 0.043961106 | G2: 0.63550174 | H2: 0.053936852 | I2: 0.81331719 | J2: 0.024945931 | K2: 0.71266267 | L2: 0.040888652 | M2: 0.81331719 | N2: 0.024945931 | O2: 48.571429 | P2: 1.6781914 | Q2: 59.714286 | R2: 0.45175395 | S2: 59.714286 | T2: 0.45175395 | U2: 0.81331719
A3: naive_bayes | B3: random_undersample | C3: tfidf | D3: 7 | E3: 0.72423146 | F3: 0.038699701 | G3: 0.59665296 | H3: 0.037473954 | I3: 0.8491929 | J3: 0.028721001 | K3: 0.70030631 | L3: 0.032167423 | M3: 0.8491929 | N3: 0.028721001 | O3: 50.714286 | P3: 1.905952 | Q3: 59.714286 | R3: 0.45175395 | S3: 59.714286 | T3: 0.45175395 | U3: 0.8491929
A4: naive_bayes | B4: random_undersample | C4: openai | D4: 7 | E4: 0.72694394 | F4: 0.032700075 | G4: 0.60473914 | H4: 0.035317499 | I4: 0.80855529 | J4: 0.029752047 | K4: 0.69165675 | L4: 0.03182398 | M4: 0.80855529 | N4: 0.029752047 | O4: 48.285714 | P4: 1.905952 | Q4: 59.714286 | R4: 0.45175395 | S4: 59.714286 | T4: 0.45175395 | U4: 0.80855529
A5: knn | B5: random_undersample | C5: openai | D5: 7 | E5: 0.71338156 | F5: 0.031503167 | G5: 0.58750513 | H5: 0.036151984 | I5: 0.83014528 | J5: 0.029152493 | K5: 0.68711148 | L5: 0.024706712 | M5: 0.83014528 | N5: 0.029152493 | O5: 49.571429 | P5: 1.7612611 | Q5: 59.714286 | R5: 0.45175395 | S5: 59.714286 | T5: 0.45175395 | U5: 0.83014528
A6: naive_bayes | B6: none | C6: openai | D6: 7 | E6: 0.7278481 | F6: 0.03674937 | G6: 0.60912082 | H6: 0.039064307 | I6: 0.78696529 | J6: 0.047560668 | K6: 0.68629838 | L6: 0.039508374 | M6: 0.78696529 | N6: 0.047560668 | O6: 47 | P6: 2.9760952 | Q6: 59.714286 | R6: 0.45175395 | S6: 59.714286 | T6: 0.45175395 | U6: 0.78696529
A7: naive_bayes | B7: class_weight | C7: openai | D7: 7 | E7: 0.7278481 | F7: 0.03674937 | G7: 0.60912082 | H7: 0.039064307 | I7: 0.78696529 | J7: 0.047560668 | K7: 0.68629838 | L7: 0.039508374 | M7: 0.78696529 | N7: 0.047560668 | O7: 47 | P7: 2.9760952 | Q7: 59.714286 | R7: 0.45175395 | S7: 59.714286 | T7: 0.45175395 | U7: 0.78696529
A8: logistic_regression | B8: random_undersample | C8: tfidf | D8: 7 | E8: 0.7124774 | F8: 0.030042039 | G8: 0.59252935 | H8: 0.034100586 | I8: 0.77514124 | J8: 0.029145174 | K8: 0.67124167 | L8: 0.028749598 | M8: 0.77514124 | N8: 0.029145174 | O8: 46.285714 | P8: 1.7496355 | Q8: 59.714286 | R8: 0.45175395 | S8: 59.714286 | T8: 0.45175395 | U8: 0.77514124
A9: random_forest | B9: random_undersample | C9: sbert_max | D9: 7 | E9: 0.71518987 | F9: 0.052736588 | G9: 0.59917661 | H9: 0.057426236 | I9: 0.76315577 | J9: 0.050596154 | K9: 0.67060893 | L9: 0.052850168 | M9: 0.76315577 | N9: 0.050596154 | O9: 45.571429 | P9: 3.0169589 | Q9: 59.714286 | R9: 0.45175395 | S9: 59.714286 | T9: 0.45175395 | U9: 0.76315577
A10: random_forest | B10: random_undersample | C10: sbert_avg | D10: 7 | E10: 0.70886076 | F10: 0.055486206 | G10: 0.59243924 | H10: 0.061046198 | I10: 0.75613398 | J10: 0.052481092 | K10: 0.66375708 | L10: 0.055948355 | M10: 0.75613398 | N10: 0.052481092 | O10: 45.142857 | P10: 2.9965967 | Q10: 59.714286 | R10: 0.45175395 | S10: 59.714286 | T10: 0.45175395 | U10: 0.75613398
A11: random_forest | B11: random_undersample | C11: sbert_tfidf_weighted | D11: 7 | E11: 0.70433996 | F11: 0.050146201 | G11: 0.58535227 | H11: 0.053219499 | I11: 0.76085553 | J11: 0.052732491 | K11: 0.66125761 | L11: 0.052029767 | M11: 0.76085553 | N11: 0.052732491 | O11: 45.428571 | P11: 3.0639444 | Q11: 59.714286 | R11: 0.45175395 | S11: 59.714286 | T11: 0.45175395 | U11: 0.76085553
A12: logistic_regression | B12: random_undersample | C12: openai | D12: 7 | E12: 0.70614828 | F12: 0.035619739 | G12: 0.59025859 | H12: 0.040387682 | I12: 0.7389427 | J12: 0.057164228 | K12: 0.65516968 | L12: 0.039336664 | M12: 0.7389427 | N12: 0.057164228 | O12: 44.142857 | P12: 3.6421568 | Q12: 59.714286 | R12: 0.45175395 | S12: 59.714286 | T12: 0.45175395 | U12: 0.7389427
A13: naive_bayes | B13: none | C13: tfidf | D13: 7 | E13: 0.75497288 | F13: 0.026791198 | G13: 0.70309246 | H13: 0.046068596 | I13: 0.6122276 | J13: 0.041411674 | K13: 0.65368818 | L13: 0.037053951 | M13: 0.6122276 | N13: 0.041411674 | O13: 36.571429 | P13: 2.6649654 | Q13: 59.714286 | R13: 0.45175395 | S13: 59.714286 | T13: 0.45175395 | U13: 0.6122276
... A61: random_forest | B61: none | C61: tfidf | D61: 7 | E61: 0.65099458 | F61: 0.022802026 | G61: 0.65132278 | H61: 0.11062201 | I61: 0.16020985 | J61: 0.056792695 | K61: 0.25390065 | L61: 0.0771089 | M61: 0.16020985 | N61: 0.056792695 | O61: 9.5714286 | P61: 3.4166459 | Q61: 59.714286 | R61: 0.45175395 | S61: 59.714286 | T61: 0.45175395 | U61: 0.16020985

Sheet Average
A1: model | B1: strategy | C1: encoding | D1: cv_folds | E1: accuracy_mean | F1: accuracy_std | G1: precision_mean | H1: precision_std | I1: recall_mean | J1: recall_std | K1: f1_mean | L1: f1_std | M1: positive_smell_recall_mean | N1: positive_smell_recall_std | O1: top_1_positive_count_mean | P1: top_1_positive_count_std | Q1: top_5_positive_count_mean | R1: top_5_positive_count_std | S1: top_10_positive_count_mean | T1: top_10_positive_count_std | U1: recall
A2: feedforward_nn | B2: random_undersample | C2: openai | D2: 7 | E2: =IF( AND(SUMIFS('dlr-shepard-shepard_arcan_combi'!E:E, 'dlr-shepard-shepard_arcan_combi'!$A:$A, $A2, 'dlr-shepard-shepard_arcan_combi'!$B:$B, $B2, 'dlr-shepard-shepard_arcan_combi'!$C:$C, $C2), SUMIFS('ongresinc-stackgres_arcan_combi'!E:E, 'ongresinc-stackgres_arcan_combi'!$A:$A, $A2, 'ongresinc-stackgres_arcan_combi'!$B:$B, $B2, 'ongresinc-stackgres_arcan_combi'!$C:$C, $C2)), AVERAGE( SUMIFS('dlr-shepard-shepard_arcan_combi'!E:E, 'dlr-shepard-shepard_arcan_combi'!$A:$A, $A2, 'dlr-shepard-shepard_arcan_combi'!$B:$B, $B2, 'dlr-shepard-shepard_arcan_combi'!$C:$C, $C2), SUMIFS('ongresinc-stackgres_arcan_combi'!E:E, 'ongresinc-stackgres_arcan_combi'!$A:$A, $A2, 'ongresinc-stackgres_arcan_combi'!$B:$B, $B2, 'ongresinc-stackgres_arcan_combi'!$C:$C, $C2)), "") | F2: =IF( AND(SUMIFS('dlr-shepard-shepard_arcan_combi'!F:F, 'dlr-shepard-shepard_arcan_combi'!$A:$A, $A2, 'dlr-shepard-shepard_arcan_combi'!$B:$B, $B2, 'dlr-shepard-shepard_arcan_combi'!$C:$C, $C2), SUMIFS('ongresinc-stackgres_arcan_combi'!F:F, 'ongresinc-stackgres_arcan_combi'!$A:$A, $A2, 'ongresinc-stackgres_arcan_combi'!$B:$B, $B2, 'ongresinc-stackgres_arcan_combi'!$C:$C, $C2)), AVERAGE( SUMIFS('dlr-shepard-shepard_arcan_combi'!F:F, 'dlr-shepard-shepard_arcan_combi'!$A:$A, $A2, 'dlr-shepard-shepard_arcan_combi'!$B:$B, $B2, 'dlr-shepard-shepard_arcan_combi'!$C:$C, $C2), SUMIFS('ongresinc-stackgres_arcan_combi'!F:F, 'ongresinc-stackgres_arcan_combi'!$A:$A, $A2, 'ongresinc-stackgres_arcan_combi'!$B:$B, $B2, 'ongresinc-stackgres_arcan_combi'!$C:$C, $C2)), "") | G2: =IF( AND(SUMIFS('dlr-shepard-shepard_arcan_combi'!G:G, 'dlr-shepard-shepard_arcan_combi'!$A:$A, $A2, 'dlr-shepard-shepard_arcan_combi'!$B:$B, $B2, 'dlr-shepard-shepard_arcan_combi'!$C:$C, $C2), SUMIFS('ongresinc-stackgres_arcan_combi'!G:G, 'ongresinc-stackgres_arcan_combi'!$A:$A, $A2, 'ongresinc-stackgres_arcan_combi'!$B:$B, $B2, 'ongresinc-stackgres_arcan_combi'!$C:$C, $C2)), AVERAGE( SUMIFS('dlr-shepard-shepard_arcan_combi'!G:G, 'dlr-shepard-shepard_arcan_combi'!$A:$A, $A2, 'dlr-shepard-shepard_arcan_combi'!$B:$B, $B2, 'dlr-shepard-shepard_arcan_combi'!$C:$C, $C2), SUMIFS('ongresinc-stackgres_arcan_combi'!G:G, 'ongresinc-stackgres_arcan_combi'!$A:$A, $A2, 'ongresinc-stackgres_arcan_combi'!$B:$B, $B2, 'ongresinc-stackgres_arcan_combi'!$C:$C, $C2)), "") | H2: =IF( AND(SUMIFS('dlr-shepard-shepard_arcan_combi'!H:H, 'dlr-shepard-shepard_arcan_combi'!$A:$A, $A2, 'dlr-shepard-shepard_arcan_combi'!$B:$B, $B2, 'dlr-shepard-shepard_arcan_combi'!$C:$C, $C2), SUMIFS('ongresinc-stackgres_arcan_combi'!H:H, 'ongresinc-stackgres_arcan_combi'!$A:$A, $A2, 'ongresinc-stackgres_arcan_combi'!$B:$B, $B2, 'ongresinc-stackgres_arcan_combi'!$C:$C, $C2)), AVERAGE( SUMIFS('dlr-shepard-shepard_arcan_combi'!H:H, 'dlr-shepard-shepard_arcan_combi'!$A:$A, $A2, 'dlr-shepard-shepard_arcan_combi'!$B:$B, $B2, 'dlr-shepard-shepard_arcan_combi'!$C:$C, $C2), SUMIFS('ongresinc-stackgres_arcan_combi'!H:H, 'ongresinc-stackgres_arcan_combi'!$A:$A, $A2, 'ongresinc-stackgres_arcan_combi'!$B:$B, $B2, 'ongresinc-stackgres_arcan_combi'!$C:$C, $C2)), "") | I2: =IF( AND(SUMIFS('dlr-shepard-shepard_arcan_combi'!I:I, 'dlr-shepard-shepard_arcan_combi'!$A:$A, $A2, 'dlr-shepard-shepard_arcan_combi'!$B:$B, $B2, 'dlr-shepard-shepard_arcan_combi'!$C:$C, $C2), SUMIFS('ongresinc-stackgres_arcan_combi'!I:I, 'ongresinc-stackgres_arcan_combi'!$A:$A, $A2, 'ongresinc-stackgres_arcan_combi'!$B:$B, $B2, 'ongresinc-stackgres_arcan_combi'!$C:$C, $C2)), AVERAGE( SUMIFS('dlr-shepard-shepard_arcan_combi'!I:I, 'dlr-shepard-shepard_arcan_combi'!$A:$A, $A2, 'dlr-shepard-shepard_arcan_combi'!$B:$B, $B2, 'dlr-shepard-shepard_arcan_combi'!$C:$C, $C2), SUMIFS('ongresinc-stackgres_arcan_combi'!I:I, 'ongresinc-stackgres_arcan_combi'!$A:$A, $A2, 'ongresinc-stackgres_arcan_combi'!$B:$B, $B2, 'ongresinc-stackgres_arcan_combi'!$C:$C, $C2)), "") | J2: =IF( AND(SUMIFS('dlr-shepard-shepard_arcan_combi'!J:J, 'dlr-shepard-shepard_arcan_combi'!$A:$A, $A2, 'dlr-shepard-shepard_arcan_combi'!$B:$B, $B2, 'dlr-shepard-shepard_arcan_combi'!$C:$C, $C2), SUMIFS('ongresinc-stackgres_arcan_combi'!J:J, 'ongresinc-stackgres_arcan_combi'!$A:$A, $A2, 'ongresinc-stackgres_arcan_combi'!$B:$B, $B2, 'ongresinc-stackgres_arcan_combi'!$C:$C, $C2)), AVERAGE( SUMIFS('dlr-shepard-shepard_arcan_combi'!J:J, 'dlr-shepard-shepard_arcan_combi'!$A:$A, $A2, 'dlr-shepard-shepard_arcan_combi'!$B:$B, $B2, 'dlr-shepard-shepard_arcan_combi'!$C:$C, $C2), SUMIFS('ongresinc-stackgres_arcan_combi'!J:J, 'ongresinc-stackgres_arcan_combi'!$A:$A, $A2, 'ongresinc-stackgres_arcan_combi'!$B:$B, $B2, 'ongresinc-stackgres_arcan_combi'!$C:$C, $C2)), "") | K2: =IF( AND(SUMIFS('dlr-shepard-shepard_arcan_combi'!K:K, 'dlr-shepard-shepard_arcan_combi'!$A:$A, $A2, 'dlr-shepard-shepard_arcan_combi'!$B:$B, $B2, 'dlr-shepard-shepard_arcan_combi'!$C:$C, $C2), SUMIFS('ongresinc-stackgres_arcan_combi'!K:K, 'ongresinc-stackgres_arcan_combi'!$A:$A, $A2, 'ongresinc-stackgres_arcan_combi'!$B:$B, $B2, 'ongresinc-stackgres_arcan_combi'!$C:$C, $C2)), AVERAGE( SUMIFS('dlr-shepard-shepard_arcan_combi'!K:K, 'dlr-shepard-shepard_arcan_combi'!$A:$A, $A2, 'dlr-shepard-shepard_arcan_combi'!$B:$B, $B2, 'dlr-shepard-shepard_arcan_combi'!$C:$C, $C2), SUMIFS('ongresinc-stackgres_arcan_combi'!K:K, 'ongresinc-stackgres_arcan_combi'!$A:$A, $A2, 'ongresinc-stackgres_arcan_combi'!$B:$B, $B2, 'ongresinc-stackgres_arcan_combi'!$C:$C, $C2)), "") | L2: =IF( AND(SUMIFS('dlr-shepard-shepard_arcan_combi'!L:L, 'dlr-shepard-shepard_arcan_combi'!$A:$A, $A2, 'dlr-shepard-shepard_arcan_combi'!$B:$B, $B2, 'dlr-shepard-shepard_arcan_combi'!$C:$C, $C2), SUMIFS('ongresinc-stackgres_arcan_combi'!L:L, 'ongresinc-stackgres_arcan_combi'!$A:$A, $A2, 'ongresinc-stackgres_arcan_combi'!$B:$B, $B2, 'ongresinc-stackgres_arcan_combi'!$C:$C, $C2)), AVERAGE( SUMIFS('dlr-shepard-shepard_arcan_combi'!L:L, 'dlr-shepard-shepard_arcan_combi'!$A:$A, $A2, 'dlr-shepard-shepard_arcan_combi'!$B:$B, $B2, 'dlr-shepard-shepard_arcan_combi'!$C:$C, $C2), SUMIFS('ongresinc-stackgres_arcan_combi'!L:L, 'ongresinc-stackgres_arcan_combi'!$A:$A, $A2, 'ongresinc-stackgres_arcan_combi'!$B:$B, $B2, 'ongresinc-stackgres_arcan_combi'!$C:$C, $C2)), "") | M2: =IF( AND(SUMIFS('dlr-shepard-shepard_arcan_combi'!M:M, 'dlr-shepard-shepard_arcan_combi'!$A:$A, $A2, 'dlr-shepard-shepard_arcan_combi'!$B:$B, $B2, 'dlr-shepard-shepard_arcan_combi'!$C:$C, $C2), SUMIFS('ongresinc-stackgres_arcan_combi'!M:M, 'ongresinc-stackgres_arcan_combi'!$A:$A, $A2, 'ongresinc-stackgres_arcan_combi'!$B:$B, $B2, 'ongresinc-stackgres_arcan_combi'!$C:$C, $C2)), AVERAGE( SUMIFS('dlr-shepard-shepard_arcan_combi'!M:M, 'dlr-shepard-shepard_arcan_combi'!$A:$A, $A2, 'dlr-shepard-shepard_arcan_combi'!$B:$B, $B2, 'dlr-shepard-shepard_arcan_combi'!$C:$C, $C2), SUMIFS('ongresinc-stackgres_arcan_combi'!M:M, 'ongresinc-stackgres_arcan_combi'!$A:$A, $A2, 'ongresinc-stackgres_arcan_combi'!$B:$B, $B2, 'ongresinc-stackgres_arcan_combi'!$C:$C, $C2)), "") | N2: =IF( AND(SUMIFS('dlr-shepard-shepard_arcan_combi'!N:N, 'dlr-shepard-shepard_arcan_combi'!$A:$A, $A2, 'dlr-shepard-shepard_arcan_combi'!$B:$B, $B2, 'dlr-shepard-shepard_arcan_combi'!$C:$C, $C2), SUMIFS('ongresinc-stackgres_arcan_combi'!N:N, 'ongresinc-stackgres_arcan_combi'!$A:$A, $A2, 'ongresinc-stackgres_arcan_combi'!$B:$B, $B2, 'ongresinc-stackgres_arcan_combi'!$C:$C, $C2)), AVERAGE( SUMIFS('dlr-shepard-shepard_arcan_combi'!N:N, 'dlr-shepard-shepard_arcan_combi'!$A:$A, $A2, 'dlr-shepard-shepard_arcan_combi'!$B:$B, $B2, 'dlr-shepard-shepard_arcan_combi'!$C:$C, $C2), SUMIFS('ongresinc-stackgres_arcan_combi'!N:N, 'ongresinc-stackgres_arcan_combi'!$A:$A, $A2, 'ongresinc-stackgres_arcan_combi'!$B:$B, $B2, 'ongresinc-stackgres_arcan_combi'!$C:$C, $C2)), "") | O2: =IF( AND(SUMIFS('dlr-shepard-shepard_arcan_combi'!O:O, 'dlr-shepard-shepard_arcan_combi'!$A:$A, $A2, 'dlr-shepard-shepard_arcan_combi'!$B:$B, $B2, 'dlr-shepard-shepard_arcan_combi'!$C:$C, $C2), SUMIFS('ongresinc-stackgres_arcan_combi'!O:O, 'ongresinc-stackgres_arcan_combi'!$A:$A, $A2, 'ongresinc-stackgres_arcan_combi'!$B:$B, $B2, 'ongresinc-stackgres_arcan_combi'!$C:$C, $C2)), AVERAGE( SUMIFS('dlr-shepard-shepard_arcan_combi'!O:O, 'dlr-shepard-shepard_arcan_combi'!$A:$A, $A2, 'dlr-shepard-shepard_arcan_combi'!$B:$B, $B2, 'dlr-shepard-shepard_arcan_combi'!$C:$C, $C2), SUMIFS('ongresinc-stackgres_arcan_combi'!O:O, 'ongresinc-stackgres_arcan_combi'!$A:$A, $A2, 'ongresinc-stackgres_arcan_combi'!$B:$B, $B2, 'ongresinc-stackgres_arcan_combi'!$C:$C, $C2)), "") | P2: =IF( AND(SUMIFS('dlr-shepard-shepard_arcan_combi'!P:P, 'dlr-shepard-shepard_arcan_combi'!$A:$A, $A2, 'dlr-shepard-shepard_arcan_combi'!$B:$B, $B2, 'dlr-shepard-shepard_arcan_combi'!$C:$C, $C2), SUMIFS('ongresinc-stackgres_arcan_combi'!P:P, 'ongresinc-stackgres_arcan_combi'!$A:$A, $A2, 'ongresinc-stackgres_arcan_combi'!$B:$B, $B2, 'ongresinc-stackgres_arcan_combi'!$C:$C, $C2)), AVERAGE( SUMIFS('dlr-shepard-shepard_arcan_combi'!P:P, 'dlr-shepard-shepard_arcan_combi'!$A:$A, $A2, 'dlr-shepard-shepard_arcan_combi'!$B:$B, $B2, 'dlr-shepard-shepard_arcan_combi'!$C:$C, $C2), SUMIFS('ongresinc-stackgres_arcan_combi'!P:P, 'ongresinc-stackgres_arcan_combi'!$A:$A, $A2, 'ongresinc-stackgres_arcan_combi'!$B:$B, $B2, 'ongresinc-stackgres_arcan_combi'!$C:$C, $C2)), "") | Q2: =IF( AND(SUMIFS('dlr-shepard-shepard_arcan_combi'!Q:Q, 'dlr-shepard-shepard_arcan_combi'!$A:$A, $A2, 'dlr-shepard-shepard_arcan_combi'!$B:$B, $B2, 'dlr-shepard-shepard_arcan_combi'!$C:$C, $C2), SUMIFS('ongresinc-stackgres_arcan_combi'!Q:Q, 'ongresinc-stackgres_arcan_combi'!$A:$A, $A2, 'ongresinc-stackgres_arcan_combi'!$B:$B, $B2, 'ongresinc-stackgres_arcan_combi'!$C:$C, $C2)), AVERAGE( SUMIFS('dlr-shepard-shepard_arcan_combi'!Q:Q, 'dlr-shepard-shepard_arcan_combi'!$A:$A, $A2, 'dlr-shepard-shepard_arcan_combi'!$B:$B, $B2, 'dlr-shepard-shepard_arcan_combi'!$C:$C, $C2), SUMIFS('ongresinc-stackgres_arcan_combi'!Q:Q, 'ongresinc-stackgres_arcan_combi'!$A:$A, $A2, 'ongresinc-stackgres_arcan_combi'!$B:$B, $B2, 'ongresinc-stackgres_arcan_combi'!$C:$C, $C2)), "") | R2: =IF( AND(SUMIFS('dlr-shepard-shepard_arcan_combi'!R:R, 'dlr-shepard-shepard_arcan_combi'!$A:$A, $A2, 'dlr-shepard-shepard_arcan_combi'!$B:$B, $B2, 'dlr-shepard-shepard_arcan_combi'!$C:$C, $C2), SUMIFS('ongresinc-stackgres_arcan_combi'!R:R, 'ongresinc-stackgres_arcan_combi'!$A:$A, $A2, 'ongresinc-stackgres_arcan_combi'!$B:$B, $B2, 'ongresinc-stackgres_arcan_combi'!$C:$C, $C2)), AVERAGE( SUMIFS('dlr-shepard-shepard_arcan_combi'!R:R, 'dlr-shepard-shepard_arcan_combi'!$A:$A, $A2, 'dlr-shepard-shepard_arcan_combi'!$B:$B, $B2, 'dlr-shepard-shepard_arcan_combi'!$C:$C, $C2), SUMIFS('ongresinc-stackgres_arcan_combi'!R:R, 'ongresinc-stackgres_arcan_combi'!$A:$A, $A2, 'ongresinc-stackgres_arcan_combi'!$B:$B, $B2, 'ongresinc-stackgres_arcan_combi'!$C:$C, $C2)), "") | S2: =IF( AND(SUMIFS('dlr-shepard-shepard_arcan_combi'!S:S, 'dlr-shepard-shepard_arcan_combi'!$A:$A, $A2, 'dlr-shepard-shepard_arcan_combi'!$B:$B, $B2, 'dlr-shepard-shepard_arcan_combi'!$C:$C, $C2), SUMIFS('ongresinc-stackgres_arcan_combi'!S:S, 'ongresinc-stackgres_arcan_combi'!$A:$A, $A2, 'ongresinc-stackgres_arcan_combi'!$B:$B, $B2, 'ongresinc-stackgres_arcan_combi'!$C:$C, $C2)), AVERAGE( SUMIFS('dlr-shepard-shepard_arcan_combi'!S:S, 'dlr-shepard-shepard_arcan_combi'!$A:$A, $A2, 'dlr-shepard-shepard_arcan_combi'!$B:$B, $B2, 'dlr-shepard-shepard_arcan_combi'!$C:$C, $C2), SUMIFS('ongresinc-stackgres_arcan_combi'!S:S, 'ongresinc-stackgres_arcan_combi'!$A:$A, $A2, 'ongresinc-stackgres_arcan_combi'!$B:$B, $B2, 'ongresinc-stackgres_arcan_combi'!$C:$C, $C2)), "") | T2: =IF( AND(SUMIFS('dlr-shepard-shepard_arcan_combi'!T:T, 'dlr-shepard-shepard_arcan_combi'!$A:$A, $A2, 'dlr-shepard-shepard_arcan_combi'!$B:$B, $B2, 'dlr-shepard-shepard_arcan_combi'!$C:$C, $C2), SUMIFS('ongresinc-stackgres_arcan_combi'!T:T, 'ongresinc-stackgres_arcan_combi'!$A:$A, $A2, 'ongresinc-stackgres_arcan_combi'!$B:$B, $B2, 'ongresinc-stackgres_arcan_combi'!$C:$C, $C2)), AVERAGE( SUMIFS('dlr-shepard-shepard_arcan_combi'!T:T, 'dlr-shepard-shepard_arcan_combi'!$A:$A, $A2, 'dlr-shepard-shepard_arcan_combi'!$B:$B, $B2, 'dlr-shepard-shepard_arcan_combi'!$C:$C, $C2), SUMIFS('ongresinc-stackgres_arcan_combi'!T:T, 'ongresinc-stackgres_arcan_combi'!$A:$A, $A2, 'ongresinc-stackgres_arcan_combi'!$B:$B, $B2, 'ongresinc-stackgres_arcan_combi'!$C:$C, $C2)), "") | U2: =IF( AND(SUMIFS('dlr-shepard-shepard_arcan_combi'!U:U, 'dlr-shepard-shepard_arcan_combi'!$A:$A, $A2, 'dlr-shepard-shepard_arcan_combi'!$B:$B, $B2, 'dlr-shepard-shepard_arcan_combi'!$C:$C, $C2), SUMIFS('ongresinc-stackgres_arcan_combi'!U:U, 'ongresinc-stackgres_arcan_combi'!$A:$A, $A2, 'ongresinc-stackgres_arcan_combi'!$B:$B, $B2, 'ongresinc-stackgres_arcan_combi'!$C:$C, $C2)), AVERAGE( SUMIFS('dlr-shepard-shepard_arcan_combi'!U:U, 'dlr-shepard-shepard_arcan_combi'!$A:$A, $A2, 'dlr-shepard-shepard_arcan_combi'!$B:$B, $B2, 'dlr-shepard-shepard_arcan_combi'!$C:$C, $C2), SUMIFS('ongresinc-stackgres_arcan_combi'!U:U, 'ongresinc-stackgres_arcan_combi'!$A:$A, $A2, 'ongresinc-stackgres_arcan_combi'!$B:$B, $B2, 'ongresinc-stackgres_arcan_combi'!$C:$C, $C2)), "")
A3: feedforward_nn | B3: random_undersample | C3: sbert_tfidf_weighted | D3: 7 | E3: =IF( AND(SUMIFS('dlr-shepard-shepard_arcan_combi'!E:E, 'dlr-shepard-shepard_arcan_combi'!$A:$A, $A3, 'dlr-shepard-shepard_arcan_combi'!$B:$B, $B3, 'dlr-shepard-shepard_arcan_combi'!$C:$C, $C3), SUMIFS('ongresinc-stackgres_arcan_combi'!E:E, 'ongresinc-stackgres_arcan_combi'!$A:$A, $A3, 'ongresinc-stackgres_arcan_combi'!$B:$B, $B3, 'ongresinc-stackgres_arcan_combi'!$C:$C, $C3)), AVERAGE( SUMIFS('dlr-shepard-shepard_arcan_combi'!E:E, 'dlr-shepard-shepard_arcan_combi'!$A:$A, $A3, 'dlr-shepard-shepard_arcan_combi'!$B:$B, $B3, 'dlr-shepard-shepard_arcan_combi'!$C:$C, $C3), SUMIFS('ongresinc-stackgres_arcan_combi'!E:E, 'ongresinc-stackgres_arcan_combi'!$A:$A, $A3, 'ongresinc-stackgres_arcan_combi'!$B:$B, $B3, 'ongresinc-stackgres_arcan_combi'!$C:$C, $C3)), "") | F3: =IF( AND(SUMIFS('dlr-shepard-shepard_arcan_combi'!F:F, 'dlr-shepard-shepard_arcan_combi'!$A:$A, $A3, 'dlr-shepard-shepard_arcan_combi'!$B:$B, $B3, 'dlr-shepard-shepard_arcan_combi'!$C:$C, $C3), SUMIFS('ongresinc-stackgres_arcan_combi'!F:F, 'ongresinc-stackgres_arcan_combi'!$A:$A, $A3, 'ongresinc-stackgres_arcan_combi'!$B:$B, $B3, 'ongresinc-stackgres_arcan_combi'!$C:$C, $C3)), AVERAGE( SUMIFS('dlr-shepard-shepard_arcan_combi'!F:F, 'dlr-shepard-shepard_arcan_combi'!$A:$A, $A3, 'dlr-shepard-shepard_arcan_combi'!$B:$B, $B3, 'dlr-shepard-shepard_arcan_combi'!$C:$C, $C3), SUMIFS('ongresinc-stackgres_arcan_combi'!F:F, 'ongresinc-stackgres_arcan_combi'!$A:$A, $A3, 'ongresinc-stackgres_arcan_combi'!$B:$B, $B3, 'ongresinc-stackgres_arcan_combi'!$C:$C, $C3)), "") | G3: =IF( AND(SUMIFS('dlr-shepard-shepard_arcan_combi'!G:G, 'dlr-shepard-shepard_arcan_combi'!$A:$A, $A3, 'dlr-shepard-shepard_arcan_combi'!$B:$B, $B3, 'dlr-shepard-shepard_arcan_combi'!$C:$C, $C3), SUMIFS('ongresinc-stackgres_arcan_combi'!G:G, 'ongresinc-stackgres_arcan_combi'!$A:$A, $A3, 'ongresinc-stackgres_arcan_combi'!$B:$B, $B3, 'ongresinc-stackgres_arcan_combi'!$C:$C, $C3)), AVERAGE( SUMIFS('dlr-shepard-shepard_arcan_combi'!G:G, 'dlr-shepard-shepard_arcan_combi'!$A:$A, $A3, 'dlr-shepard-shepard_arcan_combi'!$B:$B, $B3, 'dlr-shepard-shepard_arcan_combi'!$C:$C, $C3), SUMIFS('ongresinc-stackgres_arcan_combi'!G:G, 'ongresinc-stackgres_arcan_combi'!$A:$A, $A3, 'ongresinc-stackgres_arcan_combi'!$B:$B, $B3, 'ongresinc-stackgres_arcan_combi'!$C:$C, $C3)), "") | H3: =IF( AND(SUMIFS('dlr-shepard-shepard_arcan_combi'!H:H, 'dlr-shepard-shepard_arcan_combi'!$A:$A, $A3, 'dlr-shepard-shepard_arcan_combi'!$B:$B, $B3, 'dlr-shepard-shepard_arcan_combi'!$C:$C, $C3), SUMIFS('ongresinc-stackgres_arcan_combi'!H:H, 'ongresinc-stackgres_arcan_combi'!$A:$A, $A3, 'ongresinc-stackgres_arcan_combi'!$B:$B, $B3, 'ongresinc-stackgres_arcan_combi'!$C:$C, $C3)), AVERAGE( SUMIFS('dlr-shepard-shepard_arcan_combi'!H:H, 'dlr-shepard-shepard_arcan_combi'!$A:$A, $A3, 'dlr-shepard-shepard_arcan_combi'!$B:$B, $B3, 'dlr-shepard-shepard_arcan_combi'!$C:$C, $C3), SUMIFS('ongresinc-stackgres_arcan_combi'!H:H, 'ongresinc-stackgres_arcan_combi'!$A:$A, $A3, 'ongresinc-stackgres_arcan_combi'!$B:$B, $B3, 'ongresinc-stackgres_arcan_combi'!$C:$C, $C3)), "") | I3: =IF( AND(SUMIFS('dlr-shepard-shepard_arcan_combi'!I:I, 'dlr-shepard-shepard_arcan_combi'!$A:$A, $A3, 'dlr-shepard-shepard_arcan_combi'!$B:$B, $B3, 'dlr-shepard-shepard_arcan_combi'!$C:$C, $C3), SUMIFS('ongresinc-stackgres_arcan_combi'!I:I, 'ongresinc-stackgres_arcan_combi'!$A:$A, $A3, 'ongresinc-stackgres_arcan_combi'!$B:$B, $B3, 'ongresinc-stackgres_arcan_combi'!$C:$C, $C3)), AVERAGE( SUMIFS('dlr-shepard-shepard_arcan_combi'!I:I, 'dlr-shepard-shepard_arcan_combi'!$A:$A, $A3, 'dlr-shepard-shepard_arcan_combi'!$B:$B, $B3, 'dlr-shepard-shepard_arcan_combi'!$C:$C, $C3), SUMIFS('ongresinc-stackgres_arcan_combi'!I:I, 'ongresinc-stackgres_arcan_combi'!$A:$A, $A3, 'ongresinc-stackgres_arcan_combi'!$B:$B, $B3, 'ongresinc-stackgres_arcan_combi'!$C:$C, $C3)), "") | J3: =IF( AND(SUMIFS('dlr-shepard-shepard_arcan_combi'!J:J, 'dlr-shepard-shepard_arcan_combi'!$A:$A, $A3, 'dlr-shepard-shepard_arcan_combi'!$B:$B, $B3, 'dlr-shepard-shepard_arcan_combi'!$C:$C, $C3), SUMIFS('ongresinc-stackgres_arcan_combi'!J:J, 'ongresinc-stackgres_arcan_combi'!$A:$A, $A3, 'ongresinc-stackgres_arcan_combi'!$B:$B, $B3, 'ongresinc-stackgres_arcan_combi'!$C:$C, $C3)), AVERAGE( SUMIFS('dlr-shepard-shepard_arcan_combi'!J:J, 'dlr-shepard-shepard_arcan_combi'!$A:$A, $A3, 'dlr-shepard-shepard_arcan_combi'!$B:$B, $B3, 'dlr-shepard-shepard_arcan_combi'!$C:$C, $C3), SUMIFS('ongresinc-stackgres_arcan_combi'!J:J, 'ongresinc-stackgres_arcan_combi'!$A:$A, $A3, 'ongresinc-stackgres_arcan_combi'!$B:$B, $B3, 'ongresinc-stackgres_arcan_combi'!$C:$C, $C3)), "") | K3: =IF( AND(SUMIFS('dlr-shepard-shepard_arcan_combi'!K:K, 'dlr-shepard-shepard_arcan_combi'!$A:$A, $A3, 'dlr-shepard-shepard_arcan_combi'!$B:$B, $B3, 'dlr-shepard-shepard_arcan_combi'!$C:$C, $C3), SUMIFS('ongresinc-stackgres_arcan_combi'!K:K, 'ongresinc-stackgres_arcan_combi'!$A:$A, $A3, 'ongresinc-stackgres_arcan_combi'!$B:$B, $B3, 'ongresinc-stackgres_arcan_combi'!$C:$C, $C3)), AVERAGE( SUMIFS('dlr-shepard-shepard_arcan_combi'!K:K, 'dlr-shepard-shepard_arcan_combi'!$A:$A, $A3, 'dlr-shepard-shepard_arcan_combi'!$B:$B, $B3, 'dlr-shepard-shepard_arcan_combi'!$C:$C, $C3), SUMIFS('ongresinc-stackgres_arcan_combi'!K:K, 'ongresinc-stackgres_arcan_combi'!$A:$A, $A3, 'ongresinc-stackgres_arcan_combi'!$B:$B, $B3, 'ongresinc-stackgres_arcan_combi'!$C:$C, $C3)), "") | L3: =IF( AND(SUMIFS('dlr-shepard-shepard_arcan_combi'!L:L, 'dlr-shepard-shepard_arcan_combi'!$A:$A, $A3, 'dlr-shepard-shepard_arcan_combi'!$B:$B, $B3, 'dlr-shepard-shepard_arcan_combi'!$C:$C, $C3), SUMIFS('ongresinc-stackgres_arcan_combi'!L:L, 'ongresinc-stackgres_arcan_combi'!$A:$A, $A3, 'ongresinc-stackgres_arcan_combi'!$B:$B, $B3, 'ongresinc-stackgres_arcan_combi'!$C:$C, $C3)), AVERAGE( SUMIFS('dlr-shepard-shepard_arcan_combi'!L:L, 'dlr-shepard-shepard_arcan_combi'!$A:$A, $A3, 'dlr-shepard-shepard_arcan_combi'!$B:$B, $B3, 'dlr-shepard-shepard_arcan_combi'!$C:$C, $C3), SUMIFS('ongresinc-stackgres_arcan_combi'!L:L, 'ongresinc-stackgres_arcan_combi'!$A:$A, $A3, 'ongresinc-stackgres_arcan_combi'!$B:$B, $B3, 'ongresinc-stackgres_arcan_combi'!$C:$C, $C3)), "") | M3: =IF( AND(SUMIFS('dlr-shepard-shepard_arcan_combi'!M:M, 'dlr-shepard-shepard_arcan_combi'!$A:$A, $A3, 'dlr-shepard-shepard_arcan_combi'!$B:$B, $B3, 'dlr-shepard-shepard_arcan_combi'!$C:$C, $C3), SUMIFS('ongresinc-stackgres_arcan_combi'!M:M, 'ongresinc-stackgres_arcan_combi'!$A:$A, $A3, 'ongresinc-stackgres_arcan_combi'!$B:$B, $B3, 'ongresinc-stackgres_arcan_combi'!$C:$C, $C3)), AVERAGE( SUMIFS('dlr-shepard-shepard_arcan_combi'!M:M, 'dlr-shepard-shepard_arcan_combi'!$A:$A, $A3, 'dlr-shepard-shepard_arcan_combi'!$B:$B, $B3, 'dlr-shepard-shepard_arcan_combi'!$C:$C, $C3), SUMIFS('ongresinc-stackgres_arcan_combi'!M:M, 'ongresinc-stackgres_arcan_combi'!$A:$A, $A3, 'ongresinc-stackgres_arcan_combi'!$B:$B, $B3, 'ongresinc-stackgres_arcan_combi'!$C:$C, $C3)), "") | N3: =IF( AND(SUMIFS('dlr-shepard-shepard_arcan_combi'!N:N, 'dlr-shepard-shepard_arcan_combi'!$A:$A, $A3, 'dlr-shepard-shepard_arcan_combi'!$B:$B, $B3, 'dlr-shepard-shepard_arcan_combi'!$C:$C, $C3), SUMIFS('ongresinc-stackgres_arcan_combi'!N:N, 'ongresinc-stackgres_arcan_combi'!$A:$A, $A3, 'ongresinc-stackgres_arcan_combi'!$B:$B, $B3, 'ongresinc-stackgres_arcan_combi'!$C:$C, $C3)), AVERAGE( SUMIFS('dlr-shepard-shepard_arcan_combi'!N:N, 'dlr-shepard-shepard_arcan_combi'!$A:$A, $A3, 'dlr-shepard-shepard_arcan_combi'!$B:$B, $B3, 'dlr-shepard-shepard_arcan_combi'!$C:$C, $C3), SUMIFS('ongresinc-stackgres_arcan_combi'!N:N, 'ongresinc-stackgres_arcan_combi'!$A:$A, $A3, 'ongresinc-stackgres_arcan_combi'!$B:$B, $B3, 'ongresinc-stackgres_arcan_combi'!$C:$C, $C3)), "") | O3: =IF( AND(SUMIFS('dlr-shepard-shepard_arcan_combi'!O:O, 'dlr-shepard-shepard_arcan_combi'!$A:$A, $A3, 'dlr-shepard-shepard_arcan_combi'!$B:$B, $B3, 'dlr-shepard-shepard_arcan_combi'!$C:$C, $C3), SUMIFS('ongresinc-stackgres_arcan_combi'!O:O, 'ongresinc-stackgres_arcan_combi'!$A:$A, $A3, 'ongresinc-stackgres_arcan_combi'!$B:$B, $B3, 'ongresinc-stackgres_arcan_combi'!$C:$C, $C3)), AVERAGE( SUMIFS('dlr-shepard-shepard_arcan_combi'!O:O, 'dlr-shepard-shepard_arcan_combi'!$A:$A, $A3, 'dlr-shepard-shepard_arcan_combi'!$B:$B, $B3, 'dlr-shepard-shepard_arcan_combi'!$C:$C, $C3), SUMIFS('ongresinc-stackgres_arcan_combi'!O:O, 'ongresinc-stackgres_arcan_combi'!$A:$A, $A3, 'ongresinc-stackgres_arcan_combi'!$B:$B, $B3, 'ongresinc-stackgres_arcan_combi'!$C:$C, $C3)), "") | P3: =IF( AND(SUMIFS('dlr-shepard-shepard_arcan_combi'!P:P, 'dlr-shepard-shepard_arcan_combi'!$A:$A, $A3, 'dlr-shepard-shepard_arcan_combi'!$B:$B, $B3, 'dlr-shepard-shepard_arcan_combi'!$C:$C, $C3), SUMIFS('ongresinc-stackgres_arcan_combi'!P:P, 'ongresinc-stackgres_arcan_combi'!$A:$A, $A3, 'ongresinc-stackgres_arcan_combi'!$B:$B, $B3, 'ongresinc-stackgres_arcan_combi'!$C:$C, $C3)), AVERAGE( SUMIFS('dlr-shepard-shepard_arcan_combi'!P:P, 'dlr-shepard-shepard_arcan_combi'!$A:$A, $A3, 'dlr-shepard-shepard_arcan_combi'!$B:$B, $B3, 'dlr-shepard-shepard_arcan_combi'!$C:$C, $C3), SUMIFS('ongresinc-stackgres_arcan_combi'!P:P, 'ongresinc-stackgres_arcan_combi'!$A:$A, $A3, 'ongresinc-stackgres_arcan_combi'!$B:$B, $B3, 'ongresinc-stackgres_arcan_combi'!$C:$C, $C3)), "") | Q3: =IF( AND(SUMIFS('dlr-shepard-shepard_arcan_combi'!Q:Q, 'dlr-shepard-shepard_arcan_combi'!$A:$A, $A3, 'dlr-shepard-shepard_arcan_combi'!$B:$B, $B3, 'dlr-shepard-shepard_arcan_combi'!$C:$C, $C3), SUMIFS('ongresinc-stackgres_arcan_combi'!Q:Q, 'ongresinc-stackgres_arcan_combi'!$A:$A, $A3, 'ongresinc-stackgres_arcan_combi'!$B:$B, $B3, 'ongresinc-stackgres_arcan_combi'!$C:$C, $C3)), AVERAGE( SUMIFS('dlr-shepard-shepard_arcan_combi'!Q:Q, 'dlr-shepard-shepard_arcan_combi'!$A:$A, $A3, 'dlr-shepard-shepard_arcan_combi'!$B:$B, $B3, 'dlr-shepard-shepard_arcan_combi'!$C:$C, $C3), SUMIFS('ongresinc-stackgres_arcan_combi'!Q:Q, 'ongresinc-stackgres_arcan_combi'!$A:$A, $A3, 'ongresinc-stackgres_arcan_combi'!$B:$B, $B3, 'ongresinc-stackgres_arcan_combi'!$C:$C, $C3)), "") | R3: =IF( AND(SUMIFS('dlr-shepard-shepard_arcan_combi'!R:R, 'dlr-shepard-shepard_arcan_combi'!$A:$A, $A3, 'dlr-shepard-shepard_arcan_combi'!$B:$B, $B3, 'dlr-shepard-shepard_arcan_combi'!$C:$C, $C3), SUMIFS('ongresinc-stackgres_arcan_combi'!R:R, 'ongresinc-stackgres_arcan_combi'!$A:$A, $A3, 'ongresinc-stackgres_arcan_combi'!$B:$B, $B3, 'ongresinc-stackgres_arcan_combi'!$C:$C, $C3)), AVERAGE( SUMIFS('dlr-shepard-shepard_arcan_combi'!R:R, 'dlr-shepard-shepard_arcan_combi'!$A:$A, $A3, 'dlr-shepard-shepard_arcan_combi'!$B:$B, $B3, 'dlr-shepard-shepard_arcan_combi'!$C:$C, $C3), SUMIFS('ongresinc-stackgres_arcan_combi'!R:R, 'ongresinc-stackgres_arcan_combi'!$A:$A, $A3, 'ongresinc-stackgres_arcan_combi'!$B:$B, $B3, 'ongresinc-stackgres_arcan_combi'!$C:$C, $C3)), "") | S3: =IF( AND(SUMIFS('dlr-shepard-shepard_arcan_combi'!S:S, 'dlr-shepard-shepard_arcan_combi'!$A:$A, $A3, 'dlr-shepard-shepard_arcan_combi'!$B:$B, $B3, 'dlr-shepard-shepard_arcan_combi'!$C:$C, $C3), SUMIFS('ongresinc-stackgres_arcan_combi'!S:S, 'ongresinc-stackgres_arcan_combi'!$A:$A, $A3, 'ongresinc-stackgres_arcan_combi'!$B:$B, $B3, 'ongresinc-stackgres_arcan_combi'!$C:$C, $C3)), AVERAGE( SUMIFS('dlr-shepard-shepard_arcan_combi'!S:S, 'dlr-shepard-shepard_arcan_combi'!$A:$A, $A3, 'dlr-shepard-shepard_arcan_combi'!$B:$B, $B3, 'dlr-shepard-shepard_arcan_combi'!$C:$C, $C3), SUMIFS('ongresinc-stackgres_arcan_combi'!S:S, 'ongresinc-stackgres_arcan_combi'!$A:$A, $A3, 'ongresinc-stackgres_arcan_combi'!$B:$B, $B3, 'ongresinc-stackgres_arcan_combi'!$C:$C, $C3)), "") | T3: =IF( AND(SUMIFS('dlr-shepard-shepard_arcan_combi'!T:T, 'dlr-shepard-shepard_arcan_combi'!$A:$A, $A3, 'dlr-shepard-shepard_arcan_combi'!$B:$B, $B3, 'dlr-shepard-shepard_arcan_combi'!$C:$C, $C3), SUMIFS('ongresinc-stackgres_arcan_combi'!T:T, 'ongresinc-stackgres_arcan_combi'!$A:$A, $A3, 'ongresinc-stackgres_arcan_combi'!$B:$B, $B3, 'ongresinc-stackgres_arcan_combi'!$C:$C, $C3)), AVERAGE( SUMIFS('dlr-shepard-shepard_arcan_combi'!T:T, 'dlr-shepard-shepard_arcan_combi'!$A:$A, $A3, 'dlr-shepard-shepard_arcan_combi'!$B:$B, $B3, 'dlr-shepard-shepard_arcan_combi'!$C:$C, $C3), SUMIFS('ongresinc-stackgres_arcan_combi'!T:T, 'ongresinc-stackgres_arcan_combi'!$A:$A, $A3, 'ongresinc-stackgres_arcan_combi'!$B:$B, $B3, 'ongresinc-stackgres_arcan_combi'!$C:$C, $C3)), "") | U3: =IF( AND(SUMIFS('dlr-shepard-shepard_arcan_combi'!U:U, 'dlr-shepard-shepard_arcan_combi'!$A:$A, $A3, 'dlr-shepard-shepard_arcan_combi'!$B:$B, $B3, 'dlr-shepard-shepard_arcan_combi'!$C:$C, $C3), SUMIFS('ongresinc-stackgres_arcan_combi'!U:U, 'ongresinc-stackgres_arcan_combi'!$A:$A, $A3, 'ongresinc-stackgres_arcan_combi'!$B:$B, $B3, 'ongresinc-stackgres_arcan_combi'!$C:$C, $C3)), AVERAGE( SUMIFS('dlr-shepard-shepard_arcan_combi'!U:U, 'dlr-shepard-shepard_arcan_combi'!$A:$A, $A3, 'dlr-shepard-shepard_arcan_combi'!$B:$B, $B3, 'dlr-shepard-shepard_arcan_combi'!$C:$C, $C3), SUMIFS('ongresinc-stackgres_arcan_combi'!U:U, 'ongresinc-stackgres_arcan_combi'!$A:$A, $A3, 'ongresinc-stackgres_arcan_combi'!$B:$B, $B3, 'ongresinc-stackgres_arcan_combi'!$C:$C, $C3)), "")
A4: feedforward_nn | B4: random_undersample | C4: sbert_avg | D4: 7 | E4: =IF( AND(SUMIFS('dlr-shepard-shepard_arcan_combi'!E:E, 'dlr-shepard-shepard_arcan_combi'!$A:$A, $A4, 'dlr-shepard-shepard_arcan_combi'!$B:$B, $B4, 'dlr-shepard-shepard_arcan_combi'!$C:$C, $C4), SUMIFS('ongresinc-stackgres_arcan_combi'!E:E, 'ongresinc-stackgres_arcan_combi'!$A:$A, $A4, 'ongresinc-stackgres_arcan_combi'!$B:$B, $B4, 'ongresinc-stackgres_arcan_combi'!$C:$C, $C4)), AVERAGE( SUMIFS('dlr-shepard-shepard_arcan_combi'!E:E, 'dlr-shepard-shepard_arcan_combi'!$A:$A, $A4, 'dlr-shepard-shepard_arcan_combi'!$B:$B, $B4, 'dlr-shepard-shepard_arcan_combi'!$C:$C, $C4), SUMIFS('ongresinc-stackgres_arcan_combi'!E:E, 'ongresinc-stackgres_arcan_combi'!$A:$A, $A4, 'ongresinc-stackgres_arcan_combi'!$B:$B, $B4, 'ongresinc-stackgres_arcan_combi'!$C:$C, $C4)), "") | F4: =IF( AND(SUMIFS('dlr-shepard-shepard_arcan_combi'!F:F, 'dlr-shepard-shepard_arcan_combi'!$A:$A, $A4, 'dlr-shepard-shepard_arcan_combi'!$B:$B, $B4, 'dlr-shepard-shepard_arcan_combi'!$C:$C, $C4), SUMIFS('ongresinc-stackgres_arcan_combi'!F:F, 'ongresinc-stackgres_arcan_combi'!$A:$A, $A4, 'ongresinc-stackgres_arcan_combi'!$B:$B, $B4, 'ongresinc-stackgres_arcan_combi'!$C:$C, $C4)), AVERAGE( SUMIFS('dlr-shepard-shepard_arcan_combi'!F:F, 'dlr-shepard-shepard_arcan_combi'!$A:$A, $A4, 'dlr-shepard-shepard_arcan_combi'!$B:$B, $B4, 'dlr-shepard-shepard_arcan_combi'!$C:$C, $C4), SUMIFS('ongresinc-stackgres_arcan_combi'!F:F, 'ongresinc-stackgres_arcan_combi'!$A:$A, $A4, 'ongresinc-stackgres_arcan_combi'!$B:$B, $B4, 'ongresinc-stackgres_arcan_combi'!$C:$C, $C4)), "") | G4: =IF( AND(SUMIFS('dlr-shepard-shepard_arcan_combi'!G:G, 'dlr-shepard-shepard_arcan_combi'!$A:$A, $A4, 'dlr-shepard-shepard_arcan_combi'!$B:$B, $B4, 'dlr-shepard-shepard_arcan_combi'!$C:$C, $C4), SUMIFS('ongresinc-stackgres_arcan_combi'!G:G, 'ongresinc-stackgres_arcan_combi'!$A:$A, $A4, 'ongresinc-stackgres_arcan_combi'!$B:$B, $B4, 'ongresinc-stackgres_arcan_combi'!$C:$C, $C4)), AVERAGE( SUMIFS('dlr-shepard-shepard_arcan_combi'!G:G, 'dlr-shepard-shepard_arcan_combi'!$A:$A, $A4, 'dlr-shepard-shepard_arcan_combi'!$B:$B, $B4, 'dlr-shepard-shepard_arcan_combi'!$C:$C, $C4), SUMIFS('ongresinc-stackgres_arcan_combi'!G:G, 'ongresinc-stackgres_arcan_combi'!$A:$A, $A4, 'ongresinc-stackgres_arcan_combi'!$B:$B, $B4, 'ongresinc-stackgres_arcan_combi'!$C:$C, $C4)), "") | H4: =IF( AND(SUMIFS('dlr-shepard-shepard_arcan_combi'!H:H, 'dlr-shepard-shepard_arcan_combi'!$A:$A, $A4, 'dlr-shepard-shepard_arcan_combi'!$B:$B, $B4, 'dlr-shepard-shepard_arcan_combi'!$C:$C, $C4), SUMIFS('ongresinc-stackgres_arcan_combi'!H:H, 'ongresinc-stackgres_arcan_combi'!$A:$A, $A4, 'ongresinc-stackgres_arcan_combi'!$B:$B, $B4, 'ongresinc-stackgres_arcan_combi'!$C:$C, $C4)), AVERAGE( SUMIFS('dlr-shepard-shepard_arcan_combi'!H:H, 'dlr-shepard-shepard_arcan_combi'!$A:$A, $A4, 'dlr-shepard-shepard_arcan_combi'!$B:$B, $B4, 'dlr-shepard-shepard_arcan_combi'!$C:$C, $C4), SUMIFS('ongresinc-stackgres_arcan_combi'!H:H, 'ongresinc-stackgres_arcan_combi'!$A:$A, $A4, 'ongresinc-stackgres_arcan_combi'!$B:$B, $B4, 'ongresinc-stackgres_arcan_combi'!$C:$C, $C4)), "") | I4: =IF( AND(SUMIFS('dlr-shepard-shepard_arcan_combi'!I:I, 'dlr-shepard-shepard_arcan_combi'!$A:$A, $A4, 'dlr-shepard-shepard_arcan_combi'!$B:$B, $B4, 'dlr-shepard-shepard_arcan_combi'!$C:$C, $C4), SUMIFS('ongresinc-stackgres_arcan_combi'!I:I, 'ongresinc-stackgres_arcan_combi'!$A:$A, $A4, 'ongresinc-stackgres_arcan_combi'!$B:$B, $B4, 'ongresinc-stackgres_arcan_combi'!$C:$C, $C4)), AVERAGE( SUMIFS('dlr-shepard-shepard_arcan_combi'!I:I, 'dlr-shepard-shepard_arcan_combi'!$A:$A, $A4, 'dlr-shepard-shepard_arcan_combi'!$B:$B, $B4, 'dlr-shepard-shepard_arcan_combi'!$C:$C, $C4), SUMIFS('ongresinc-stackgres_arcan_combi'!I:I, 'ongresinc-stackgres_arcan_combi'!$A:$A, $A4, 'ongresinc-stackgres_arcan_combi'!$B:$B, $B4, 'ongresinc-stackgres_arcan_combi'!$C:$C, $C4)), "") | J4: =IF( AND(SUMIFS('dlr-shepard-shepard_arcan_combi'!J:J, 'dlr-shepard-shepard_arcan_combi'!$A:$A, $A4, 'dlr-shepard-shepard_arcan_combi'!$B:$B, $B4, 'dlr-shepard-shepard_arcan_combi'!$C:$C, $C4), SUMIFS('ongresinc-stackgres_arcan_combi'!J:J, 'ongresinc-stackgres_arcan_combi'!$A:$A, $A4, 'ongresinc-stackgres_arcan_combi'!$B:$B, $B4, 'ongresinc-stackgres_arcan_combi'!$C:$C, $C4)), AVERAGE( SUMIFS('dlr-shepard-shepard_arcan_combi'!J:J, 'dlr-shepard-shepard_arcan_combi'!$A:$A, $A4, 'dlr-shepard-shepard_arcan_combi'!$B:$B, $B4, 'dlr-shepard-shepard_arcan_combi'!$C:$C, $C4), SUMIFS('ongresinc-stackgres_arcan_combi'!J:J, 'ongresinc-stackgres_arcan_combi'!$A:$A, $A4, 'ongresinc-stackgres_arcan_combi'!$B:$B, $B4, 'ongresinc-stackgres_arcan_combi'!$C:$C, $C4)), "") | K4: =IF( AND(SUMIFS('dlr-shepard-shepard_arcan_combi'!K:K, 'dlr-shepard-shepard_arcan_combi'!$A:$A, $A4, 'dlr-shepard-shepard_arcan_combi'!$B:$B, $B4, 'dlr-shepard-shepard_arcan_combi'!$C:$C, $C4), SUMIFS('ongresinc-stackgres_arcan_combi'!K:K, 'ongresinc-stackgres_arcan_combi'!$A:$A, $A4, 'ongresinc-stackgres_arcan_combi'!$B:$B, $B4, 'ongresinc-stackgres_arcan_combi'!$C:$C, $C4)), AVERAGE( SUMIFS('dlr-shepard-shepard_arcan_combi'!K:K, 'dlr-shepard-shepard_arcan_combi'!$A:$A, $A4, 'dlr-shepard-shepard_arcan_combi'!$B:$B, $B4, 'dlr-shepard-shepard_arcan_combi'!$C:$C, $C4), SUMIFS('ongresinc-stackgres_arcan_combi'!K:K, 'ongresinc-stackgres_arcan_combi'!$A:$A, $A4, 'ongresinc-stackgres_arcan_combi'!$B:$B, $B4, 'ongresinc-stackgres_arcan_combi'!$C:$C, $C4)), "") | L4: =IF( AND(SUMIFS('dlr-shepard-shepard_arcan_combi'!L:L, 'dlr-shepard-shepard_arcan_combi'!$A:$A, $A4, 'dlr-shepard-shepard_arcan_combi'!$B:$B, $B4, 'dlr-shepard-shepard_arcan_combi'!$C:$C, $C4), SUMIFS('ongresinc-stackgres_arcan_combi'!L:L, 'ongresinc-stackgres_arcan_combi'!$A:$A, $A4, 'ongresinc-stackgres_arcan_combi'!$B:$B, $B4, 'ongresinc-stackgres_arcan_combi'!$C:$C, $C4)), AVERAGE( SUMIFS('dlr-shepard-shepard_arcan_combi'!L:L, 'dlr-shepard-shepard_arcan_combi'!$A:$A, $A4, 'dlr-shepard-shepard_arcan_combi'!$B:$B, $B4, 'dlr-shepard-shepard_arcan_combi'!$C:$C, $C4), SUMIFS('ongresinc-stackgres_arcan_combi'!L:L, 'ongresinc-stackgres_arcan_combi'!$A:$A, $A4, 'ongresinc-stackgres_arcan_combi'!$B:$B, $B4, 'ongresinc-stackgres_arcan_combi'!$C:$C, $C4)), "") | M4: =IF( AND(SUMIFS('dlr-shepard-shepard_arcan_combi'!M:M, 'dlr-shepard-shepard_arcan_combi'!$A:$A, $A4, 'dlr-shepard-shepard_arcan_combi'!$B:$B, $B4, 'dlr-shepard-shepard_arcan_combi'!$C:$C, $C4), SUMIFS('ongresinc-stackgres_arcan_combi'!M:M, 'ongresinc-stackgres_arcan_combi'!$A:$A, $A4, 'ongresinc-stackgres_arcan_combi'!$B:$B, $B4, 'ongresinc-stackgres_arcan_combi'!$C:$C, $C4)), AVERAGE( SUMIFS('dlr-shepard-shepard_arcan_combi'!M:M, 'dlr-shepard-shepard_arcan_combi'!$A:$A, $A4, 'dlr-shepard-shepard_arcan_combi'!$B:$B, $B4, 'dlr-shepard-shepard_arcan_combi'!$C:$C, $C4), SUMIFS('ongresinc-stackgres_arcan_combi'!M:M, 'ongresinc-stackgres_arcan_combi'!$A:$A, $A4, 'ongresinc-stackgres_arcan_combi'!$B:$B, $B4, 'ongresinc-stackgres_arcan_combi'!$C:$C, $C4)), "") | N4: =IF( AND(SUMIFS('dlr-shepard-shepard_arcan_combi'!N:N, 'dlr-shepard-shepard_arcan_combi'!$A:$A, $A4, 'dlr-shepard-shepard_arcan_combi'!$B:$B, $B4, 'dlr-shepard-shepard_arcan_combi'!$C:$C, $C4), SUMIFS('ongresinc-stackgres_arcan_combi'!N:N, 'ongresinc-stackgres_arcan_combi'!$A:$A, $A4, 'ongresinc-stackgres_arcan_combi'!$B:$B, $B4, 'ongresinc-stackgres_arcan_combi'!$C:$C, $C4)), AVERAGE( SUMIFS('dlr-shepard-shepard_arcan_combi'!N:N, 'dlr-shepard-shepard_arcan_combi'!$A:$A, $A4, 'dlr-shepard-shepard_arcan_combi'!$B:$B, $B4, 'dlr-shepard-shepard_arcan_combi'!$C:$C, $C4), SUMIFS('ongresinc-stackgres_arcan_combi'!N:N, 'ongresinc-stackgres_arcan_combi'!$A:$A, $A4, 'ongresinc-stackgres_arcan_combi'!$B:$B, $B4, 'ongresinc-stackgres_arcan_combi'!$C:$C, $C4)), "") | O4: =IF( AND(SUMIFS('dlr-shepard-shepard_arcan_combi'!O:O, 'dlr-shepard-shepard_arcan_combi'!$A:$A, $A4, 'dlr-shepard-shepard_arcan_combi'!$B:$B, $B4, 'dlr-shepard-shepard_arcan_combi'!$C:$C, $C4), SUMIFS('ongresinc-stackgres_arcan_combi'!O:O, 'ongresinc-stackgres_arcan_combi'!$A:$A, $A4, 'ongresinc-stackgres_arcan_combi'!$B:$B, $B4, 'ongresinc-stackgres_arcan_combi'!$C:$C, $C4)), AVERAGE( SUMIFS('dlr-shepard-shepard_arcan_combi'!O:O, 'dlr-shepard-shepard_arcan_combi'!$A:$A, $A4, 'dlr-shepard-shepard_arcan_combi'!$B:$B, $B4, 'dlr-shepard-shepard_arcan_combi'!$C:$C, $C4), SUMIFS('ongresinc-stackgres_arcan_combi'!O:O, 'ongresinc-stackgres_arcan_combi'!$A:$A, $A4, 'ongresinc-stackgres_arcan_combi'!$B:$B, $B4, 'ongresinc-stackgres_arcan_combi'!$C:$C, $C4)), "") | P4: =IF( AND(SUMIFS('dlr-shepard-shepard_arcan_combi'!P:P, 'dlr-shepard-shepard_arcan_combi'!$A:$A, $A4, 'dlr-shepard-shepard_arcan_combi'!$B:$B, $B4, 'dlr-shepard-shepard_arcan_combi'!$C:$C, $C4), SUMIFS('ongresinc-stackgres_arcan_combi'!P:P, 'ongresinc-stackgres_arcan_combi'!$A:$A, $A4, 'ongresinc-stackgres_arcan_combi'!$B:$B, $B4, 'ongresinc-stackgres_arcan_combi'!$C:$C, $C4)), AVERAGE( SUMIFS('dlr-shepard-shepard_arcan_combi'!P:P, 'dlr-shepard-shepard_arcan_combi'!$A:$A, $A4, 'dlr-shepard-shepard_arcan_combi'!$B:$B, $B4, 'dlr-shepard-shepard_arcan_combi'!$C:$C, $C4), SUMIFS('ongresinc-stackgres_arcan_combi'!P:P, 'ongresinc-stackgres_arcan_combi'!$A:$A, $A4, 'ongresinc-stackgres_arcan_combi'!$B:$B, $B4, 'ongresinc-stackgres_arcan_combi'!$C:$C, $C4)), "") | Q4: =IF( AND(SUMIFS('dlr-shepard-shepard_arcan_combi'!Q:Q, 'dlr-shepard-shepard_arcan_combi'!$A:$A, $A4, 'dlr-shepard-shepard_arcan_combi'!$B:$B, $B4, 'dlr-shepard-shepard_arcan_combi'!$C:$C, $C4), SUMIFS('ongresinc-stackgres_arcan_combi'!Q:Q, 'ongresinc-stackgres_arcan_combi'!$A:$A, $A4, 'ongresinc-stackgres_arcan_combi'!$B:$B, $B4, 'ongresinc-stackgres_arcan_combi'!$C:$C, $C4)), AVERAGE( SUMIFS('dlr-shepard-shepard_arcan_combi'!Q:Q, 'dlr-shepard-shepard_arcan_combi'!$A:$A, $A4, 'dlr-shepard-shepard_arcan_combi'!$B:$B, $B4, 'dlr-shepard-shepard_arcan_combi'!$C:$C, $C4), SUMIFS('ongresinc-stackgres_arcan_combi'!Q:Q, 'ongresinc-stackgres_arcan_combi'!$A:$A, $A4, 'ongresinc-stackgres_arcan_combi'!$B:$B, $B4, 'ongresinc-stackgres_arcan_combi'!$C:$C, $C4)), "") | R4: =IF( AND(SUMIFS('dlr-shepard-shepard_arcan_combi'!R:R, 'dlr-shepard-shepard_arcan_combi'!$A:$A, $A4, 'dlr-shepard-shepard_arcan_combi'!$B:$B, $B4, 'dlr-shepard-shepard_arcan_combi'!$C:$C, $C4), SUMIFS('ongresinc-stackgres_arcan_combi'!R:R, 'ongresinc-stackgres_arcan_combi'!$A:$A, $A4, 'ongresinc-stackgres_arcan_combi'!$B:$B, $B4, 'ongresinc-stackgres_arcan_combi'!$C:$C, $C4)), AVERAGE( SUMIFS('dlr-shepard-shepard_arcan_combi'!R:R, 'dlr-shepard-shepard_arcan_combi'!$A:$A, $A4, 'dlr-shepard-shepard_arcan_combi'!$B:$B, $B4, 'dlr-shepard-shepard_arcan_combi'!$C:$C, $C4), SUMIFS('ongresinc-stackgres_arcan_combi'!R:R, 'ongresinc-stackgres_arcan_combi'!$A:$A, $A4, 'ongresinc-stackgres_arcan_combi'!$B:$B, $B4, 'ongresinc-stackgres_arcan_combi'!$C:$C, $C4)), "") | S4: =IF( AND(SUMIFS('dlr-shepard-shepard_arcan_combi'!S:S, 'dlr-shepard-shepard_arcan_combi'!$A:$A, $A4, 'dlr-shepard-shepard_arcan_combi'!$B:$B, $B4, 'dlr-shepard-shepard_arcan_combi'!$C:$C, $C4), SUMIFS('ongresinc-stackgres_arcan_combi'!S:S, 'ongresinc-stackgres_arcan_combi'!$A:$A, $A4, 'ongresinc-stackgres_arcan_combi'!$B:$B, $B4, 'ongresinc-stackgres_arcan_combi'!$C:$C, $C4)), AVERAGE( SUMIFS('dlr-shepard-shepard_arcan_combi'!S:S, 'dlr-shepard-shepard_arcan_combi'!$A:$A, $A4, 'dlr-shepard-shepard_arcan_combi'!$B:$B, $B4, 'dlr-shepard-shepard_arcan_combi'!$C:$C, $C4), SUMIFS('ongresinc-stackgres_arcan_combi'!S:S, 'ongresinc-stackgres_arcan_combi'!$A:$A, $A4, 'ongresinc-stackgres_arcan_combi'!$B:$B, $B4, 'ongresinc-stackgres_arcan_combi'!$C:$C, $C4)), "") | T4: =IF( AND(SUMIFS('dlr-shepard-shepard_arcan_combi'!T:T, 'dlr-shepard-shepard_arcan_combi'!$A:$A, $A4, 'dlr-shepard-shepard_arcan_combi'!$B:$B, $B4, 'dlr-shepard-shepard_arcan_combi'!$C:$C, $C4), SUMIFS('ongresinc-stackgres_arcan_combi'!T:T, 'ongresinc-stackgres_arcan_combi'!$A:$A, $A4, 'ongresinc-stackgres_arcan_combi'!$B:$B, $B4, 'ongresinc-stackgres_arcan_combi'!$C:$C, $C4)), AVERAGE( SUMIFS('dlr-shepard-shepard_arcan_combi'!T:T, 'dlr-shepard-shepard_arcan_combi'!$A:$A, $A4, 'dlr-shepard-shepard_arcan_combi'!$B:$B, $B4, 'dlr-shepard-shepard_arcan_combi'!$C:$C, $C4), SUMIFS('ongresinc-stackgres_arcan_combi'!T:T, 'ongresinc-stackgres_arcan_combi'!$A:$A, $A4, 'ongresinc-stackgres_arcan_combi'!$B:$B, $B4, 'ongresinc-stackgres_arcan_combi'!$C:$C, $C4)), "") | U4: =IF( AND(SUMIFS('dlr-shepard-shepard_arcan_combi'!U:U, 'dlr-shepard-shepard_arcan_combi'!$A:$A, $A4, 'dlr-shepard-shepard_arcan_combi'!$B:$B, $B4, 'dlr-shepard-shepard_arcan_combi'!$C:$C, $C4), SUMIFS('ongresinc-stackgres_arcan_combi'!U:U, 'ongresinc-stackgres_arcan_combi'!$A:$A, $A4, 'ongresinc-stackgres_arcan_combi'!$B:$B, $B4, 'ongresinc-stackgres_arcan_combi'!$C:$C, $C4)), AVERAGE( SUMIFS('dlr-shepard-shepard_arcan_combi'!U:U, 'dlr-shepard-shepard_arcan_combi'!$A:$A, $A4, 'dlr-shepard-shepard_arcan_combi'!$B:$B, $B4, 'dlr-shepard-shepard_arcan_combi'!$C:$C, $C4), SUMIFS('ongresinc-stackgres_arcan_combi'!U:U, 'ongresinc-stackgres_arcan_combi'!$A:$A, $A4, 'ongresinc-stackgres_arcan_combi'!$B:$B, $B4, 'ongresinc-stackgres_arcan_combi'!$C:$C, $C4)), "")
