Workbook

Sheet dlr-shepard-shepard_arcade_comb
A1: model | B1: strategy | C1: encoding | D1: cv_folds | E1: accuracy_mean | F1: accuracy_std | G1: precision_mean | H1: precision_std | I1: recall_mean | J1: recall_std | K1: f1_mean | L1: f1_std | M1: positive_smell_recall_mean | N1: positive_smell_recall_std | O1: top_1_positive_count_mean | P1: top_1_positive_count_std | Q1: top_5_positive_count_mean | R1: top_5_positive_count_std | S1: top_10_positive_count_mean | T1: top_10_positive_count_std | U1: recall
A2: logistic_regression | B2: none | C2: openai | D2: 7 | E2: 0.8515006 | F2: 0.031345179 | G2: 0.32142857 | H2: 0.34626285 | I2: 0.16666667 | J2: 0.16618979 | K2: 0.21258503 | L2: 0.21367446 | M2: 0.16666667 | N2: 0.16618979 | O2: 0.85714286 | P2: 0.83299313 | Q2: 5.1428571 | R2: 0.34992711 | S2: 5.1428571 | T2: 0.34992711 | U2: 0.16666667
A3: logistic_regression | B3: class_weight | C3: openai | D3: 7 | E3: 0.81416567 | F3: 0.029911476 | G3: 0.36938776 | H3: 0.10106678 | I3: 0.33333333 | J3: 0.087287156 | K3: 0.34718615 | L3: 0.087343436 | M3: 0.33333333 | N3: 0.087287156 | O3: 1.7142857 | P3: 0.45175395 | Q3: 5.1428571 | R3: 0.34992711 | S3: 5.1428571 | T3: 0.34992711 | U3: 0.33333333
A4: logistic_regression | B4: random_undersample | C4: openai | D4: 7 | E4: 0.59531813 | F4: 0.055396405 | G4: 0.2112495 | H4: 0.069176715 | I4: 0.64285714 | J4: 0.23819046 | K4: 0.317469 | L4: 0.1068799 | M4: 0.64285714 | N4: 0.23819046 | O4: 3.2857143 | P4: 1.1605769 | Q4: 5.1428571 | R4: 0.34992711 | S4: 5.1428571 | T4: 0.34992711 | U4: 0.64285714
A5: random_forest | B5: none | C5: openai | D5: 7 | E5: 0.8512605 | F5: 0.0094647795 | G5: 0 | H5: 0 | I5: 0 | J5: 0 | K5: 0 | L5: 0 | M5: 0 | N5: 0 | O5: 0 | P5: 0 | Q5: 5.1428571 | R5: 0.34992711 | S5: 5.1428571 | T5: 0.34992711 | U5: 0
A6: random_forest | B6: class_weight | C6: openai | D6: 7 | E6: 0.8512605 | F6: 0.0094647795 | G6: 0 | H6: 0 | I6: 0 | J6: 0 | K6: 0 | L6: 0 | M6: 0 | N6: 0 | O6: 0 | P6: 0 | Q6: 5.1428571 | R6: 0.34992711 | S6: 5.1428571 | T6: 0.34992711 | U6: 0
A7: random_forest | B7: random_undersample | C7: openai | D7: 7 | E7: 0.59915966 | F7: 0.047013784 | G7: 0.21446275 | H7: 0.030635181 | I7: 0.64285714 | J7: 0.14982984 | K7: 0.31973164 | L7: 0.050556978 | M7: 0.64285714 | N7: 0.14982984 | O7: 3.2857143 | P7: 0.69985421 | Q7: 5.1428571 | R7: 0.34992711 | S7: 5.1428571 | T7: 0.34992711 | U7: 0.64285714
A8: knn | B8: none | C8: openai | D8: 7 | E8: 0.82629052 | F8: 0.041919971 | G8: 0.26190476 | H8: 0.35475391 | I8: 0.080952381 | J8: 0.094040084 | K8: 0.11734694 | L8: 0.13594809 | M8: 0.080952381 | N8: 0.094040084 | O8: 0.42857143 | P8: 0.49487166 | Q8: 5.1428571 | R8: 0.34992711 | S8: 5.1428571 | T8: 0.34992711 | U8: 0.080952381
A9: knn | B9: class_weight | C9: openai | D9: 7 | E9: 0.82629052 | F9: 0.041919971 | G9: 0.26190476 | H9: 0.35475391 | I9: 0.080952381 | J9: 0.094040084 | K9: 0.11734694 | L9: 0.13594809 | M9: 0.080952381 | N9: 0.094040084 | O9: 0.42857143 | P9: 0.49487166 | Q9: 5.1428571 | R9: 0.34992711 | S9: 5.1428571 | T9: 0.34992711 | U9: 0.080952381
A10: knn | B10: random_undersample | C10: openai | D10: 7 | E10: 0.47947179 | F10: 0.070947262 | G10: 0.19723634 | H10: 0.052932739 | I10: 0.8047619 | J10: 0.18553105 | K10: 0.31546296 | L10: 0.079082328 | M10: 0.8047619 | N10: 0.18553105 | O10: 4.1428571 | P10: 0.98974332 | Q10: 5.1428571 | R10: 0.34992711 | S10: 5.1428571 | T10: 0.34992711 | U10: 0.8047619
A11: naive_bayes | B11: none | C11: openai | D11: 7 | E11: 0.77310924 | F11: 0.055106356 | G11: 0.28231293 | H11: 0.11180599 | I11: 0.27619048 | J11: 0.09035079 | K11: 0.26947656 | L11: 0.085649123 | M11: 0.27619048 | N11: 0.09035079 | O11: 1.4285714 | P11: 0.49487166 | Q11: 5.1428571 | R11: 0.34992711 | S11: 5.1428571 | T11: 0.34992711 | U11: 0.27619048
A12: naive_bayes | B12: class_weight | C12: openai | D12: 7 | E12: 0.77310924 | F12: 0.055106356 | G12: 0.28231293 | H12: 0.11180599 | I12: 0.27619048 | J12: 0.09035079 | K12: 0.26947656 | L12: 0.085649123 | M12: 0.27619048 | N12: 0.09035079 | O12: 1.4285714 | P12: 0.49487166 | Q12: 5.1428571 | R12: 0.34992711 | S12: 5.1428571 | T12: 0.34992711 | U12: 0.27619048
A13: naive_bayes | B13: random_undersample | C13: openai | D13: 7 | E13: 0.64465786 | F13: 0.069579815 | G13: 0.234063 | H13: 0.084417574 | I13: 0.61428571 | J13: 0.22946255 | K13: 0.33734888 | L13: 0.12018194 | M13: 0.61428571 | N13: 0.22946255 | O13: 3.1428571 | P13: 1.1248583 | Q13: 5.1428571 | R13: 0.34992711 | S13: 5.1428571 | T13: 0.34992711 | U13: 0.61428571
... A61: naive_bayes | B61: random_undersample | C61: sbert_tfidf_weighted | D61: 7 | E61: 0.64093637 | F61: 0.052326341 | G61: 0.22450416 | H61: 0.079094955 | I61: 0.61428571 | J61: 0.2747912 | K61: 0.32694724 | L61: 0.12324404 | M61: 0.61428571 | N61: 0.2747912 | O61: 3.1428571 | P61: 1.3552619 | Q61: 5.1428571 | R61: 0.34992711 | S61: 5.1428571 | T61: 0.34992711 | U61: 0.61428571

Sheet ongresinc-stackgres_arcade_comb
A1: model | B1: strategy | C1: encoding | D1: cv_folds | E1: accuracy_mean | F1: accuracy_std | G1: precision_mean | H1: precision_std | I1: recall_mean | J1: recall_std | K1: f1_mean | L1: f1_std | M1: positive_smell_recall_mean | N1: positive_smell_recall_std | O1: top_1_positive_count_mean | P1: top_1_positive_count_std | Q1: top_5_positive_count_mean | R1: top_5_positive_count_std | S1: top_10_positive_count_mean | T1: top_10_positive_count_std | U1: recall
A2: logistic_regression | B2: none | C2: openai | D2: 7 | E2: 0.75858951 | F2: 0.023298551 | G2: 0.35605827 | H2: 0.071928186 | I2: 0.28960253 | J2: 0.088988607 | K2: 0.31685972 | L2: 0.079999861 | M2: 0.28960253 | N2: 0.088988607 | O2: 9 | P2: 2.7255406 | Q2: 31.142857 | R2: 0.34992711 | S2: 31.142857 | T2: 0.34992711 | U2: 0.28960253
A3: logistic_regression | B3: class_weight | C3: openai | D3: 7 | E3: 0.73598553 | F3: 0.030581437 | G3: 0.34100009 | H3: 0.069842254 | I3: 0.36779954 | J3: 0.091060297 | K3: 0.35243373 | L3: 0.076800662 | M3: 0.36779954 | N3: 0.091060297 | O3: 11.428571 | P3: 2.7701028 | Q3: 31.142857 | R3: 0.34992711 | S3: 31.142857 | T3: 0.34992711 | U3: 0.36779954
A4: logistic_regression | B4: random_undersample | C4: openai | D4: 7 | E4: 0.60940325 | F4: 0.037476278 | G4: 0.28305708 | H4: 0.022501731 | I4: 0.63335253 | J4: 0.072775824 | K4: 0.38984927 | L4: 0.026217248 | M4: 0.63335253 | N4: 0.072775824 | O4: 19.714286 | P4: 2.1852941 | Q4: 31.142857 | R4: 0.34992711 | S4: 31.142857 | T4: 0.34992711 | U4: 0.63335253
A5: random_forest | B5: none | C5: openai | D5: 7 | E5: 0.80289331 | F5: 0.0022147285 | G5: 0 | H5: 0 | I5: 0 | J5: 0 | K5: 0 | L5: 0 | M5: 0 | N5: 0 | O5: 0 | P5: 0 | Q5: 31.142857 | R5: 0.34992711 | S5: 31.142857 | T5: 0.34992711 | U5: 0
A6: random_forest | B6: class_weight | C6: openai | D6: 7 | E6: 0.79927667 | F6: 0.0055736112 | G6: 0 | H6: 0 | I6: 0 | J6: 0 | K6: 0 | L6: 0 | M6: 0 | N6: 0 | O6: 0 | P6: 0 | Q6: 31.142857 | R6: 0.34992711 | S6: 31.142857 | T6: 0.34992711 | U6: 0
A7: random_forest | B7: random_undersample | C7: openai | D7: 7 | E7: 0.61121157 | F7: 0.039140797 | G7: 0.29708766 | H7: 0.029146187 | I7: 0.70679724 | J7: 0.086930052 | K7: 0.41747188 | L7: 0.039772565 | M7: 0.70679724 | N7: 0.086930052 | O7: 22 | P7: 2.6186147 | Q7: 31.142857 | R7: 0.34992711 | S7: 31.142857 | T7: 0.34992711 | U7: 0.70679724
A8: knn | B8: none | C8: openai | D8: 7 | E8: 0.77938517 | F8: 0.011926678 | G8: 0.34702381 | H8: 0.075910946 | I8: 0.14674539 | J8: 0.059232095 | K8: 0.20324053 | L8: 0.070238729 | M8: 0.14674539 | N8: 0.059232095 | O8: 4.5714286 | P8: 1.8405855 | Q8: 31.142857 | R8: 0.34992711 | S8: 31.142857 | T8: 0.34992711 | U8: 0.14674539
A9: knn | B9: class_weight | C9: openai | D9: 7 | E9: 0.77938517 | F9: 0.011926678 | G9: 0.34702381 | H9: 0.075910946 | I9: 0.14674539 | J9: 0.059232095 | K9: 0.20324053 | L9: 0.070238729 | M9: 0.14674539 | N9: 0.059232095 | O9: 4.5714286 | P9: 1.8405855 | Q9: 31.142857 | R9: 0.34992711 | S9: 31.142857 | T9: 0.34992711 | U9: 0.14674539
A10: knn | B10: random_undersample | C10: openai | D10: 7 | E10: 0.61934901 | F10: 0.049191575 | G10: 0.30863601 | H10: 0.032878519 | I10: 0.73401498 | J10: 0.076233806 | K10: 0.43302043 | L10: 0.037732873 | M10: 0.73401498 | N10: 0.076233806 | O10: 22.857143 | P10: 2.3560604 | Q10: 31.142857 | R10: 0.34992711 | S10: 31.142857 | T10: 0.34992711 | U10: 0.73401498
A11: naive_bayes | B11: none | C11: openai | D11: 7 | E11: 0.62477396 | F11: 0.035757179 | G11: 0.30028063 | H11: 0.036733634 | I11: 0.67957949 | J11: 0.09561583 | K11: 0.41610269 | L11: 0.052103906 | M11: 0.67957949 | N11: 0.09561583 | O11: 21.142857 | P11: 2.849991 | Q11: 31.142857 | R11: 0.34992711 | S11: 31.142857 | T11: 0.34992711 | U11: 0.67957949
A12: naive_bayes | B12: class_weight | C12: openai | D12: 7 | E12: 0.62477396 | F12: 0.035757179 | G12: 0.30028063 | H12: 0.036733634 | I12: 0.67957949 | J12: 0.09561583 | K12: 0.41610269 | L12: 0.052103906 | M12: 0.67957949 | N12: 0.09561583 | O12: 21.142857 | P12: 2.849991 | Q12: 31.142857 | R12: 0.34992711 | S12: 31.142857 | T12: 0.34992711 | U12: 0.67957949
A13: naive_bayes | B13: random_undersample | C13: openai | D13: 7 | E13: 0.60036166 | F13: 0.044552206 | G13: 0.29963932 | H13: 0.035933851 | I13: 0.76166475 | J13: 0.091968349 | K13: 0.42936252 | L13: 0.048689944 | M13: 0.76166475 | N13: 0.091968349 | O13: 23.714286 | P13: 2.8139594 | Q13: 31.142857 | R13: 0.34992711 | S13: 31.142857 | T13: 0.34992711 | U13: 0.76166475
... A61: naive_bayes | B61: random_undersample | C61: sbert_tfidf_weighted | D61: 7 | E61: 0.59222423 | F61: 0.025509468 | G61: 0.28450715 | H61: 0.022234749 | I61: 0.70694124 | J61: 0.080750785 | K61: 0.40526673 | L61: 0.033894543 | M61: 0.70694124 | N61: 0.080750785 | O61: 22 | P61: 2.3904572 | Q61: 31.142857 | R61: 0.34992711 | S61: 31.142857 | T61: 0.34992711 | U61: 0.70694124

Sheet inkscape_acdc_combined_results
A1: model | B1: strategy | C1: encoding | D1: cv_folds | E1: accuracy_mean | F1: accuracy_std | G1: precision_mean | H1: precision_std | I1: recall_mean | J1: recall_std | K1: f1_mean | L1: f1_std | M1: positive_smell_recall_mean | N1: positive_smell_recall_std | O1: top_1_positive_count_mean | P1: top_1_positive_count_std | Q1: top_5_positive_count_mean | R1: top_5_positive_count_std | S1: top_10_positive_count_mean | T1: top_10_positive_count_std | U1: recall
A2: naive_bayes | B2: class_weight | C2: tfidf | D2: 7 | E2: 0.83719328 | F2: 0.011733408 | G2: 0.27271695 | H2: 0.046701535 | I2: 0.36659341 | J2: 0.07403234 | K2: 0.31245286 | L2: 0.056980492 | M2: 0.36659341 | N2: 0.07403234 | O2: 9.4285714 | P2: 1.9166297 | Q2: 25.714286 | R2: 0.45175395 | S2: 25.714286 | T2: 0.45175395 | U2: 0.36659341
A3: naive_bayes | B3: class_weight | C3: openai | D3: 7 | E3: 0.74026196 | F3: 0.024551874 | G3: 0.19360773 | H3: 0.027063337 | I3: 0.48879121 | J3: 0.069883198 | K3: 0.27654642 | L3: 0.036043052 | M3: 0.48879121 | N3: 0.069883198 | O3: 12.571429 | P3: 1.8405855 | Q3: 25.714286 | R3: 0.45175395 | S3: 25.714286 | T3: 0.45175395 | U3: 0.48879121
A4: naive_bayes | B4: none | C4: openai | D4: 7 | E4: 0.75547869 | F4: 0.024798748 | G4: 0.19473817 | H4: 0.032046057 | I4: 0.44461538 | J4: 0.068978784 | K4: 0.26999591 | L4: 0.040873836 | M4: 0.44461538 | N4: 0.068978784 | O4: 11.428571 | P4: 1.7612611 | Q4: 25.714286 | R4: 0.45175395 | S4: 25.714286 | T4: 0.45175395 | U4: 0.44461538
A5: logistic_regression | B5: random_undersample | C5: openai | D5: 7 | E5: 0.63770858 | F5: 0.027936269 | G5: 0.16944022 | H5: 0.017467601 | I5: 0.6556044 | J5: 0.063205062 | K5: 0.26896194 | L5: 0.025744387 | M5: 0.6556044 | N5: 0.063205062 | O5: 16.857143 | P5: 1.6413036 | Q5: 25.714286 | R5: 0.45175395 | S5: 25.714286 | T5: 0.45175395 | U5: 0.6556044
A6: knn | B6: random_undersample | C6: openai | D6: 7 | E6: 0.61290832 | F6: 0.028597785 | G6: 0.16197025 | H6: 0.013793342 | I6: 0.67274725 | J6: 0.065641843 | K6: 0.26071784 | L6: 0.020751748 | M6: 0.67274725 | N6: 0.065641843 | O6: 17.285714 | P6: 1.5779087 | Q6: 25.714286 | R6: 0.45175395 | S6: 25.714286 | T6: 0.45175395 | U6: 0.67274725
A7: logistic_regression | B7: random_undersample | C7: tfidf | D7: 7 | E7: 0.62200723 | F7: 0.042013721 | G7: 0.16280866 | H7: 0.028338088 | I7: 0.65428571 | J7: 0.10979336 | K7: 0.26029664 | L7: 0.0441563 | M7: 0.65428571 | N7: 0.10979336 | O7: 16.857143 | P7: 2.9965967 | Q7: 25.714286 | R7: 0.45175395 | S7: 25.714286 | T7: 0.45175395 | U7: 0.65428571
A8: logistic_regression | B8: class_weight | C8: openai | D8: 7 | E8: 0.74476807 | F8: 0.013674897 | G8: 0.18318204 | H8: 0.019660716 | I8: 0.4389011 | J8: 0.056983718 | K8: 0.25815935 | L8: 0.028362768 | M8: 0.4389011 | N8: 0.056983718 | O8: 11.285714 | P8: 1.484615 | Q8: 25.714286 | R8: 0.45175395 | S8: 25.714286 | T8: 0.45175395 | U8: 0.4389011
A9: naive_bayes | B9: random_undersample | C9: openai | D9: 7 | E9: 0.63208428 | F9: 0.027602258 | G9: 0.1619501 | H9: 0.018477009 | I9: 0.62791209 | J9: 0.078607615 | K9: 0.25712311 | L9: 0.028646846 | M9: 0.62791209 | N9: 0.078607615 | O9: 16.142857 | P9: 2.0303815 | Q9: 25.714286 | R9: 0.45175395 | S9: 25.714286 | T9: 0.45175395 | U9: 0.62791209
A10: random_forest | B10: random_undersample | C10: openai | D10: 7 | E10: 0.62983456 | F10: 0.025588844 | G10: 0.15803347 | H10: 0.012605982 | I10: 0.61098901 | J10: 0.062343246 | K10: 0.25080182 | L10: 0.019334408 | M10: 0.61098901 | N10: 0.062343246 | O10: 15.714286 | P10: 1.6659863 | Q10: 25.714286 | R10: 0.45175395 | S10: 25.714286 | T10: 0.45175395 | U10: 0.61098901
A11: logistic_regression | B11: none | C11: openai | D11: 7 | E11: 0.85352152 | F11: 0.011808623 | G11: 0.25685344 | H11: 0.059527752 | I11: 0.2389011 | J11: 0.072635285 | K11: 0.2459287 | L11: 0.063159555 | M11: 0.2389011 | N11: 0.072635285 | O11: 6.1428571 | P11: 1.8844151 | Q11: 25.714286 | R11: 0.45175395 | S11: 25.714286 | T11: 0.45175395 | U11: 0.2389011
A12: logistic_regression | B12: random_undersample | C12: sbert_tfidf_weighted | D12: 7 | E12: 0.58480684 | F12: 0.024437094 | G12: 0.1485493 | H12: 0.013616867 | I12: 0.65648352 | J12: 0.09518133 | K12: 0.24199528 | L12: 0.023400969 | M12: 0.65648352 | N12: 0.09518133 | O12: 16.857143 | P12: 2.2946255 | Q12: 25.714286 | R12: 0.45175395 | S12: 25.714286 | T12: 0.45175395 | U12: 0.65648352
A13: naive_bayes | B13: none | C13: sbert_avg | D13: 7 | E13: 0.71382999 | F13: 0.026751727 | G13: 0.16517361 | H13: 0.022033488 | I13: 0.44527473 | J13: 0.0531532 | K13: 0.24068593 | L13: 0.030453886 | M13: 0.44527473 | N13: 0.0531532 | O13: 11.428571 | P13: 1.1780302 | Q13: 25.714286 | R13: 0.45175395 | S13: 25.714286 | T13: 0.45175395 | U13: 0.44527473
... A88: random_forest | B88: none | C88: sbert_tfidf_weighted | D88: 7 | E88: 0.8985937 | F88: 0.0016450633 | G88: 0 | H88: 0 | I88: 0 | J88: 0 | K88: 0 | L88: 0 | M88: 0 | N88: 0 | O88: 0 | P88: 0 | Q88: 25.714286 | R88: 0.45175395 | S88: 25.714286 | T88: 0.45175395 | U88: 0

Sheet Average
A1: model | B1: strategy | C1: encoding | D1: cv_folds | E1: accuracy_mean | F1: accuracy_std | G1: precision_mean | H1: precision_std | I1: recall_mean | J1: recall_std | K1: f1_mean | L1: f1_std | M1: positive_smell_recall_mean | N1: positive_smell_recall_std | O1: top_1_positive_count_mean | P1: top_1_positive_count_std | Q1: top_5_positive_count_mean | R1: top_5_positive_count_std | S1: top_10_positive_count_mean | T1: top_10_positive_count_std | U1: recall
A2: feedforward_nn | B2: random_undersample | C2: openai | D2: 7 | E2: =IF( AND(SUMIFS('dlr-shepard-shepard_arcade_comb'!E:E, 'dlr-shepard-shepard_arcade_comb'!$A:$A, $A2, 'dlr-shepard-shepard_arcade_comb'!$B:$B, $B2, 'dlr-shepard-shepard_arcade_comb'!$C:$C, $C2), SUMIFS('ongresinc-stackgres_arcade_comb'!E:E, 'ongresinc-stackgres_arcade_comb'!$A:$A, $A2, 'ongresinc-stackgres_arcade_comb'!$B:$B, $B2, 'ongresinc-stackgres_arcade_comb'!$C:$C, $C2), SUMIFS(inkscape_acdc_combined_results!E:E, inkscape_acdc_combined_results!$A:$A, $A2, inkscape_acdc_combined_results!$B:$B, $B2, inkscape_acdc_combined_results!$C:$C, $C2)), AVERAGE( SUMIFS('dlr-shepard-shepard_arcade_comb'!E:E, 'dlr-shepard-shepard_arcade_comb'!$A:$A, $A2, 'dlr-shepard-shepard_arcade_comb'!$B:$B, $B2, 'dlr-shepard-shepard_arcade_comb'!$C:$C, $C2), SUMIFS('ongresinc-stackgres_arcade_comb'!E:E, 'ongresinc-stackgres_arcade_comb'!$A:$A, $A2, 'ongresinc-stackgres_arcade_comb'!$B:$B, $B2, 'ongresinc-stackgres_arcade_comb'!$C:$C, $C2), SUMIFS(inkscape_acdc_combined_results!E:E, inkscape_acdc_combined_results!$A:$A, $A2, inkscape_acdc_combined_results!$B:$B, $B2, inkscape_acdc_combined_results!$C:$C, $C2) ), "") | F2: =IF( AND(SUMIFS('dlr-shepard-shepard_arcade_comb'!F:F, 'dlr-shepard-shepard_arcade_comb'!$A:$A, $A2, 'dlr-shepard-shepard_arcade_comb'!$B:$B, $B2, 'dlr-shepard-shepard_arcade_comb'!$C:$C, $C2), SUMIFS('ongresinc-stackgres_arcade_comb'!F:F, 'ongresinc-stackgres_arcade_comb'!$A:$A, $A2, 'ongresinc-stackgres_arcade_comb'!$B:$B, $B2, 'ongresinc-stackgres_arcade_comb'!$C:$C, $C2), SUMIFS(inkscape_acdc_combined_results!F:F, inkscape_acdc_combined_results!$A:$A, $A2, inkscape_acdc_combined_results!$B:$B, $B2, inkscape_acdc_combined_results!$C:$C, $C2)), AVERAGE( SUMIFS('dlr-shepard-shepard_arcade_comb'!F:F, 'dlr-shepard-shepard_arcade_comb'!$A:$A, $A2, 'dlr-shepard-shepard_arcade_comb'!$B:$B, $B2, 'dlr-shepard-shepard_arcade_comb'!$C:$C, $C2), SUMIFS('ongresinc-stackgres_arcade_comb'!F:F, 'ongresinc-stackgres_arcade_comb'!$A:$A, $A2, 'ongresinc-stackgres_arcade_comb'!$B:$B, $B2, 'ongresinc-stackgres_arcade_comb'!$C:$C, $C2), SUMIFS(inkscape_acdc_combined_results!F:F, inkscape_acdc_combined_results!$A:$A, $A2, inkscape_acdc_combined_results!$B:$B, $B2, inkscape_acdc_combined_results!$C:$C, $C2) ), "") | G2: =IF( AND(SUMIFS('dlr-shepard-shepard_arcade_comb'!G:G, 'dlr-shepard-shepard_arcade_comb'!$A:$A, $A2, 'dlr-shepard-shepard_arcade_comb'!$B:$B, $B2, 'dlr-shepard-shepard_arcade_comb'!$C:$C, $C2), SUMIFS('ongresinc-stackgres_arcade_comb'!G:G, 'ongresinc-stackgres_arcade_comb'!$A:$A, $A2, 'ongresinc-stackgres_arcade_comb'!$B:$B, $B2, 'ongresinc-stackgres_arcade_comb'!$C:$C, $C2), SUMIFS(inkscape_acdc_combined_results!G:G, inkscape_acdc_combined_results!$A:$A, $A2, inkscape_acdc_combined_results!$B:$B, $B2, inkscape_acdc_combined_results!$C:$C, $C2)), AVERAGE( SUMIFS('dlr-shepard-shepard_arcade_comb'!G:G, 'dlr-shepard-shepard_arcade_comb'!$A:$A, $A2, 'dlr-shepard-shepard_arcade_comb'!$B:$B, $B2, 'dlr-shepard-shepard_arcade_comb'!$C:$C, $C2), SUMIFS('ongresinc-stackgres_arcade_comb'!G:G, 'ongresinc-stackgres_arcade_comb'!$A:$A, $A2, 'ongresinc-stackgres_arcade_comb'!$B:$B, $B2, 'ongresinc-stackgres_arcade_comb'!$C:$C, $C2), SUMIFS(inkscape_acdc_combined_results!G:G, inkscape_acdc_combined_results!$A:$A, $A2, inkscape_acdc_combined_results!$B:$B, $B2, inkscape_acdc_combined_results!$C:$C, $C2) ), "") | H2: =IF( AND(SUMIFS('dlr-shepard-shepard_arcade_comb'!H:H, 'dlr-shepard-shepard_arcade_comb'!$A:$A, $A2, 'dlr-shepard-shepard_arcade_comb'!$B:$B, $B2, 'dlr-shepard-shepard_arcade_comb'!$C:$C, $C2), SUMIFS('ongresinc-stackgres_arcade_comb'!H:H, 'ongresinc-stackgres_arcade_comb'!$A:$A, $A2, 'ongresinc-stackgres_arcade_comb'!$B:$B, $B2, 'ongresinc-stackgres_arcade_comb'!$C:$C, $C2), SUMIFS(inkscape_acdc_combined_results!H:H, inkscape_acdc_combined_results!$A:$A, $A2, inkscape_acdc_combined_results!$B:$B, $B2, inkscape_acdc_combined_results!$C:$C, $C2)), AVERAGE( SUMIFS('dlr-shepard-shepard_arcade_comb'!H:H, 'dlr-shepard-shepard_arcade_comb'!$A:$A, $A2, 'dlr-shepard-shepard_arcade_comb'!$B:$B, $B2, 'dlr-shepard-shepard_arcade_comb'!$C:$C, $C2), SUMIFS('ongresinc-stackgres_arcade_comb'!H:H, 'ongresinc-stackgres_arcade_comb'!$A:$A, $A2, 'ongresinc-stackgres_arcade_comb'!$B:$B, $B2, 'ongresinc-stackgres_arcade_comb'!$C:$C, $C2), SUMIFS(inkscape_acdc_combined_results!H:H, inkscape_acdc_combined_results!$A:$A, $A2, inkscape_acdc_combined_results!$B:$B, $B2, inkscape_acdc_combined_results!$C:$C, $C2) ), "") | I2: =IF( AND(SUMIFS('dlr-shepard-shepard_arcade_comb'!I:I, 'dlr-shepard-shepard_arcade_comb'!$A:$A, $A2, 'dlr-shepard-shepard_arcade_comb'!$B:$B, $B2, 'dlr-shepard-shepard_arcade_comb'!$C:$C, $C2), SUMIFS('ongresinc-stackgres_arcade_comb'!I:I, 'ongresinc-stackgres_arcade_comb'!$A:$A, $A2, 'ongresinc-stackgres_arcade_comb'!$B:$B, $B2, 'ongresinc-stackgres_arcade_comb'!$C:$C, $C2), SUMIFS(inkscape_acdc_combined_results!I:I, inkscape_acdc_combined_results!$A:$A, $A2, inkscape_acdc_combined_results!$B:$B, $B2, inkscape_acdc_combined_results!$C:$C, $C2)), AVERAGE( SUMIFS('dlr-shepard-shepard_arcade_comb'!I:I, 'dlr-shepard-shepard_arcade_comb'!$A:$A, $A2, 'dlr-shepard-shepard_arcade_comb'!$B:$B, $B2, 'dlr-shepard-shepard_arcade_comb'!$C:$C, $C2), SUMIFS('ongresinc-stackgres_arcade_comb'!I:I, 'ongresinc-stackgres_arcade_comb'!$A:$A, $A2, 'ongresinc-stackgres_arcade_comb'!$B:$B, $B2, 'ongresinc-stackgres_arcade_comb'!$C:$C, $C2), SUMIFS(inkscape_acdc_combined_results!I:I, inkscape_acdc_combined_results!$A:$A, $A2, inkscape_acdc_combined_results!$B:$B, $B2, inkscape_acdc_combined_results!$C:$C, $C2) ), "") | J2: =IF( AND(SUMIFS('dlr-shepard-shepard_arcade_comb'!J:J, 'dlr-shepard-shepard_arcade_comb'!$A:$A, $A2, 'dlr-shepard-shepard_arcade_comb'!$B:$B, $B2, 'dlr-shepard-shepard_arcade_comb'!$C:$C, $C2), SUMIFS('ongresinc-stackgres_arcade_comb'!J:J, 'ongresinc-stackgres_arcade_comb'!$A:$A, $A2, 'ongresinc-stackgres_arcade_comb'!$B:$B, $B2, 'ongresinc-stackgres_arcade_comb'!$C:$C, $C2), SUMIFS(inkscape_acdc_combined_results!J:J, inkscape_acdc_combined_results!$A:$A, $A2, inkscape_acdc_combined_results!$B:$B, $B2, inkscape_acdc_combined_results!$C:$C, $C2)), AVERAGE( SUMIFS('dlr-shepard-shepard_arcade_comb'!J:J, 'dlr-shepard-shepard_arcade_comb'!$A:$A, $A2, 'dlr-shepard-shepard_arcade_comb'!$B:$B, $B2, 'dlr-shepard-shepard_arcade_comb'!$C:$C, $C2), SUMIFS('ongresinc-stackgres_arcade_comb'!J:J, 'ongresinc-stackgres_arcade_comb'!$A:$A, $A2, 'ongresinc-stackgres_arcade_comb'!$B:$B, $B2, 'ongresinc-stackgres_arcade_comb'!$C:$C, $C2), SUMIFS(inkscape_acdc_combined_results!J:J, inkscape_acdc_combined_results!$A:$A, $A2, inkscape_acdc_combined_results!$B:$B, $B2, inkscape_acdc_combined_results!$C:$C, $C2) ), "") | K2: =IF( AND(SUMIFS('dlr-shepard-shepard_arcade_comb'!K:K, 'dlr-shepard-shepard_arcade_comb'!$A:$A, $A2, 'dlr-shepard-shepard_arcade_comb'!$B:$B, $B2, 'dlr-shepard-shepard_arcade_comb'!$C:$C, $C2), SUMIFS('ongresinc-stackgres_arcade_comb'!K:K, 'ongresinc-stackgres_arcade_comb'!$A:$A, $A2, 'ongresinc-stackgres_arcade_comb'!$B:$B, $B2, 'ongresinc-stackgres_arcade_comb'!$C:$C, $C2), SUMIFS(inkscape_acdc_combined_results!K:K, inkscape_acdc_combined_results!$A:$A, $A2, inkscape_acdc_combined_results!$B:$B, $B2, inkscape_acdc_combined_results!$C:$C, $C2)), AVERAGE( SUMIFS('dlr-shepard-shepard_arcade_comb'!K:K, 'dlr-shepard-shepard_arcade_comb'!$A:$A, $A2, 'dlr-shepard-shepard_arcade_comb'!$B:$B, $B2, 'dlr-shepard-shepard_arcade_comb'!$C:$C, $C2), SUMIFS('ongresinc-stackgres_arcade_comb'!K:K, 'ongresinc-stackgres_arcade_comb'!$A:$A, $A2, 'ongresinc-stackgres_arcade_comb'!$B:$B, $B2, 'ongresinc-stackgres_arcade_comb'!$C:$C, $C2), SUMIFS(inkscape_acdc_combined_results!K:K, inkscape_acdc_combined_results!$A:$A, $A2, inkscape_acdc_combined_results!$B:$B, $B2, inkscape_acdc_combined_results!$C:$C, $C2) ), "") | L2: =IF( AND(SUMIFS('dlr-shepard-shepard_arcade_comb'!L:L, 'dlr-shepard-shepard_arcade_comb'!$A:$A, $A2, 'dlr-shepard-shepard_arcade_comb'!$B:$B, $B2, 'dlr-shepard-shepard_arcade_comb'!$C:$C, $C2), SUMIFS('ongresinc-stackgres_arcade_comb'!L:L, 'ongresinc-stackgres_arcade_comb'!$A:$A, $A2, 'ongresinc-stackgres_arcade_comb'!$B:$B, $B2, 'ongresinc-stackgres_arcade_comb'!$C:$C, $C2), SUMIFS(inkscape_acdc_combined_results!L:L, inkscape_acdc_combined_results!$A:$A, $A2, inkscape_acdc_combined_results!$B:$B, $B2, inkscape_acdc_combined_results!$C:$C, $C2)), AVERAGE( SUMIFS('dlr-shepard-shepard_arcade_comb'!L:L, 'dlr-shepard-shepard_arcade_comb'!$A:$A, $A2, 'dlr-shepard-shepard_arcade_comb'!$B:$B, $B2, 'dlr-shepard-shepard_arcade_comb'!$C:$C, $C2), SUMIFS('ongresinc-stackgres_arcade_comb'!L:L, 'ongresinc-stackgres_arcade_comb'!$A:$A, $A2, 'ongresinc-stackgres_arcade_comb'!$B:$B, $B2, 'ongresinc-stackgres_arcade_comb'!$C:$C, $C2), SUMIFS(inkscape_acdc_combined_results!L:L, inkscape_acdc_combined_results!$A:$A, $A2, inkscape_acdc_combined_results!$B:$B, $B2, inkscape_acdc_combined_results!$C:$C, $C2) ), "") | M2: =IF( AND(SUMIFS('dlr-shepard-shepard_arcade_comb'!M:M, 'dlr-shepard-shepard_arcade_comb'!$A:$A, $A2, 'dlr-shepard-shepard_arcade_comb'!$B:$B, $B2, 'dlr-shepard-shepard_arcade_comb'!$C:$C, $C2), SUMIFS('ongresinc-stackgres_arcade_comb'!M:M, 'ongresinc-stackgres_arcade_comb'!$A:$A, $A2, 'ongresinc-stackgres_arcade_comb'!$B:$B, $B2, 'ongresinc-stackgres_arcade_comb'!$C:$C, $C2), SUMIFS(inkscape_acdc_combined_results!M:M, inkscape_acdc_combined_results!$A:$A, $A2, inkscape_acdc_combined_results!$B:$B, $B2, inkscape_acdc_combined_results!$C:$C, $C2)), AVERAGE( SUMIFS('dlr-shepard-shepard_arcade_comb'!M:M, 'dlr-shepard-shepard_arcade_comb'!$A:$A, $A2, 'dlr-shepard-shepard_arcade_comb'!$B:$B, $B2, 'dlr-shepard-shepard_arcade_comb'!$C:$C, $C2), SUMIFS('ongresinc-stackgres_arcade_comb'!M:M, 'ongresinc-stackgres_arcade_comb'!$A:$A, $A2, 'ongresinc-stackgres_arcade_comb'!$B:$B, $B2, 'ongresinc-stackgres_arcade_comb'!$C:$C, $C2), SUMIFS(inkscape_acdc_combined_results!M:M, inkscape_acdc_combined_results!$A:$A, $A2, inkscape_acdc_combined_results!$B:$B, $B2, inkscape_acdc_combined_results!$C:$C, $C2) ), "") | N2: =IF( AND(SUMIFS('dlr-shepard-shepard_arcade_comb'!N:N, 'dlr-shepard-shepard_arcade_comb'!$A:$A, $A2, 'dlr-shepard-shepard_arcade_comb'!$B:$B, $B2, 'dlr-shepard-shepard_arcade_comb'!$C:$C, $C2), SUMIFS('ongresinc-stackgres_arcade_comb'!N:N, 'ongresinc-stackgres_arcade_comb'!$A:$A, $A2, 'ongresinc-stackgres_arcade_comb'!$B:$B, $B2, 'ongresinc-stackgres_arcade_comb'!$C:$C, $C2), SUMIFS(inkscape_acdc_combined_results!N:N, inkscape_acdc_combined_results!$A:$A, $A2, inkscape_acdc_combined_results!$B:$B, $B2, inkscape_acdc_combined_results!$C:$C, $C2)), AVERAGE( SUMIFS('dlr-shepard-shepard_arcade_comb'!N:N, 'dlr-shepard-shepard_arcade_comb'!$A:$A, $A2, 'dlr-shepard-shepard_arcade_comb'!$B:$B, $B2, 'dlr-shepard-shepard_arcade_comb'!$C:$C, $C2), SUMIFS('ongresinc-stackgres_arcade_comb'!N:N, 'ongresinc-stackgres_arcade_comb'!$A:$A, $A2, 'ongresinc-stackgres_arcade_comb'!$B:$B, $B2, 'ongresinc-stackgres_arcade_comb'!$C:$C, $C2), SUMIFS(inkscape_acdc_combined_results!N:N, inkscape_acdc_combined_results!$A:$A, $A2, inkscape_acdc_combined_results!$B:$B, $B2, inkscape_acdc_combined_results!$C:$C, $C2) ), "") | O2: =IF( AND(SUMIFS('dlr-shepard-shepard_arcade_comb'!O:O, 'dlr-shepard-shepard_arcade_comb'!$A:$A, $A2, 'dlr-shepard-shepard_arcade_comb'!$B:$B, $B2, 'dlr-shepard-shepard_arcade_comb'!$C:$C, $C2), SUMIFS('ongresinc-stackgres_arcade_comb'!O:O, 'ongresinc-stackgres_arcade_comb'!$A:$A, $A2, 'ongresinc-stackgres_arcade_comb'!$B:$B, $B2, 'ongresinc-stackgres_arcade_comb'!$C:$C, $C2), SUMIFS(inkscape_acdc_combined_results!O:O, inkscape_acdc_combined_results!$A:$A, $A2, inkscape_acdc_combined_results!$B:$B, $B2, inkscape_acdc_combined_results!$C:$C, $C2)), AVERAGE( SUMIFS('dlr-shepard-shepard_arcade_comb'!O:O, 'dlr-shepard-shepard_arcade_comb'!$A:$A, $A2, 'dlr-shepard-shepard_arcade_comb'!$B:$B, $B2, 'dlr-shepard-shepard_arcade_comb'!$C:$C, $C2), SUMIFS('ongresinc-stackgres_arcade_comb'!O:O, 'ongresinc-stackgres_arcade_comb'!$A:$A, $A2, 'ongresinc-stackgres_arcade_comb'!$B:$B, $B2, 'ongresinc-stackgres_arcade_comb'!$C:$C, $C2), SUMIFS(inkscape_acdc_combined_results!O:O, inkscape_acdc_combined_results!$A:$A, $A2, inkscape_acdc_combined_results!$B:$B, $B2, inkscape_acdc_combined_results!$C:$C, $C2) ), "") | P2: =IF( AND(SUMIFS('dlr-shepard-shepard_arcade_comb'!P:P, 'dlr-shepard-shepard_arcade_comb'!$A:$A, $A2, 'dlr-shepard-shepard_arcade_comb'!$B:$B, $B2, 'dlr-shepard-shepard_arcade_comb'!$C:$C, $C2), SUMIFS('ongresinc-stackgres_arcade_comb'!P:P, 'ongresinc-stackgres_arcade_comb'!$A:$A, $A2, 'ongresinc-stackgres_arcade_comb'!$B:$B, $B2, 'ongresinc-stackgres_arcade_comb'!$C:$C, $C2), SUMIFS(inkscape_acdc_combined_results!P:P, inkscape_acdc_combined_results!$A:$A, $A2, inkscape_acdc_combined_results!$B:$B, $B2, inkscape_acdc_combined_results!$C:$C, $C2)), AVERAGE( SUMIFS('dlr-shepard-shepard_arcade_comb'!P:P, 'dlr-shepard-shepard_arcade_comb'!$A:$A, $A2, 'dlr-shepard-shepard_arcade_comb'!$B:$B, $B2, 'dlr-shepard-shepard_arcade_comb'!$C:$C, $C2), SUMIFS('ongresinc-stackgres_arcade_comb'!P:P, 'ongresinc-stackgres_arcade_comb'!$A:$A, $A2, 'ongresinc-stackgres_arcade_comb'!$B:$B, $B2, 'ongresinc-stackgres_arcade_comb'!$C:$C, $C2), SUMIFS(inkscape_acdc_combined_results!P:P, inkscape_acdc_combined_results!$A:$A, $A2, inkscape_acdc_combined_results!$B:$B, $B2, inkscape_acdc_combined_results!$C:$C, $C2) ), "") | Q2: =IF( AND(SUMIFS('dlr-shepard-shepard_arcade_comb'!Q:Q, 'dlr-shepard-shepard_arcade_comb'!$A:$A, $A2, 'dlr-shepard-shepard_arcade_comb'!$B:$B, $B2, 'dlr-shepard-shepard_arcade_comb'!$C:$C, $C2), SUMIFS('ongresinc-stackgres_arcade_comb'!Q:Q, 'ongresinc-stackgres_arcade_comb'!$A:$A, $A2, 'ongresinc-stackgres_arcade_comb'!$B:$B, $B2, 'ongresinc-stackgres_arcade_comb'!$C:$C, $C2), SUMIFS(inkscape_acdc_combined_results!Q:Q, inkscape_acdc_combined_results!$A:$A, $A2, inkscape_acdc_combined_results!$B:$B, $B2, inkscape_acdc_combined_results!$C:$C, $C2)), AVERAGE( SUMIFS('dlr-shepard-shepard_arcade_comb'!Q:Q, 'dlr-shepard-shepard_arcade_comb'!$A:$A, $A2, 'dlr-shepard-shepard_arcade_comb'!$B:$B, $B2, 'dlr-shepard-shepard_arcade_comb'!$C:$C, $C2), SUMIFS('ongresinc-stackgres_arcade_comb'!Q:Q, 'ongresinc-stackgres_arcade_comb'!$A:$A, $A2, 'ongresinc-stackgres_arcade_comb'!$B:$B, $B2, 'ongresinc-stackgres_arcade_comb'!$C:$C, $C2), SUMIFS(inkscape_acdc_combined_results!Q:Q, inkscape_acdc_combined_results!$A:$A, $A2, inkscape_acdc_combined_results!$B:$B, $B2, inkscape_acdc_combined_results!$C:$C, $C2) ), "") | R2: =IF( AND(SUMIFS('dlr-shepard-shepard_arcade_comb'!R:R, 'dlr-shepard-shepard_arcade_comb'!$A:$A, $A2, 'dlr-shepard-shepard_arcade_comb'!$B:$B, $B2, 'dlr-shepard-shepard_arcade_comb'!$C:$C, $C2), SUMIFS('ongresinc-stackgres_arcade_comb'!R:R, 'ongresinc-stackgres_arcade_comb'!$A:$A, $A2, 'ongresinc-stackgres_arcade_comb'!$B:$B, $B2, 'ongresinc-stackgres_arcade_comb'!$C:$C, $C2), SUMIFS(inkscape_acdc_combined_results!R:R, inkscape_acdc_combined_results!$A:$A, $A2, inkscape_acdc_combined_results!$B:$B, $B2, inkscape_acdc_combined_results!$C:$C, $C2)), AVERAGE( SUMIFS('dlr-shepard-shepard_arcade_comb'!R:R, 'dlr-shepard-shepard_arcade_comb'!$A:$A, $A2, 'dlr-shepard-shepard_arcade_comb'!$B:$B, $B2, 'dlr-shepard-shepard_arcade_comb'!$C:$C, $C2), SUMIFS('ongresinc-stackgres_arcade_comb'!R:R, 'ongresinc-stackgres_arcade_comb'!$A:$A, $A2, 'ongresinc-stackgres_arcade_comb'!$B:$B, $B2, 'ongresinc-stackgres_arcade_comb'!$C:$C, $C2), SUMIFS(inkscape_acdc_combined_results!R:R, inkscape_acdc_combined_results!$A:$A, $A2, inkscape_acdc_combined_results!$B:$B, $B2, inkscape_acdc_combined_results!$C:$C, $C2) ), "") | S2: =IF( AND(SUMIFS('dlr-shepard-shepard_arcade_comb'!S:S, 'dlr-shepard-shepard_arcade_comb'!$A:$A, $A2, 'dlr-shepard-shepard_arcade_comb'!$B:$B, $B2, 'dlr-shepard-shepard_arcade_comb'!$C:$C, $C2), SUMIFS('ongresinc-stackgres_arcade_comb'!S:S, 'ongresinc-stackgres_arcade_comb'!$A:$A, $A2, 'ongresinc-stackgres_arcade_comb'!$B:$B, $B2, 'ongresinc-stackgres_arcade_comb'!$C:$C, $C2), SUMIFS(inkscape_acdc_combined_results!S:S, inkscape_acdc_combined_results!$A:$A, $A2, inkscape_acdc_combined_results!$B:$B, $B2, inkscape_acdc_combined_results!$C:$C, $C2)), AVERAGE( SUMIFS('dlr-shepard-shepard_arcade_comb'!S:S, 'dlr-shepard-shepard_arcade_comb'!$A:$A, $A2, 'dlr-shepard-shepard_arcade_comb'!$B:$B, $B2, 'dlr-shepard-shepard_arcade_comb'!$C:$C, $C2), SUMIFS('ongresinc-stackgres_arcade_comb'!S:S, 'ongresinc-stackgres_arcade_comb'!$A:$A, $A2, 'ongresinc-stackgres_arcade_comb'!$B:$B, $B2, 'ongresinc-stackgres_arcade_comb'!$C:$C, $C2), SUMIFS(inkscape_acdc_combined_results!S:S, inkscape_acdc_combined_results!$A:$A, $A2, inkscape_acdc_combined_results!$B:$B, $B2, inkscape_acdc_combined_results!$C:$C, $C2) ), "") | T2: =IF( AND(SUMIFS('dlr-shepard-shepard_arcade_comb'!T:T, 'dlr-shepard-shepard_arcade_comb'!$A:$A, $A2, 'dlr-shepard-shepard_arcade_comb'!$B:$B, $B2, 'dlr-shepard-shepard_arcade_comb'!$C:$C, $C2), SUMIFS('ongresinc-stackgres_arcade_comb'!T:T, 'ongresinc-stackgres_arcade_comb'!$A:$A, $A2, 'ongresinc-stackgres_arcade_comb'!$B:$B, $B2, 'ongresinc-stackgres_arcade_comb'!$C:$C, $C2), SUMIFS(inkscape_acdc_combined_results!T:T, inkscape_acdc_combined_results!$A:$A, $A2, inkscape_acdc_combined_results!$B:$B, $B2, inkscape_acdc_combined_results!$C:$C, $C2)), AVERAGE( SUMIFS('dlr-shepard-shepard_arcade_comb'!T:T, 'dlr-shepard-shepard_arcade_comb'!$A:$A, $A2, 'dlr-shepard-shepard_arcade_comb'!$B:$B, $B2, 'dlr-shepard-shepard_arcade_comb'!$C:$C, $C2), SUMIFS('ongresinc-stackgres_arcade_comb'!T:T, 'ongresinc-stackgres_arcade_comb'!$A:$A, $A2, 'ongresinc-stackgres_arcade_comb'!$B:$B, $B2, 'ongresinc-stackgres_arcade_comb'!$C:$C, $C2), SUMIFS(inkscape_acdc_combined_results!T:T, inkscape_acdc_combined_results!$A:$A, $A2, inkscape_acdc_combined_results!$B:$B, $B2, inkscape_acdc_combined_results!$C:$C, $C2) ), "") | U2: =IF( AND(SUMIFS('dlr-shepard-shepard_arcade_comb'!U:U, 'dlr-shepard-shepard_arcade_comb'!$A:$A, $A2, 'dlr-shepard-shepard_arcade_comb'!$B:$B, $B2, 'dlr-shepard-shepard_arcade_comb'!$C:$C, $C2), SUMIFS('ongresinc-stackgres_arcade_comb'!U:U, 'ongresinc-stackgres_arcade_comb'!$A:$A, $A2, 'ongresinc-stackgres_arcade_comb'!$B:$B, $B2, 'ongresinc-stackgres_arcade_comb'!$C:$C, $C2), SUMIFS(inkscape_acdc_combined_results!U:U, inkscape_acdc_combined_results!$A:$A, $A2, inkscape_acdc_combined_results!$B:$B, $B2, inkscape_acdc_combined_results!$C:$C, $C2)), AVERAGE( SUMIFS('dlr-shepard-shepard_arcade_comb'!U:U, 'dlr-shepard-shepard_arcade_comb'!$A:$A, $A2, 'dlr-shepard-shepard_arcade_comb'!$B:$B, $B2, 'dlr-shepard-shepard_arcade_comb'!$C:$C, $C2), SUMIFS('ongresinc-stackgres_arcade_comb'!U:U, 'ongresinc-stackgres_arcade_comb'!$A:$A, $A2, 'ongresinc-stackgres_arcade_comb'!$B:$B, $B2, 'ongresinc-stackgres_arcade_comb'!$C:$C, $C2), SUMIFS(inkscape_acdc_combined_results!U:U, inkscape_acdc_combined_results!$A:$A, $A2, inkscape_acdc_combined_results!$B:$B, $B2, inkscape_acdc_combined_results!$C:$C, $C2) ), "")
A3: feedforward_nn | B3: random_undersample | C3: sbert_tfidf_weighted | D3: 7 | E3: =IF( AND(SUMIFS('dlr-shepard-shepard_arcade_comb'!E:E, 'dlr-shepard-shepard_arcade_comb'!$A:$A, $A3, 'dlr-shepard-shepard_arcade_comb'!$B:$B, $B3, 'dlr-shepard-shepard_arcade_comb'!$C:$C, $C3), SUMIFS('ongresinc-stackgres_arcade_comb'!E:E, 'ongresinc-stackgres_arcade_comb'!$A:$A, $A3, 'ongresinc-stackgres_arcade_comb'!$B:$B, $B3, 'ongresinc-stackgres_arcade_comb'!$C:$C, $C3), SUMIFS(inkscape_acdc_combined_results!E:E, inkscape_acdc_combined_results!$A:$A, $A3, inkscape_acdc_combined_results!$B:$B, $B3, inkscape_acdc_combined_results!$C:$C, $C3)), AVERAGE( SUMIFS('dlr-shepard-shepard_arcade_comb'!E:E, 'dlr-shepard-shepard_arcade_comb'!$A:$A, $A3, 'dlr-shepard-shepard_arcade_comb'!$B:$B, $B3, 'dlr-shepard-shepard_arcade_comb'!$C:$C, $C3), SUMIFS('ongresinc-stackgres_arcade_comb'!E:E, 'ongresinc-stackgres_arcade_comb'!$A:$A, $A3, 'ongresinc-stackgres_arcade_comb'!$B:$B, $B3, 'ongresinc-stackgres_arcade_comb'!$C:$C, $C3), SUMIFS(inkscape_acdc_combined_results!E:E, inkscape_acdc_combined_results!$A:$A, $A3, inkscape_acdc_combined_results!$B:$B, $B3, inkscape_acdc_combined_results!$C:$C, $C3) ), "") | F3: =IF( AND(SUMIFS('dlr-shepard-shepard_arcade_comb'!F:F, 'dlr-shepard-shepard_arcade_comb'!$A:$A, $A3, 'dlr-shepard-shepard_arcade_comb'!$B:$B, $B3, 'dlr-shepard-shepard_arcade_comb'!$C:$C, $C3), SUMIFS('ongresinc-stackgres_arcade_comb'!F:F, 'ongresinc-stackgres_arcade_comb'!$A:$A, $A3, 'ongresinc-stackgres_arcade_comb'!$B:$B, $B3, 'ongresinc-stackgres_arcade_comb'!$C:$C, $C3), SUMIFS(inkscape_acdc_combined_results!F:F, inkscape_acdc_combined_results!$A:$A, $A3, inkscape_acdc_combined_results!$B:$B, $B3, inkscape_acdc_combined_results!$C:$C, $C3)), AVERAGE( SUMIFS('dlr-shepard-shepard_arcade_comb'!F:F, 'dlr-shepard-shepard_arcade_comb'!$A:$A, $A3, 'dlr-shepard-shepard_arcade_comb'!$B:$B, $B3, 'dlr-shepard-shepard_arcade_comb'!$C:$C, $C3), SUMIFS('ongresinc-stackgres_arcade_comb'!F:F, 'ongresinc-stackgres_arcade_comb'!$A:$A, $A3, 'ongresinc-stackgres_arcade_comb'!$B:$B, $B3, 'ongresinc-stackgres_arcade_comb'!$C:$C, $C3), SUMIFS(inkscape_acdc_combined_results!F:F, inkscape_acdc_combined_results!$A:$A, $A3, inkscape_acdc_combined_results!$B:$B, $B3, inkscape_acdc_combined_results!$C:$C, $C3) ), "") | G3: =IF( AND(SUMIFS('dlr-shepard-shepard_arcade_comb'!G:G, 'dlr-shepard-shepard_arcade_comb'!$A:$A, $A3, 'dlr-shepard-shepard_arcade_comb'!$B:$B, $B3, 'dlr-shepard-shepard_arcade_comb'!$C:$C, $C3), SUMIFS('ongresinc-stackgres_arcade_comb'!G:G, 'ongresinc-stackgres_arcade_comb'!$A:$A, $A3, 'ongresinc-stackgres_arcade_comb'!$B:$B, $B3, 'ongresinc-stackgres_arcade_comb'!$C:$C, $C3), SUMIFS(inkscape_acdc_combined_results!G:G, inkscape_acdc_combined_results!$A:$A, $A3, inkscape_acdc_combined_results!$B:$B, $B3, inkscape_acdc_combined_results!$C:$C, $C3)), AVERAGE( SUMIFS('dlr-shepard-shepard_arcade_comb'!G:G, 'dlr-shepard-shepard_arcade_comb'!$A:$A, $A3, 'dlr-shepard-shepard_arcade_comb'!$B:$B, $B3, 'dlr-shepard-shepard_arcade_comb'!$C:$C, $C3), SUMIFS('ongresinc-stackgres_arcade_comb'!G:G, 'ongresinc-stackgres_arcade_comb'!$A:$A, $A3, 'ongresinc-stackgres_arcade_comb'!$B:$B, $B3, 'ongresinc-stackgres_arcade_comb'!$C:$C, $C3), SUMIFS(inkscape_acdc_combined_results!G:G, inkscape_acdc_combined_results!$A:$A, $A3, inkscape_acdc_combined_results!$B:$B, $B3, inkscape_acdc_combined_results!$C:$C, $C3) ), "") | H3: =IF( AND(SUMIFS('dlr-shepard-shepard_arcade_comb'!H:H, 'dlr-shepard-shepard_arcade_comb'!$A:$A, $A3, 'dlr-shepard-shepard_arcade_comb'!$B:$B, $B3, 'dlr-shepard-shepard_arcade_comb'!$C:$C, $C3), SUMIFS('ongresinc-stackgres_arcade_comb'!H:H, 'ongresinc-stackgres_arcade_comb'!$A:$A, $A3, 'ongresinc-stackgres_arcade_comb'!$B:$B, $B3, 'ongresinc-stackgres_arcade_comb'!$C:$C, $C3), SUMIFS(inkscape_acdc_combined_results!H:H, inkscape_acdc_combined_results!$A:$A, $A3, inkscape_acdc_combined_results!$B:$B, $B3, inkscape_acdc_combined_results!$C:$C, $C3)), AVERAGE( SUMIFS('dlr-shepard-shepard_arcade_comb'!H:H, 'dlr-shepard-shepard_arcade_comb'!$A:$A, $A3, 'dlr-shepard-shepard_arcade_comb'!$B:$B, $B3, 'dlr-shepard-shepard_arcade_comb'!$C:$C, $C3), SUMIFS('ongresinc-stackgres_arcade_comb'!H:H, 'ongresinc-stackgres_arcade_comb'!$A:$A, $A3, 'ongresinc-stackgres_arcade_comb'!$B:$B, $B3, 'ongresinc-stackgres_arcade_comb'!$C:$C, $C3), SUMIFS(inkscape_acdc_combined_results!H:H, inkscape_acdc_combined_results!$A:$A, $A3, inkscape_acdc_combined_results!$B:$B, $B3, inkscape_acdc_combined_results!$C:$C, $C3) ), "") | I3: =IF( AND(SUMIFS('dlr-shepard-shepard_arcade_comb'!I:I, 'dlr-shepard-shepard_arcade_comb'!$A:$A, $A3, 'dlr-shepard-shepard_arcade_comb'!$B:$B, $B3, 'dlr-shepard-shepard_arcade_comb'!$C:$C, $C3), SUMIFS('ongresinc-stackgres_arcade_comb'!I:I, 'ongresinc-stackgres_arcade_comb'!$A:$A, $A3, 'ongresinc-stackgres_arcade_comb'!$B:$B, $B3, 'ongresinc-stackgres_arcade_comb'!$C:$C, $C3), SUMIFS(inkscape_acdc_combined_results!I:I, inkscape_acdc_combined_results!$A:$A, $A3, inkscape_acdc_combined_results!$B:$B, $B3, inkscape_acdc_combined_results!$C:$C, $C3)), AVERAGE( SUMIFS('dlr-shepard-shepard_arcade_comb'!I:I, 'dlr-shepard-shepard_arcade_comb'!$A:$A, $A3, 'dlr-shepard-shepard_arcade_comb'!$B:$B, $B3, 'dlr-shepard-shepard_arcade_comb'!$C:$C, $C3), SUMIFS('ongresinc-stackgres_arcade_comb'!I:I, 'ongresinc-stackgres_arcade_comb'!$A:$A, $A3, 'ongresinc-stackgres_arcade_comb'!$B:$B, $B3, 'ongresinc-stackgres_arcade_comb'!$C:$C, $C3), SUMIFS(inkscape_acdc_combined_results!I:I, inkscape_acdc_combined_results!$A:$A, $A3, inkscape_acdc_combined_results!$B:$B, $B3, inkscape_acdc_combined_results!$C:$C, $C3) ), "") | J3: =IF( AND(SUMIFS('dlr-shepard-shepard_arcade_comb'!J:J, 'dlr-shepard-shepard_arcade_comb'!$A:$A, $A3, 'dlr-shepard-shepard_arcade_comb'!$B:$B, $B3, 'dlr-shepard-shepard_arcade_comb'!$C:$C, $C3), SUMIFS('ongresinc-stackgres_arcade_comb'!J:J, 'ongresinc-stackgres_arcade_comb'!$A:$A, $A3, 'ongresinc-stackgres_arcade_comb'!$B:$B, $B3, 'ongresinc-stackgres_arcade_comb'!$C:$C, $C3), SUMIFS(inkscape_acdc_combined_results!J:J, inkscape_acdc_combined_results!$A:$A, $A3, inkscape_acdc_combined_results!$B:$B, $B3, inkscape_acdc_combined_results!$C:$C, $C3)), AVERAGE( SUMIFS('dlr-shepard-shepard_arcade_comb'!J:J, 'dlr-shepard-shepard_arcade_comb'!$A:$A, $A3, 'dlr-shepard-shepard_arcade_comb'!$B:$B, $B3, 'dlr-shepard-shepard_arcade_comb'!$C:$C, $C3), SUMIFS('ongresinc-stackgres_arcade_comb'!J:J, 'ongresinc-stackgres_arcade_comb'!$A:$A, $A3, 'ongresinc-stackgres_arcade_comb'!$B:$B, $B3, 'ongresinc-stackgres_arcade_comb'!$C:$C, $C3), SUMIFS(inkscape_acdc_combined_results!J:J, inkscape_acdc_combined_results!$A:$A, $A3, inkscape_acdc_combined_results!$B:$B, $B3, inkscape_acdc_combined_results!$C:$C, $C3) ), "") | K3: =IF( AND(SUMIFS('dlr-shepard-shepard_arcade_comb'!K:K, 'dlr-shepard-shepard_arcade_comb'!$A:$A, $A3, 'dlr-shepard-shepard_arcade_comb'!$B:$B, $B3, 'dlr-shepard-shepard_arcade_comb'!$C:$C, $C3), SUMIFS('ongresinc-stackgres_arcade_comb'!K:K, 'ongresinc-stackgres_arcade_comb'!$A:$A, $A3, 'ongresinc-stackgres_arcade_comb'!$B:$B, $B3, 'ongresinc-stackgres_arcade_comb'!$C:$C, $C3), SUMIFS(inkscape_acdc_combined_results!K:K, inkscape_acdc_combined_results!$A:$A, $A3, inkscape_acdc_combined_results!$B:$B, $B3, inkscape_acdc_combined_results!$C:$C, $C3)), AVERAGE( SUMIFS('dlr-shepard-shepard_arcade_comb'!K:K, 'dlr-shepard-shepard_arcade_comb'!$A:$A, $A3, 'dlr-shepard-shepard_arcade_comb'!$B:$B, $B3, 'dlr-shepard-shepard_arcade_comb'!$C:$C, $C3), SUMIFS('ongresinc-stackgres_arcade_comb'!K:K, 'ongresinc-stackgres_arcade_comb'!$A:$A, $A3, 'ongresinc-stackgres_arcade_comb'!$B:$B, $B3, 'ongresinc-stackgres_arcade_comb'!$C:$C, $C3), SUMIFS(inkscape_acdc_combined_results!K:K, inkscape_acdc_combined_results!$A:$A, $A3, inkscape_acdc_combined_results!$B:$B, $B3, inkscape_acdc_combined_results!$C:$C, $C3) ), "") | L3: =IF( AND(SUMIFS('dlr-shepard-shepard_arcade_comb'!L:L, 'dlr-shepard-shepard_arcade_comb'!$A:$A, $A3, 'dlr-shepard-shepard_arcade_comb'!$B:$B, $B3, 'dlr-shepard-shepard_arcade_comb'!$C:$C, $C3), SUMIFS('ongresinc-stackgres_arcade_comb'!L:L, 'ongresinc-stackgres_arcade_comb'!$A:$A, $A3, 'ongresinc-stackgres_arcade_comb'!$B:$B, $B3, 'ongresinc-stackgres_arcade_comb'!$C:$C, $C3), SUMIFS(inkscape_acdc_combined_results!L:L, inkscape_acdc_combined_results!$A:$A, $A3, inkscape_acdc_combined_results!$B:$B, $B3, inkscape_acdc_combined_results!$C:$C, $C3)), AVERAGE( SUMIFS('dlr-shepard-shepard_arcade_comb'!L:L, 'dlr-shepard-shepard_arcade_comb'!$A:$A, $A3, 'dlr-shepard-shepard_arcade_comb'!$B:$B, $B3, 'dlr-shepard-shepard_arcade_comb'!$C:$C, $C3), SUMIFS('ongresinc-stackgres_arcade_comb'!L:L, 'ongresinc-stackgres_arcade_comb'!$A:$A, $A3, 'ongresinc-stackgres_arcade_comb'!$B:$B, $B3, 'ongresinc-stackgres_arcade_comb'!$C:$C, $C3), SUMIFS(inkscape_acdc_combined_results!L:L, inkscape_acdc_combined_results!$A:$A, $A3, inkscape_acdc_combined_results!$B:$B, $B3, inkscape_acdc_combined_results!$C:$C, $C3) ), "") | M3: =IF( AND(SUMIFS('dlr-shepard-shepard_arcade_comb'!M:M, 'dlr-shepard-shepard_arcade_comb'!$A:$A, $A3, 'dlr-shepard-shepard_arcade_comb'!$B:$B, $B3, 'dlr-shepard-shepard_arcade_comb'!$C:$C, $C3), SUMIFS('ongresinc-stackgres_arcade_comb'!M:M, 'ongresinc-stackgres_arcade_comb'!$A:$A, $A3, 'ongresinc-stackgres_arcade_comb'!$B:$B, $B3, 'ongresinc-stackgres_arcade_comb'!$C:$C, $C3), SUMIFS(inkscape_acdc_combined_results!M:M, inkscape_acdc_combined_results!$A:$A, $A3, inkscape_acdc_combined_results!$B:$B, $B3, inkscape_acdc_combined_results!$C:$C, $C3)), AVERAGE( SUMIFS('dlr-shepard-shepard_arcade_comb'!M:M, 'dlr-shepard-shepard_arcade_comb'!$A:$A, $A3, 'dlr-shepard-shepard_arcade_comb'!$B:$B, $B3, 'dlr-shepard-shepard_arcade_comb'!$C:$C, $C3), SUMIFS('ongresinc-stackgres_arcade_comb'!M:M, 'ongresinc-stackgres_arcade_comb'!$A:$A, $A3, 'ongresinc-stackgres_arcade_comb'!$B:$B, $B3, 'ongresinc-stackgres_arcade_comb'!$C:$C, $C3), SUMIFS(inkscape_acdc_combined_results!M:M, inkscape_acdc_combined_results!$A:$A, $A3, inkscape_acdc_combined_results!$B:$B, $B3, inkscape_acdc_combined_results!$C:$C, $C3) ), "") | N3: =IF( AND(SUMIFS('dlr-shepard-shepard_arcade_comb'!N:N, 'dlr-shepard-shepard_arcade_comb'!$A:$A, $A3, 'dlr-shepard-shepard_arcade_comb'!$B:$B, $B3, 'dlr-shepard-shepard_arcade_comb'!$C:$C, $C3), SUMIFS('ongresinc-stackgres_arcade_comb'!N:N, 'ongresinc-stackgres_arcade_comb'!$A:$A, $A3, 'ongresinc-stackgres_arcade_comb'!$B:$B, $B3, 'ongresinc-stackgres_arcade_comb'!$C:$C, $C3), SUMIFS(inkscape_acdc_combined_results!N:N, inkscape_acdc_combined_results!$A:$A, $A3, inkscape_acdc_combined_results!$B:$B, $B3, inkscape_acdc_combined_results!$C:$C, $C3)), AVERAGE( SUMIFS('dlr-shepard-shepard_arcade_comb'!N:N, 'dlr-shepard-shepard_arcade_comb'!$A:$A, $A3, 'dlr-shepard-shepard_arcade_comb'!$B:$B, $B3, 'dlr-shepard-shepard_arcade_comb'!$C:$C, $C3), SUMIFS('ongresinc-stackgres_arcade_comb'!N:N, 'ongresinc-stackgres_arcade_comb'!$A:$A, $A3, 'ongresinc-stackgres_arcade_comb'!$B:$B, $B3, 'ongresinc-stackgres_arcade_comb'!$C:$C, $C3), SUMIFS(inkscape_acdc_combined_results!N:N, inkscape_acdc_combined_results!$A:$A, $A3, inkscape_acdc_combined_results!$B:$B, $B3, inkscape_acdc_combined_results!$C:$C, $C3) ), "") | O3: =IF( AND(SUMIFS('dlr-shepard-shepard_arcade_comb'!O:O, 'dlr-shepard-shepard_arcade_comb'!$A:$A, $A3, 'dlr-shepard-shepard_arcade_comb'!$B:$B, $B3, 'dlr-shepard-shepard_arcade_comb'!$C:$C, $C3), SUMIFS('ongresinc-stackgres_arcade_comb'!O:O, 'ongresinc-stackgres_arcade_comb'!$A:$A, $A3, 'ongresinc-stackgres_arcade_comb'!$B:$B, $B3, 'ongresinc-stackgres_arcade_comb'!$C:$C, $C3), SUMIFS(inkscape_acdc_combined_results!O:O, inkscape_acdc_combined_results!$A:$A, $A3, inkscape_acdc_combined_results!$B:$B, $B3, inkscape_acdc_combined_results!$C:$C, $C3)), AVERAGE( SUMIFS('dlr-shepard-shepard_arcade_comb'!O:O, 'dlr-shepard-shepard_arcade_comb'!$A:$A, $A3, 'dlr-shepard-shepard_arcade_comb'!$B:$B, $B3, 'dlr-shepard-shepard_arcade_comb'!$C:$C, $C3), SUMIFS('ongresinc-stackgres_arcade_comb'!O:O, 'ongresinc-stackgres_arcade_comb'!$A:$A, $A3, 'ongresinc-stackgres_arcade_comb'!$B:$B, $B3, 'ongresinc-stackgres_arcade_comb'!$C:$C, $C3), SUMIFS(inkscape_acdc_combined_results!O:O, inkscape_acdc_combined_results!$A:$A, $A3, inkscape_acdc_combined_results!$B:$B, $B3, inkscape_acdc_combined_results!$C:$C, $C3) ), "") | P3: =IF( AND(SUMIFS('dlr-shepard-shepard_arcade_comb'!P:P, 'dlr-shepard-shepard_arcade_comb'!$A:$A, $A3, 'dlr-shepard-shepard_arcade_comb'!$B:$B, $B3, 'dlr-shepard-shepard_arcade_comb'!$C:$C, $C3), SUMIFS('ongresinc-stackgres_arcade_comb'!P:P, 'ongresinc-stackgres_arcade_comb'!$A:$A, $A3, 'ongresinc-stackgres_arcade_comb'!$B:$B, $B3, 'ongresinc-stackgres_arcade_comb'!$C:$C, $C3), SUMIFS(inkscape_acdc_combined_results!P:P, inkscape_acdc_combined_results!$A:$A, $A3, inkscape_acdc_combined_results!$B:$B, $B3, inkscape_acdc_combined_results!$C:$C, $C3)), AVERAGE( SUMIFS('dlr-shepard-shepard_arcade_comb'!P:P, 'dlr-shepard-shepard_arcade_comb'!$A:$A, $A3, 'dlr-shepard-shepard_arcade_comb'!$B:$B, $B3, 'dlr-shepard-shepard_arcade_comb'!$C:$C, $C3), SUMIFS('ongresinc-stackgres_arcade_comb'!P:P, 'ongresinc-stackgres_arcade_comb'!$A:$A, $A3, 'ongresinc-stackgres_arcade_comb'!$B:$B, $B3, 'ongresinc-stackgres_arcade_comb'!$C:$C, $C3), SUMIFS(inkscape_acdc_combined_results!P:P, inkscape_acdc_combined_results!$A:$A, $A3, inkscape_acdc_combined_results!$B:$B, $B3, inkscape_acdc_combined_results!$C:$C, $C3) ), "") | Q3: =IF( AND(SUMIFS('dlr-shepard-shepard_arcade_comb'!Q:Q, 'dlr-shepard-shepard_arcade_comb'!$A:$A, $A3, 'dlr-shepard-shepard_arcade_comb'!$B:$B, $B3, 'dlr-shepard-shepard_arcade_comb'!$C:$C, $C3), SUMIFS('ongresinc-stackgres_arcade_comb'!Q:Q, 'ongresinc-stackgres_arcade_comb'!$A:$A, $A3, 'ongresinc-stackgres_arcade_comb'!$B:$B, $B3, 'ongresinc-stackgres_arcade_comb'!$C:$C, $C3), SUMIFS(inkscape_acdc_combined_results!Q:Q, inkscape_acdc_combined_results!$A:$A, $A3, inkscape_acdc_combined_results!$B:$B, $B3, inkscape_acdc_combined_results!$C:$C, $C3)), AVERAGE( SUMIFS('dlr-shepard-shepard_arcade_comb'!Q:Q, 'dlr-shepard-shepard_arcade_comb'!$A:$A, $A3, 'dlr-shepard-shepard_arcade_comb'!$B:$B, $B3, 'dlr-shepard-shepard_arcade_comb'!$C:$C, $C3), SUMIFS('ongresinc-stackgres_arcade_comb'!Q:Q, 'ongresinc-stackgres_arcade_comb'!$A:$A, $A3, 'ongresinc-stackgres_arcade_comb'!$B:$B, $B3, 'ongresinc-stackgres_arcade_comb'!$C:$C, $C3), SUMIFS(inkscape_acdc_combined_results!Q:Q, inkscape_acdc_combined_results!$A:$A, $A3, inkscape_acdc_combined_results!$B:$B, $B3, inkscape_acdc_combined_results!$C:$C, $C3) ), "") | R3: =IF( AND(SUMIFS('dlr-shepard-shepard_arcade_comb'!R:R, 'dlr-shepard-shepard_arcade_comb'!$A:$A, $A3, 'dlr-shepard-shepard_arcade_comb'!$B:$B, $B3, 'dlr-shepard-shepard_arcade_comb'!$C:$C, $C3), SUMIFS('ongresinc-stackgres_arcade_comb'!R:R, 'ongresinc-stackgres_arcade_comb'!$A:$A, $A3, 'ongresinc-stackgres_arcade_comb'!$B:$B, $B3, 'ongresinc-stackgres_arcade_comb'!$C:$C, $C3), SUMIFS(inkscape_acdc_combined_results!R:R, inkscape_acdc_combined_results!$A:$A, $A3, inkscape_acdc_combined_results!$B:$B, $B3, inkscape_acdc_combined_results!$C:$C, $C3)), AVERAGE( SUMIFS('dlr-shepard-shepard_arcade_comb'!R:R, 'dlr-shepard-shepard_arcade_comb'!$A:$A, $A3, 'dlr-shepard-shepard_arcade_comb'!$B:$B, $B3, 'dlr-shepard-shepard_arcade_comb'!$C:$C, $C3), SUMIFS('ongresinc-stackgres_arcade_comb'!R:R, 'ongresinc-stackgres_arcade_comb'!$A:$A, $A3, 'ongresinc-stackgres_arcade_comb'!$B:$B, $B3, 'ongresinc-stackgres_arcade_comb'!$C:$C, $C3), SUMIFS(inkscape_acdc_combined_results!R:R, inkscape_acdc_combined_results!$A:$A, $A3, inkscape_acdc_combined_results!$B:$B, $B3, inkscape_acdc_combined_results!$C:$C, $C3) ), "") | S3: =IF( AND(SUMIFS('dlr-shepard-shepard_arcade_comb'!S:S, 'dlr-shepard-shepard_arcade_comb'!$A:$A, $A3, 'dlr-shepard-shepard_arcade_comb'!$B:$B, $B3, 'dlr-shepard-shepard_arcade_comb'!$C:$C, $C3), SUMIFS('ongresinc-stackgres_arcade_comb'!S:S, 'ongresinc-stackgres_arcade_comb'!$A:$A, $A3, 'ongresinc-stackgres_arcade_comb'!$B:$B, $B3, 'ongresinc-stackgres_arcade_comb'!$C:$C, $C3), SUMIFS(inkscape_acdc_combined_results!S:S, inkscape_acdc_combined_results!$A:$A, $A3, inkscape_acdc_combined_results!$B:$B, $B3, inkscape_acdc_combined_results!$C:$C, $C3)), AVERAGE( SUMIFS('dlr-shepard-shepard_arcade_comb'!S:S, 'dlr-shepard-shepard_arcade_comb'!$A:$A, $A3, 'dlr-shepard-shepard_arcade_comb'!$B:$B, $B3, 'dlr-shepard-shepard_arcade_comb'!$C:$C, $C3), SUMIFS('ongresinc-stackgres_arcade_comb'!S:S, 'ongresinc-stackgres_arcade_comb'!$A:$A, $A3, 'ongresinc-stackgres_arcade_comb'!$B:$B, $B3, 'ongresinc-stackgres_arcade_comb'!$C:$C, $C3), SUMIFS(inkscape_acdc_combined_results!S:S, inkscape_acdc_combined_results!$A:$A, $A3, inkscape_acdc_combined_results!$B:$B, $B3, inkscape_acdc_combined_results!$C:$C, $C3) ), "") | T3: =IF( AND(SUMIFS('dlr-shepard-shepard_arcade_comb'!T:T, 'dlr-shepard-shepard_arcade_comb'!$A:$A, $A3, 'dlr-shepard-shepard_arcade_comb'!$B:$B, $B3, 'dlr-shepard-shepard_arcade_comb'!$C:$C, $C3), SUMIFS('ongresinc-stackgres_arcade_comb'!T:T, 'ongresinc-stackgres_arcade_comb'!$A:$A, $A3, 'ongresinc-stackgres_arcade_comb'!$B:$B, $B3, 'ongresinc-stackgres_arcade_comb'!$C:$C, $C3), SUMIFS(inkscape_acdc_combined_results!T:T, inkscape_acdc_combined_results!$A:$A, $A3, inkscape_acdc_combined_results!$B:$B, $B3, inkscape_acdc_combined_results!$C:$C, $C3)), AVERAGE( SUMIFS('dlr-shepard-shepard_arcade_comb'!T:T, 'dlr-shepard-shepard_arcade_comb'!$A:$A, $A3, 'dlr-shepard-shepard_arcade_comb'!$B:$B, $B3, 'dlr-shepard-shepard_arcade_comb'!$C:$C, $C3), SUMIFS('ongresinc-stackgres_arcade_comb'!T:T, 'ongresinc-stackgres_arcade_comb'!$A:$A, $A3, 'ongresinc-stackgres_arcade_comb'!$B:$B, $B3, 'ongresinc-stackgres_arcade_comb'!$C:$C, $C3), SUMIFS(inkscape_acdc_combined_results!T:T, inkscape_acdc_combined_results!$A:$A, $A3, inkscape_acdc_combined_results!$B:$B, $B3, inkscape_acdc_combined_results!$C:$C, $C3) ), "") | U3: =IF( AND(SUMIFS('dlr-shepard-shepard_arcade_comb'!U:U, 'dlr-shepard-shepard_arcade_comb'!$A:$A, $A3, 'dlr-shepard-shepard_arcade_comb'!$B:$B, $B3, 'dlr-shepard-shepard_arcade_comb'!$C:$C, $C3), SUMIFS('ongresinc-stackgres_arcade_comb'!U:U, 'ongresinc-stackgres_arcade_comb'!$A:$A, $A3, 'ongresinc-stackgres_arcade_comb'!$B:$B, $B3, 'ongresinc-stackgres_arcade_comb'!$C:$C, $C3), SUMIFS(inkscape_acdc_combined_results!U:U, inkscape_acdc_combined_results!$A:$A, $A3, inkscape_acdc_combined_results!$B:$B, $B3, inkscape_acdc_combined_results!$C:$C, $C3)), AVERAGE( SUMIFS('dlr-shepard-shepard_arcade_comb'!U:U, 'dlr-shepard-shepard_arcade_comb'!$A:$A, $A3, 'dlr-shepard-shepard_arcade_comb'!$B:$B, $B3, 'dlr-shepard-shepard_arcade_comb'!$C:$C, $C3), SUMIFS('ongresinc-stackgres_arcade_comb'!U:U, 'ongresinc-stackgres_arcade_comb'!$A:$A, $A3, 'ongresinc-stackgres_arcade_comb'!$B:$B, $B3, 'ongresinc-stackgres_arcade_comb'!$C:$C, $C3), SUMIFS(inkscape_acdc_combined_results!U:U, inkscape_acdc_combined_results!$A:$A, $A3, inkscape_acdc_combined_results!$B:$B, $B3, inkscape_acdc_combined_results!$C:$C, $C3) ), "")
