Workbook

Sheet traditional_ml_results_all
A1: project | B1: detector | C1: text_source | D1: encoding_method | E1: imbalance_strategy | F1: ml_model | G1: run_name | H1: accuracy | I1: precision | J1: recall | K1: f1 | L1: cv_accuracy_mean | M1: cv_accuracy_std | N1: cv_f1_mean | O1: cv_f1_std | P1: random_baseline_f1 | Q1: random_baseline_accuracy | R1: random_baseline_cv_f1 | S1: f1_improvement_over_random | T1: wilcoxon_p_value | U1: significant_improvement | V1: num_samples | W1: runtime_seconds | X1: error
A2: inkscape | B2: acdc | C2: combined_unfiltered | D2: openai | E2: random_undersample | F2: feedforward_nn | G2: inkscape_acdc_combined_unfiltered_openai_random_undersample_feedforward_nn | H2: 0.50131234 | I2: 0.15207373 | J2: 0.84615385 | K2: 0.2578125 | L2: 0.72785961 | M2: 0.102952 | N2: 0.2867259 | O2: 0.063818099 | P2: 0.052631579 | Q2: 0.81102362 | R2: 0.091644205 | S2: 0.20518092 | T2: 0.0078125 | U2: True | V2: 2536 | W2: 4.1166813
A3: inkscape | B3: acdc | C3: description | D3: openai | E3: random_undersample | F3: feedforward_nn | G3: inkscape_acdc_description_openai_random_undersample_feedforward_nn | H3: 0.47244094 | I3: 0.13839286 | J3: 0.79487179 | K3: 0.23574144 | L3: 0.60778865 | M3: 0.17865503 | N3: 0.25601524 | O3: 0.040949367 | P3: 0.052631579 | Q3: 0.81102362 | R3: 0.091644205 | S3: 0.18310987 | T3: 0.0078125 | U3: True | V3: 2536 | W3: 3.3519228
A4: inkscape | B4: acdc | C4: combined | D4: openai | E4: random_undersample | F4: feedforward_nn | G4: inkscape_acdc_combined_openai_random_undersample_feedforward_nn | H4: 0.28346457 | I4: 0.11764706 | J4: 0.92307692 | K4: 0.20869565 | L4: 0.57367384 | M4: 0.11748813 | N4: 0.23581898 | O4: 0.041463153 | P4: 0.052631579 | Q4: 0.81102362 | R4: 0.091644205 | S4: 0.15606407 | T4: 0.015625 | U4: True | V4: 2536 | W4: 2.7281318
A5: inkscape | B5: acdc | C5: description | D5: sbert_tfidf_weighted | E5: random_undersample | F5: feedforward_nn | G5: inkscape_acdc_description_sbert_tfidf_weighted_random_undersample_feedforward_nn | H5: 0.76902887 | I5: 0.18987342 | J5: 0.38461538 | K5: 0.25423729 | L5: 0.58922847 | M5: 0.084190325 | N5: 0.22488931 | O5: 0.0397486 | P5: 0.052631579 | Q5: 0.81102362 | R5: 0.091644205 | S5: 0.20160571 | T5: 0.0078125 | U5: True | V5: 2536 | W5: 1.6422977
A6: inkscape | B6: acdc | C6: description | D6: sbert_max | E6: random_undersample | F6: feedforward_nn | G6: inkscape_acdc_description_sbert_max_random_undersample_feedforward_nn | H6: 0.66666667 | I6: 0.16153846 | J6: 0.53846154 | K6: 0.24852071 | L6: 0.57573683 | M6: 0.088357648 | N6: 0.22057277 | O6: 0.041649591 | P6: 0.052631579 | Q6: 0.81102362 | R6: 0.091644205 | S6: 0.19588913 | T6: 0.0078125 | U6: True | V6: 2536 | W6: 1.3406072
A7: inkscape | B7: acdc | C7: combined_unfiltered | D7: sbert_avg | E7: random_undersample | F7: feedforward_nn | G7: inkscape_acdc_combined_unfiltered_sbert_avg_random_undersample_feedforward_nn | H7: 0.68503937 | I7: 0.18110236 | J7: 0.58974359 | K7: 0.27710843 | L7: 0.51256686 | M7: 0.092669106 | N7: 0.21920973 | O7: 0.03026171 | P7: 0.052631579 | Q7: 0.81102362 | R7: 0.091644205 | S7: 0.22447685 | T7: 0.015625 | U7: True | V7: 2536 | W7: 1.0090365
A8: inkscape | B8: acdc | C8: combined_unfiltered | D8: sbert_max | E8: random_undersample | F8: feedforward_nn | G8: inkscape_acdc_combined_unfiltered_sbert_max_random_undersample_feedforward_nn | H8: 0.52493438 | I8: 0.12631579 | J8: 0.61538462 | K8: 0.20960699 | L8: 0.50031123 | M8: 0.089410362 | N8: 0.21786863 | O8: 0.037789358 | P8: 0.052631579 | Q8: 0.81102362 | R8: 0.091644205 | S8: 0.15697541 | T8: 0.015625 | U8: True | V8: 2536 | W8: 1.0545197
A9: inkscape | B9: acdc | C9: description | D9: sbert_avg | E9: random_undersample | F9: feedforward_nn | G9: inkscape_acdc_description_sbert_avg_random_undersample_feedforward_nn | H9: 0.65616798 | I9: 0.16176471 | J9: 0.56410256 | K9: 0.25142857 | L9: 0.61289276 | M9: 0.071897941 | N9: 0.21088078 | O9: 0.038998301 | P9: 0.052631579 | Q9: 0.81102362 | R9: 0.091644205 | S9: 0.19879699 | T9: 0.0078125 | U9: True | V9: 2536 | W9: 1.3859317
A10: inkscape | B10: acdc | C10: combined_unfiltered | D10: sbert_tfidf_weighted | E10: random_undersample | F10: feedforward_nn | G10: inkscape_acdc_combined_unfiltered_sbert_tfidf_weighted_random_undersample_feedforward_nn | H10: 0.71391076 | I10: 0.19298246 | J10: 0.56410256 | K10: 0.2875817 | L10: 0.57743523 | M10: 0.087231923 | N10: 0.20759809 | O10: 0.026298738 | P10: 0.052631579 | Q10: 0.81102362 | R10: 0.091644205 | S10: 0.23495012 | T10: 0.015625 | U10: True | V10: 2536 | W10: 1.9955909
A11: inkscape | B11: acdc | C11: combined | D11: sbert_avg | E11: random_undersample | F11: feedforward_nn | G11: inkscape_acdc_combined_sbert_avg_random_undersample_feedforward_nn | H11: 0.69291339 | I11: 0.1637931 | J11: 0.48717949 | K11: 0.24516129 | L11: 0.59438148 | M11: 0.12690415 | N11: 0.20433718 | O11: 0.04425518 | P11: 0.052631579 | Q11: 0.81102362 | R11: 0.091644205 | S11: 0.19252971 | T11: 0.015625 | U11: True | V11: 2536 | W11: 0.80032134
A12: inkscape | B12: acdc | C12: combined | D12: sbert_tfidf_weighted | E12: random_undersample | F12: feedforward_nn | G12: inkscape_acdc_combined_sbert_tfidf_weighted_random_undersample_feedforward_nn | H12: 0.72703412 | I12: 0.17821782 | J12: 0.46153846 | K12: 0.25714286 | L12: 0.49510041 | M12: 0.14563676 | N12: 0.20242041 | O12: 0.030294026 | P12: 0.052631579 | Q12: 0.81102362 | R12: 0.091644205 | S12: 0.20451128 | T12: 0.015625 | U12: True | V12: 2536 | W12: 1.6625938
A13: inkscape | B13: acdc | C13: combined | D13: sbert_max | E13: random_undersample | F13: feedforward_nn | G13: inkscape_acdc_combined_sbert_max_random_undersample_feedforward_nn | H13: 0.36220472 | I13: 0.12222222 | J13: 0.84615385 | K13: 0.21359223 | L13: 0.60050819 | M13: 0.076257667 | N13: 0.19252135 | O13: 0.054026192 | P13: 0.052631579 | Q13: 0.81102362 | R13: 0.091644205 | S13: 0.16096065 | T13: 0.0234375 | U13: True | V13: 2536 | W13: 1.029604
... A1531: stackgres | B1531: arcan | C1531: combined_unfiltered | D1531: sbert_avg | E1531: none | F1531: xgboost | G1531: stackgres_arcan_combined_unfiltered_sbert_avg_none_xgboost | H1531: 0.71848739 | I1531: 0.67164179 | J1531: 0.5 | K1531: 0.57324841 | L1531: 0.71699819 | M1531: 0.014238712 | N1531: 0.57581277 | O1531: 0.027763165 | P1531: 0.39106145 | Q1531: 0.54201681 | R1531: 0.36839926 | S1531: 0.18218696 | T1531: 0.0078125 | U1531: True | V1531: 1581 | W1531: 69.120102

Sheet average_arcade
A1: detector | B1: text_source | C1: encoding_method | D1: imbalance_strategy | E1: ml_model | F1: accuracy | G1: precision | H1: recall | I1: f1 | J1: cv_accuracy_mean | K1: cv_accuracy_std | L1: cv_f1_mean | M1: cv_f1_std | N1: random_baseline_f1 | O1: random_baseline_accuracy | P1: random_baseline_cv_f1 | Q1: f1_improvement_over_random | R1: wilcoxon_p_value | S1: significant_improvement | T1: num_samples | U1: runtime_seconds
A2: acdc | B2: description | C2: sbert_avg | D2: random_undersample | E2: feedforward_nn | F2: =AVERAGEIFS( traditional_ml_results_all!H:H, traditional_ml_results_all!$B:$B, $A2, traditional_ml_results_all!$C:$C, $B2, traditional_ml_results_all!$D:$D, $C2, traditional_ml_results_all!$E:$E, $D2, traditional_ml_results_all!$F:$F, $E2 ) -> 0.61788232 | G2: =AVERAGEIFS( traditional_ml_results_all!I:I, traditional_ml_results_all!$B:$B, $A2, traditional_ml_results_all!$C:$C, $B2, traditional_ml_results_all!$D:$D, $C2, traditional_ml_results_all!$E:$E, $D2, traditional_ml_results_all!$F:$F, $E2 ) -> 0.23642728 | H2: =AVERAGEIFS( traditional_ml_results_all!J:J, traditional_ml_results_all!$B:$B, $A2, traditional_ml_results_all!$C:$C, $B2, traditional_ml_results_all!$D:$D, $C2, traditional_ml_results_all!$E:$E, $D2, traditional_ml_results_all!$F:$F, $E2 ) -> 0.64991362 | I2: =AVERAGEIFS( traditional_ml_results_all!K:K, traditional_ml_results_all!$B:$B, $A2, traditional_ml_results_all!$C:$C, $B2, traditional_ml_results_all!$D:$D, $C2, traditional_ml_results_all!$E:$E, $D2, traditional_ml_results_all!$F:$F, $E2 ) -> 0.33380952 | J2: =AVERAGEIFS( traditional_ml_results_all!L:L, traditional_ml_results_all!$B:$B, $A2, traditional_ml_results_all!$C:$C, $B2, traditional_ml_results_all!$D:$D, $C2, traditional_ml_results_all!$E:$E, $D2, traditional_ml_results_all!$F:$F, $E2 ) -> 0.53416827 | K2: =AVERAGEIFS( traditional_ml_results_all!M:M, traditional_ml_results_all!$B:$B, $A2, traditional_ml_results_all!$C:$C, $B2, traditional_ml_results_all!$D:$D, $C2, traditional_ml_results_all!$E:$E, $D2, traditional_ml_results_all!$F:$F, $E2 ) -> 0.076899234 | L2: =AVERAGEIFS( traditional_ml_results_all!N:N, traditional_ml_results_all!$B:$B, $A2, traditional_ml_results_all!$C:$C, $B2, traditional_ml_results_all!$D:$D, $C2, traditional_ml_results_all!$E:$E, $D2, traditional_ml_results_all!$F:$F, $E2 ) -> 0.31189695 | M2: =AVERAGEIFS( traditional_ml_results_all!O:O, traditional_ml_results_all!$B:$B, $A2, traditional_ml_results_all!$C:$C, $B2, traditional_ml_results_all!$D:$D, $C2, traditional_ml_results_all!$E:$E, $D2, traditional_ml_results_all!$F:$F, $E2 ) -> 0.052261321 | N2: =AVERAGEIFS( traditional_ml_results_all!P:P, traditional_ml_results_all!$B:$B, $A2, traditional_ml_results_all!$C:$C, $B2, traditional_ml_results_all!$D:$D, $C2, traditional_ml_results_all!$E:$E, $D2, traditional_ml_results_all!$F:$F, $E2 ) -> 0.14169845 | O2: =AVERAGEIFS( traditional_ml_results_all!Q:Q, traditional_ml_results_all!$B:$B, $A2, traditional_ml_results_all!$C:$C, $B2, traditional_ml_results_all!$D:$D, $C2, traditional_ml_results_all!$E:$E, $D2, traditional_ml_results_all!$F:$F, $E2 ) -> 0.75563532 | P2: =AVERAGEIFS( traditional_ml_results_all!R:R, traditional_ml_results_all!$B:$B, $A2, traditional_ml_results_all!$C:$C, $B2, traditional_ml_results_all!$D:$D, $C2, traditional_ml_results_all!$E:$E, $D2, traditional_ml_results_all!$F:$F, $E2 ) -> 0.16584663 | Q2: =AVERAGEIFS( traditional_ml_results_all!S:S, traditional_ml_results_all!$B:$B, $A2, traditional_ml_results_all!$C:$C, $B2, traditional_ml_results_all!$D:$D, $C2, traditional_ml_results_all!$E:$E, $D2, traditional_ml_results_all!$F:$F, $E2 ) -> 0.19211107 | R2: =AVERAGEIFS( traditional_ml_results_all!T:T, traditional_ml_results_all!$B:$B, $A2, traditional_ml_results_all!$C:$C, $B2, traditional_ml_results_all!$D:$D, $C2, traditional_ml_results_all!$E:$E, $D2, traditional_ml_results_all!$F:$F, $E2 ) -> 0.1015625 | S2: =AVERAGEIFS( traditional_ml_results_all!U:U, traditional_ml_results_all!$B:$B, $A2, traditional_ml_results_all!$C:$C, $B2, traditional_ml_results_all!$D:$D, $C2, traditional_ml_results_all!$E:$E, $D2, traditional_ml_results_all!$F:$F, $E2 ) -> #DIV/0! | T2: =AVERAGEIFS( traditional_ml_results_all!V:V, traditional_ml_results_all!$B:$B, $A2, traditional_ml_results_all!$C:$C, $B2, traditional_ml_results_all!$D:$D, $C2, traditional_ml_results_all!$E:$E, $D2, traditional_ml_results_all!$F:$F, $E2 ) -> 1487.6667 | U2: =AVERAGEIFS( traditional_ml_results_all!W:W, traditional_ml_results_all!$B:$B, $A2, traditional_ml_results_all!$C:$C, $B2, traditional_ml_results_all!$D:$D, $C2, traditional_ml_results_all!$E:$E, $D2, traditional_ml_results_all!$F:$F, $E2 ) -> 0.8995084
A3: acdc | B3: description | C3: sbert_tfidf_weighted | D3: random_undersample | E3: feedforward_nn | F3: =AVERAGEIFS( traditional_ml_results_all!H:H, traditional_ml_results_all!$B:$B, $A3, traditional_ml_results_all!$C:$C, $B3, traditional_ml_results_all!$D:$D, $C3, traditional_ml_results_all!$E:$E, $D3, traditional_ml_results_all!$F:$F, $E3 ) -> 0.6527015 | G3: =AVERAGEIFS( traditional_ml_results_all!I:I, traditional_ml_results_all!$B:$B, $A3, traditional_ml_results_all!$C:$C, $B3, traditional_ml_results_all!$D:$D, $C3, traditional_ml_results_all!$E:$E, $D3, traditional_ml_results_all!$F:$F, $E3 ) -> 0.24287447 | H3: =AVERAGEIFS( traditional_ml_results_all!J:J, traditional_ml_results_all!$B:$B, $A3, traditional_ml_results_all!$C:$C, $B3, traditional_ml_results_all!$D:$D, $C3, traditional_ml_results_all!$E:$E, $D3, traditional_ml_results_all!$F:$F, $E3 ) -> 0.59008456 | I3: =AVERAGEIFS( traditional_ml_results_all!K:K, traditional_ml_results_all!$B:$B, $A3, traditional_ml_results_all!$C:$C, $B3, traditional_ml_results_all!$D:$D, $C3, traditional_ml_results_all!$E:$E, $D3, traditional_ml_results_all!$F:$F, $E3 ) -> 0.33255997 | J3: =AVERAGEIFS( traditional_ml_results_all!L:L, traditional_ml_results_all!$B:$B, $A3, traditional_ml_results_all!$C:$C, $B3, traditional_ml_results_all!$D:$D, $C3, traditional_ml_results_all!$E:$E, $D3, traditional_ml_results_all!$F:$F, $E3 ) -> 0.51995106 | K3: =AVERAGEIFS( traditional_ml_results_all!M:M, traditional_ml_results_all!$B:$B, $A3, traditional_ml_results_all!$C:$C, $B3, traditional_ml_results_all!$D:$D, $C3, traditional_ml_results_all!$E:$E, $D3, traditional_ml_results_all!$F:$F, $E3 ) -> 0.0837845 | L3: =AVERAGEIFS( traditional_ml_results_all!N:N, traditional_ml_results_all!$B:$B, $A3, traditional_ml_results_all!$C:$C, $B3, traditional_ml_results_all!$D:$D, $C3, traditional_ml_results_all!$E:$E, $D3, traditional_ml_results_all!$F:$F, $E3 ) -> 0.31336258 | M3: =AVERAGEIFS( traditional_ml_results_all!O:O, traditional_ml_results_all!$B:$B, $A3, traditional_ml_results_all!$C:$C, $B3, traditional_ml_results_all!$D:$D, $C3, traditional_ml_results_all!$E:$E, $D3, traditional_ml_results_all!$F:$F, $E3 ) -> 0.051301705 | N3: =AVERAGEIFS( traditional_ml_results_all!P:P, traditional_ml_results_all!$B:$B, $A3, traditional_ml_results_all!$C:$C, $B3, traditional_ml_results_all!$D:$D, $C3, traditional_ml_results_all!$E:$E, $D3, traditional_ml_results_all!$F:$F, $E3 ) -> 0.14169845 | O3: =AVERAGEIFS( traditional_ml_results_all!Q:Q, traditional_ml_results_all!$B:$B, $A3, traditional_ml_results_all!$C:$C, $B3, traditional_ml_results_all!$D:$D, $C3, traditional_ml_results_all!$E:$E, $D3, traditional_ml_results_all!$F:$F, $E3 ) -> 0.75563532 | P3: =AVERAGEIFS( traditional_ml_results_all!R:R, traditional_ml_results_all!$B:$B, $A3, traditional_ml_results_all!$C:$C, $B3, traditional_ml_results_all!$D:$D, $C3, traditional_ml_results_all!$E:$E, $D3, traditional_ml_results_all!$F:$F, $E3 ) -> 0.16584663 | Q3: =AVERAGEIFS( traditional_ml_results_all!S:S, traditional_ml_results_all!$B:$B, $A3, traditional_ml_results_all!$C:$C, $B3, traditional_ml_results_all!$D:$D, $C3, traditional_ml_results_all!$E:$E, $D3, traditional_ml_results_all!$F:$F, $E3 ) -> 0.19086152 | R3: =AVERAGEIFS( traditional_ml_results_all!T:T, traditional_ml_results_all!$B:$B, $A3, traditional_ml_results_all!$C:$C, $B3, traditional_ml_results_all!$D:$D, $C3, traditional_ml_results_all!$E:$E, $D3, traditional_ml_results_all!$F:$F, $E3 ) -> 0.1015625 | S3: =AVERAGEIFS( traditional_ml_results_all!U:U, traditional_ml_results_all!$B:$B, $A3, traditional_ml_results_all!$C:$C, $B3, traditional_ml_results_all!$D:$D, $C3, traditional_ml_results_all!$E:$E, $D3, traditional_ml_results_all!$F:$F, $E3 ) -> #DIV/0! | T3: =AVERAGEIFS( traditional_ml_results_all!V:V, traditional_ml_results_all!$B:$B, $A3, traditional_ml_results_all!$C:$C, $B3, traditional_ml_results_all!$D:$D, $C3, traditional_ml_results_all!$E:$E, $D3, traditional_ml_results_all!$F:$F, $E3 ) -> 1487.6667 | U3: =AVERAGEIFS( traditional_ml_results_all!W:W, traditional_ml_results_all!$B:$B, $A3, traditional_ml_results_all!$C:$C, $B3, traditional_ml_results_all!$D:$D, $C3, traditional_ml_results_all!$E:$E, $D3, traditional_ml_results_all!$F:$F, $E3 ) -> 1.1516352
A4: acdc | B4: description | C4: sbert_max | D4: random_undersample | E4: feedforward_nn | F4: =AVERAGEIFS( traditional_ml_results_all!H:H, traditional_ml_results_all!$B:$B, $A4, traditional_ml_results_all!$C:$C, $B4, traditional_ml_results_all!$D:$D, $C4, traditional_ml_results_all!$E:$E, $D4, traditional_ml_results_all!$F:$F, $E4 ) -> 0.61718021 | G4: =AVERAGEIFS( traditional_ml_results_all!I:I, traditional_ml_results_all!$B:$B, $A4, traditional_ml_results_all!$C:$C, $B4, traditional_ml_results_all!$D:$D, $C4, traditional_ml_results_all!$E:$E, $D4, traditional_ml_results_all!$F:$F, $E4 ) -> 0.23036642 | H4: =AVERAGEIFS( traditional_ml_results_all!J:J, traditional_ml_results_all!$B:$B, $A4, traditional_ml_results_all!$C:$C, $B4, traditional_ml_results_all!$D:$D, $C4, traditional_ml_results_all!$E:$E, $D4, traditional_ml_results_all!$F:$F, $E4 ) -> 0.63427441 | I4: =AVERAGEIFS( traditional_ml_results_all!K:K, traditional_ml_results_all!$B:$B, $A4, traditional_ml_results_all!$C:$C, $B4, traditional_ml_results_all!$D:$D, $C4, traditional_ml_results_all!$E:$E, $D4, traditional_ml_results_all!$F:$F, $E4 ) -> 0.32622867 | J4: =AVERAGEIFS( traditional_ml_results_all!L:L, traditional_ml_results_all!$B:$B, $A4, traditional_ml_results_all!$C:$C, $B4, traditional_ml_results_all!$D:$D, $C4, traditional_ml_results_all!$E:$E, $D4, traditional_ml_results_all!$F:$F, $E4 ) -> 0.52660514 | K4: =AVERAGEIFS( traditional_ml_results_all!M:M, traditional_ml_results_all!$B:$B, $A4, traditional_ml_results_all!$C:$C, $B4, traditional_ml_results_all!$D:$D, $C4, traditional_ml_results_all!$E:$E, $D4, traditional_ml_results_all!$F:$F, $E4 ) -> 0.086414264 | L4: =AVERAGEIFS( traditional_ml_results_all!N:N, traditional_ml_results_all!$B:$B, $A4, traditional_ml_results_all!$C:$C, $B4, traditional_ml_results_all!$D:$D, $C4, traditional_ml_results_all!$E:$E, $D4, traditional_ml_results_all!$F:$F, $E4 ) -> 0.31151821 | M4: =AVERAGEIFS( traditional_ml_results_all!O:O, traditional_ml_results_all!$B:$B, $A4, traditional_ml_results_all!$C:$C, $B4, traditional_ml_results_all!$D:$D, $C4, traditional_ml_results_all!$E:$E, $D4, traditional_ml_results_all!$F:$F, $E4 ) -> 0.05548754 | N4: =AVERAGEIFS( traditional_ml_results_all!P:P, traditional_ml_results_all!$B:$B, $A4, traditional_ml_results_all!$C:$C, $B4, traditional_ml_results_all!$D:$D, $C4, traditional_ml_results_all!$E:$E, $D4, traditional_ml_results_all!$F:$F, $E4 ) -> 0.14169845 | O4: =AVERAGEIFS( traditional_ml_results_all!Q:Q, traditional_ml_results_all!$B:$B, $A4, traditional_ml_results_all!$C:$C, $B4, traditional_ml_results_all!$D:$D, $C4, traditional_ml_results_all!$E:$E, $D4, traditional_ml_results_all!$F:$F, $E4 ) -> 0.75563532 | P4: =AVERAGEIFS( traditional_ml_results_all!R:R, traditional_ml_results_all!$B:$B, $A4, traditional_ml_results_all!$C:$C, $B4, traditional_ml_results_all!$D:$D, $C4, traditional_ml_results_all!$E:$E, $D4, traditional_ml_results_all!$F:$F, $E4 ) -> 0.16584663 | Q4: =AVERAGEIFS( traditional_ml_results_all!S:S, traditional_ml_results_all!$B:$B, $A4, traditional_ml_results_all!$C:$C, $B4, traditional_ml_results_all!$D:$D, $C4, traditional_ml_results_all!$E:$E, $D4, traditional_ml_results_all!$F:$F, $E4 ) -> 0.18453022 | R4: =AVERAGEIFS( traditional_ml_results_all!T:T, traditional_ml_results_all!$B:$B, $A4, traditional_ml_results_all!$C:$C, $B4, traditional_ml_results_all!$D:$D, $C4, traditional_ml_results_all!$E:$E, $D4, traditional_ml_results_all!$F:$F, $E4 ) -> 0.1015625 | S4: =AVERAGEIFS( traditional_ml_results_all!U:U, traditional_ml_results_all!$B:$B, $A4, traditional_ml_results_all!$C:$C, $B4, traditional_ml_results_all!$D:$D, $C4, traditional_ml_results_all!$E:$E, $D4, traditional_ml_results_all!$F:$F, $E4 ) -> #DIV/0! | T4: =AVERAGEIFS( traditional_ml_results_all!V:V, traditional_ml_results_all!$B:$B, $A4, traditional_ml_results_all!$C:$C, $B4, traditional_ml_results_all!$D:$D, $C4, traditional_ml_results_all!$E:$E, $D4, traditional_ml_results_all!$F:$F, $E4 ) -> 1487.6667 | U4: =AVERAGEIFS( traditional_ml_results_all!W:W, traditional_ml_results_all!$B:$B, $A4, traditional_ml_results_all!$C:$C, $B4, traditional_ml_results_all!$D:$D, $C4, traditional_ml_results_all!$E:$E, $D4, traditional_ml_results_all!$F:$F, $E4 ) -> 0.8571163
A5: acdc | B5: combined_unfiltered | C5: sbert_tfidf_weighted | D5: random_undersample | E5: feedforward_nn | F5: =AVERAGEIFS( traditional_ml_results_all!H:H, traditional_ml_results_all!$B:$B, $A5, traditional_ml_results_all!$C:$C, $B5, traditional_ml_results_all!$D:$D, $C5, traditional_ml_results_all!$E:$E, $D5, traditional_ml_results_all!$F:$F, $E5 ) -> 0.61752207 | G5: =AVERAGEIFS( traditional_ml_results_all!I:I, traditional_ml_results_all!$B:$B, $A5, traditional_ml_results_all!$C:$C, $B5, traditional_ml_results_all!$D:$D, $C5, traditional_ml_results_all!$E:$E, $D5, traditional_ml_results_all!$F:$F, $E5 ) -> 0.22462711 | H5: =AVERAGEIFS( traditional_ml_results_all!J:J, traditional_ml_results_all!$B:$B, $A5, traditional_ml_results_all!$C:$C, $B5, traditional_ml_results_all!$D:$D, $C5, traditional_ml_results_all!$E:$E, $D5, traditional_ml_results_all!$F:$F, $E5 ) -> 0.61533915 | I5: =AVERAGEIFS( traditional_ml_results_all!K:K, traditional_ml_results_all!$B:$B, $A5, traditional_ml_results_all!$C:$C, $B5, traditional_ml_results_all!$D:$D, $C5, traditional_ml_results_all!$E:$E, $D5, traditional_ml_results_all!$F:$F, $E5 ) -> 0.32367274 | J5: =AVERAGEIFS( traditional_ml_results_all!L:L, traditional_ml_results_all!$B:$B, $A5, traditional_ml_results_all!$C:$C, $B5, traditional_ml_results_all!$D:$D, $C5, traditional_ml_results_all!$E:$E, $D5, traditional_ml_results_all!$F:$F, $E5 ) -> 0.53255064 | K5: =AVERAGEIFS( traditional_ml_results_all!M:M, traditional_ml_results_all!$B:$B, $A5, traditional_ml_results_all!$C:$C, $B5, traditional_ml_results_all!$D:$D, $C5, traditional_ml_results_all!$E:$E, $D5, traditional_ml_results_all!$F:$F, $E5 ) -> 0.082628738 | L5: =AVERAGEIFS( traditional_ml_results_all!N:N, traditional_ml_results_all!$B:$B, $A5, traditional_ml_results_all!$C:$C, $B5, traditional_ml_results_all!$D:$D, $C5, traditional_ml_results_all!$E:$E, $D5, traditional_ml_results_all!$F:$F, $E5 ) -> 0.30657737 | M5: =AVERAGEIFS( traditional_ml_results_all!O:O, traditional_ml_results_all!$B:$B, $A5, traditional_ml_results_all!$C:$C, $B5, traditional_ml_results_all!$D:$D, $C5, traditional_ml_results_all!$E:$E, $D5, traditional_ml_results_all!$F:$F, $E5 ) -> 0.05026001 | N5: =AVERAGEIFS( traditional_ml_results_all!P:P, traditional_ml_results_all!$B:$B, $A5, traditional_ml_results_all!$C:$C, $B5, traditional_ml_results_all!$D:$D, $C5, traditional_ml_results_all!$E:$E, $D5, traditional_ml_results_all!$F:$F, $E5 ) -> 0.14169845 | O5: =AVERAGEIFS( traditional_ml_results_all!Q:Q, traditional_ml_results_all!$B:$B, $A5, traditional_ml_results_all!$C:$C, $B5, traditional_ml_results_all!$D:$D, $C5, traditional_ml_results_all!$E:$E, $D5, traditional_ml_results_all!$F:$F, $E5 ) -> 0.75563532 | P5: =AVERAGEIFS( traditional_ml_results_all!R:R, traditional_ml_results_all!$B:$B, $A5, traditional_ml_results_all!$C:$C, $B5, traditional_ml_results_all!$D:$D, $C5, traditional_ml_results_all!$E:$E, $D5, traditional_ml_results_all!$F:$F, $E5 ) -> 0.16584663 | Q5: =AVERAGEIFS( traditional_ml_results_all!S:S, traditional_ml_results_all!$B:$B, $A5, traditional_ml_results_all!$C:$C, $B5, traditional_ml_results_all!$D:$D, $C5, traditional_ml_results_all!$E:$E, $D5, traditional_ml_results_all!$F:$F, $E5 ) -> 0.18197429 | R5: =AVERAGEIFS( traditional_ml_results_all!T:T, traditional_ml_results_all!$B:$B, $A5, traditional_ml_results_all!$C:$C, $B5, traditional_ml_results_all!$D:$D, $C5, traditional_ml_results_all!$E:$E, $D5, traditional_ml_results_all!$F:$F, $E5 ) -> 0.12239583 | S5: =AVERAGEIFS( traditional_ml_results_all!U:U, traditional_ml_results_all!$B:$B, $A5, traditional_ml_results_all!$C:$C, $B5, traditional_ml_results_all!$D:$D, $C5, traditional_ml_results_all!$E:$E, $D5, traditional_ml_results_all!$F:$F, $E5 ) -> #DIV/0! | T5: =AVERAGEIFS( traditional_ml_results_all!V:V, traditional_ml_results_all!$B:$B, $A5, traditional_ml_results_all!$C:$C, $B5, traditional_ml_results_all!$D:$D, $C5, traditional_ml_results_all!$E:$E, $D5, traditional_ml_results_all!$F:$F, $E5 ) -> 1487.6667 | U5: =AVERAGEIFS( traditional_ml_results_all!W:W, traditional_ml_results_all!$B:$B, $A5, traditional_ml_results_all!$C:$C, $B5, traditional_ml_results_all!$D:$D, $C5, traditional_ml_results_all!$E:$E, $D5, traditional_ml_results_all!$F:$F, $E5 ) -> 1.2626662
A6: acdc | B6: combined | C6: sbert_tfidf_weighted | D6: random_undersample | E6: feedforward_nn | F6: =AVERAGEIFS( traditional_ml_results_all!H:H, traditional_ml_results_all!$B:$B, $A6, traditional_ml_results_all!$C:$C, $B6, traditional_ml_results_all!$D:$D, $C6, traditional_ml_results_all!$E:$E, $D6, traditional_ml_results_all!$F:$F, $E6 ) -> 0.62609821 | G6: =AVERAGEIFS( traditional_ml_results_all!I:I, traditional_ml_results_all!$B:$B, $A6, traditional_ml_results_all!$C:$C, $B6, traditional_ml_results_all!$D:$D, $C6, traditional_ml_results_all!$E:$E, $D6, traditional_ml_results_all!$F:$F, $E6 ) -> 0.22607261 | H6: =AVERAGEIFS( traditional_ml_results_all!J:J, traditional_ml_results_all!$B:$B, $A6, traditional_ml_results_all!$C:$C, $B6, traditional_ml_results_all!$D:$D, $C6, traditional_ml_results_all!$E:$E, $D6, traditional_ml_results_all!$F:$F, $E6 ) -> 0.59533552 | I6: =AVERAGEIFS( traditional_ml_results_all!K:K, traditional_ml_results_all!$B:$B, $A6, traditional_ml_results_all!$C:$C, $B6, traditional_ml_results_all!$D:$D, $C6, traditional_ml_results_all!$E:$E, $D6, traditional_ml_results_all!$F:$F, $E6 ) -> 0.3223643 | J6: =AVERAGEIFS( traditional_ml_results_all!L:L, traditional_ml_results_all!$B:$B, $A6, traditional_ml_results_all!$C:$C, $B6, traditional_ml_results_all!$D:$D, $C6, traditional_ml_results_all!$E:$E, $D6, traditional_ml_results_all!$F:$F, $E6 ) -> 0.50329738 | K6: =AVERAGEIFS( traditional_ml_results_all!M:M, traditional_ml_results_all!$B:$B, $A6, traditional_ml_results_all!$C:$C, $B6, traditional_ml_results_all!$D:$D, $C6, traditional_ml_results_all!$E:$E, $D6, traditional_ml_results_all!$F:$F, $E6 ) -> 0.10354303 | L6: =AVERAGEIFS( traditional_ml_results_all!N:N, traditional_ml_results_all!$B:$B, $A6, traditional_ml_results_all!$C:$C, $B6, traditional_ml_results_all!$D:$D, $C6, traditional_ml_results_all!$E:$E, $D6, traditional_ml_results_all!$F:$F, $E6 ) -> 0.30188288 | M6: =AVERAGEIFS( traditional_ml_results_all!O:O, traditional_ml_results_all!$B:$B, $A6, traditional_ml_results_all!$C:$C, $B6, traditional_ml_results_all!$D:$D, $C6, traditional_ml_results_all!$E:$E, $D6, traditional_ml_results_all!$F:$F, $E6 ) -> 0.052640513 | N6: =AVERAGEIFS( traditional_ml_results_all!P:P, traditional_ml_results_all!$B:$B, $A6, traditional_ml_results_all!$C:$C, $B6, traditional_ml_results_all!$D:$D, $C6, traditional_ml_results_all!$E:$E, $D6, traditional_ml_results_all!$F:$F, $E6 ) -> 0.14169845 | O6: =AVERAGEIFS( traditional_ml_results_all!Q:Q, traditional_ml_results_all!$B:$B, $A6, traditional_ml_results_all!$C:$C, $B6, traditional_ml_results_all!$D:$D, $C6, traditional_ml_results_all!$E:$E, $D6, traditional_ml_results_all!$F:$F, $E6 ) -> 0.75563532 | P6: =AVERAGEIFS( traditional_ml_results_all!R:R, traditional_ml_results_all!$B:$B, $A6, traditional_ml_results_all!$C:$C, $B6, traditional_ml_results_all!$D:$D, $C6, traditional_ml_results_all!$E:$E, $D6, traditional_ml_results_all!$F:$F, $E6 ) -> 0.16584663 | Q6: =AVERAGEIFS( traditional_ml_results_all!S:S, traditional_ml_results_all!$B:$B, $A6, traditional_ml_results_all!$C:$C, $B6, traditional_ml_results_all!$D:$D, $C6, traditional_ml_results_all!$E:$E, $D6, traditional_ml_results_all!$F:$F, $E6 ) -> 0.18066586 | R6: =AVERAGEIFS( traditional_ml_results_all!T:T, traditional_ml_results_all!$B:$B, $A6, traditional_ml_results_all!$C:$C, $B6, traditional_ml_results_all!$D:$D, $C6, traditional_ml_results_all!$E:$E, $D6, traditional_ml_results_all!$F:$F, $E6 ) -> 0.12239583 | S6: =AVERAGEIFS( traditional_ml_results_all!U:U, traditional_ml_results_all!$B:$B, $A6, traditional_ml_results_all!$C:$C, $B6, traditional_ml_results_all!$D:$D, $C6, traditional_ml_results_all!$E:$E, $D6, traditional_ml_results_all!$F:$F, $E6 ) -> #DIV/0! | T6: =AVERAGEIFS( traditional_ml_results_all!V:V, traditional_ml_results_all!$B:$B, $A6, traditional_ml_results_all!$C:$C, $B6, traditional_ml_results_all!$D:$D, $C6, traditional_ml_results_all!$E:$E, $D6, traditional_ml_results_all!$F:$F, $E6 ) -> 1487.6667 | U6: =AVERAGEIFS( traditional_ml_results_all!W:W, traditional_ml_results_all!$B:$B, $A6, traditional_ml_results_all!$C:$C, $B6, traditional_ml_results_all!$D:$D, $C6, traditional_ml_results_all!$E:$E, $D6, traditional_ml_results_all!$F:$F, $E6 ) -> 1.0786261
A7: acdc | B7: combined_unfiltered | C7: sbert_avg | D7: random_undersample | E7: feedforward_nn | F7: =AVERAGEIFS( traditional_ml_results_all!H:H, traditional_ml_results_all!$B:$B, $A7, traditional_ml_results_all!$C:$C, $B7, traditional_ml_results_all!$D:$D, $C7, traditional_ml_results_all!$E:$E, $D7, traditional_ml_results_all!$F:$F, $E7 ) -> 0.6367175 | G7: =AVERAGEIFS( traditional_ml_results_all!I:I, traditional_ml_results_all!$B:$B, $A7, traditional_ml_results_all!$C:$C, $B7, traditional_ml_results_all!$D:$D, $C7, traditional_ml_results_all!$E:$E, $D7, traditional_ml_results_all!$F:$F, $E7 ) -> 0.23515308 | H7: =AVERAGEIFS( traditional_ml_results_all!J:J, traditional_ml_results_all!$B:$B, $A7, traditional_ml_results_all!$C:$C, $B7, traditional_ml_results_all!$D:$D, $C7, traditional_ml_results_all!$E:$E, $D7, traditional_ml_results_all!$F:$F, $E7 ) -> 0.58842517 | I7: =AVERAGEIFS( traditional_ml_results_all!K:K, traditional_ml_results_all!$B:$B, $A7, traditional_ml_results_all!$C:$C, $B7, traditional_ml_results_all!$D:$D, $C7, traditional_ml_results_all!$E:$E, $D7, traditional_ml_results_all!$F:$F, $E7 ) -> 0.32168971 | J7: =AVERAGEIFS( traditional_ml_results_all!L:L, traditional_ml_results_all!$B:$B, $A7, traditional_ml_results_all!$C:$C, $B7, traditional_ml_results_all!$D:$D, $C7, traditional_ml_results_all!$E:$E, $D7, traditional_ml_results_all!$F:$F, $E7 ) -> 0.51836475 | K7: =AVERAGEIFS( traditional_ml_results_all!M:M, traditional_ml_results_all!$B:$B, $A7, traditional_ml_results_all!$C:$C, $B7, traditional_ml_results_all!$D:$D, $C7, traditional_ml_results_all!$E:$E, $D7, traditional_ml_results_all!$F:$F, $E7 ) -> 0.090780253 | L7: =AVERAGEIFS( traditional_ml_results_all!N:N, traditional_ml_results_all!$B:$B, $A7, traditional_ml_results_all!$C:$C, $B7, traditional_ml_results_all!$D:$D, $C7, traditional_ml_results_all!$E:$E, $D7, traditional_ml_results_all!$F:$F, $E7 ) -> 0.31607294 | M7: =AVERAGEIFS( traditional_ml_results_all!O:O, traditional_ml_results_all!$B:$B, $A7, traditional_ml_results_all!$C:$C, $B7, traditional_ml_results_all!$D:$D, $C7, traditional_ml_results_all!$E:$E, $D7, traditional_ml_results_all!$F:$F, $E7 ) -> 0.049557039 | N7: =AVERAGEIFS( traditional_ml_results_all!P:P, traditional_ml_results_all!$B:$B, $A7, traditional_ml_results_all!$C:$C, $B7, traditional_ml_results_all!$D:$D, $C7, traditional_ml_results_all!$E:$E, $D7, traditional_ml_results_all!$F:$F, $E7 ) -> 0.14169845 | O7: =AVERAGEIFS( traditional_ml_results_all!Q:Q, traditional_ml_results_all!$B:$B, $A7, traditional_ml_results_all!$C:$C, $B7, traditional_ml_results_all!$D:$D, $C7, traditional_ml_results_all!$E:$E, $D7, traditional_ml_results_all!$F:$F, $E7 ) -> 0.75563532 | P7: =AVERAGEIFS( traditional_ml_results_all!R:R, traditional_ml_results_all!$B:$B, $A7, traditional_ml_results_all!$C:$C, $B7, traditional_ml_results_all!$D:$D, $C7, traditional_ml_results_all!$E:$E, $D7, traditional_ml_results_all!$F:$F, $E7 ) -> 0.16584663 | Q7: =AVERAGEIFS( traditional_ml_results_all!S:S, traditional_ml_results_all!$B:$B, $A7, traditional_ml_results_all!$C:$C, $B7, traditional_ml_results_all!$D:$D, $C7, traditional_ml_results_all!$E:$E, $D7, traditional_ml_results_all!$F:$F, $E7 ) -> 0.17999126 | R7: =AVERAGEIFS( traditional_ml_results_all!T:T, traditional_ml_results_all!$B:$B, $A7, traditional_ml_results_all!$C:$C, $B7, traditional_ml_results_all!$D:$D, $C7, traditional_ml_results_all!$E:$E, $D7, traditional_ml_results_all!$F:$F, $E7 ) -> 0.10416667 | S7: =AVERAGEIFS( traditional_ml_results_all!U:U, traditional_ml_results_all!$B:$B, $A7, traditional_ml_results_all!$C:$C, $B7, traditional_ml_results_all!$D:$D, $C7, traditional_ml_results_all!$E:$E, $D7, traditional_ml_results_all!$F:$F, $E7 ) -> #DIV/0! | T7: =AVERAGEIFS( traditional_ml_results_all!V:V, traditional_ml_results_all!$B:$B, $A7, traditional_ml_results_all!$C:$C, $B7, traditional_ml_results_all!$D:$D, $C7, traditional_ml_results_all!$E:$E, $D7, traditional_ml_results_all!$F:$F, $E7 ) -> 1487.6667 | U7: =AVERAGEIFS( traditional_ml_results_all!W:W, traditional_ml_results_all!$B:$B, $A7, traditional_ml_results_all!$C:$C, $B7, traditional_ml_results_all!$D:$D, $C7, traditional_ml_results_all!$E:$E, $D7, traditional_ml_results_all!$F:$F, $E7 ) -> 0.75477028
A8: acdc | B8: combined | C8: sbert_avg | D8: random_undersample | E8: feedforward_nn | F8: =AVERAGEIFS( traditional_ml_results_all!H:H, traditional_ml_results_all!$B:$B, $A8, traditional_ml_results_all!$C:$C, $B8, traditional_ml_results_all!$D:$D, $C8, traditional_ml_results_all!$E:$E, $D8, traditional_ml_results_all!$F:$F, $E8 ) -> 0.62113489 | G8: =AVERAGEIFS( traditional_ml_results_all!I:I, traditional_ml_results_all!$B:$B, $A8, traditional_ml_results_all!$C:$C, $B8, traditional_ml_results_all!$D:$D, $C8, traditional_ml_results_all!$E:$E, $D8, traditional_ml_results_all!$F:$F, $E8 ) -> 0.22204807 | H8: =AVERAGEIFS( traditional_ml_results_all!J:J, traditional_ml_results_all!$B:$B, $A8, traditional_ml_results_all!$C:$C, $B8, traditional_ml_results_all!$D:$D, $C8, traditional_ml_results_all!$E:$E, $D8, traditional_ml_results_all!$F:$F, $E8 ) -> 0.59679033 | I8: =AVERAGEIFS( traditional_ml_results_all!K:K, traditional_ml_results_all!$B:$B, $A8, traditional_ml_results_all!$C:$C, $B8, traditional_ml_results_all!$D:$D, $C8, traditional_ml_results_all!$E:$E, $D8, traditional_ml_results_all!$F:$F, $E8 ) -> 0.3182236 | J8: =AVERAGEIFS( traditional_ml_results_all!L:L, traditional_ml_results_all!$B:$B, $A8, traditional_ml_results_all!$C:$C, $B8, traditional_ml_results_all!$D:$D, $C8, traditional_ml_results_all!$E:$E, $D8, traditional_ml_results_all!$F:$F, $E8 ) -> 0.54865015 | K8: =AVERAGEIFS( traditional_ml_results_all!M:M, traditional_ml_results_all!$B:$B, $A8, traditional_ml_results_all!$C:$C, $B8, traditional_ml_results_all!$D:$D, $C8, traditional_ml_results_all!$E:$E, $D8, traditional_ml_results_all!$F:$F, $E8 ) -> 0.098849012 | L8: =AVERAGEIFS( traditional_ml_results_all!N:N, traditional_ml_results_all!$B:$B, $A8, traditional_ml_results_all!$C:$C, $B8, traditional_ml_results_all!$D:$D, $C8, traditional_ml_results_all!$E:$E, $D8, traditional_ml_results_all!$F:$F, $E8 ) -> 0.31486376 | M8: =AVERAGEIFS( traditional_ml_results_all!O:O, traditional_ml_results_all!$B:$B, $A8, traditional_ml_results_all!$C:$C, $B8, traditional_ml_results_all!$D:$D, $C8, traditional_ml_results_all!$E:$E, $D8, traditional_ml_results_all!$F:$F, $E8 ) -> 0.058592048 | N8: =AVERAGEIFS( traditional_ml_results_all!P:P, traditional_ml_results_all!$B:$B, $A8, traditional_ml_results_all!$C:$C, $B8, traditional_ml_results_all!$D:$D, $C8, traditional_ml_results_all!$E:$E, $D8, traditional_ml_results_all!$F:$F, $E8 ) -> 0.14169845 | O8: =AVERAGEIFS( traditional_ml_results_all!Q:Q, traditional_ml_results_all!$B:$B, $A8, traditional_ml_results_all!$C:$C, $B8, traditional_ml_results_all!$D:$D, $C8, traditional_ml_results_all!$E:$E, $D8, traditional_ml_results_all!$F:$F, $E8 ) -> 0.75563532 | P8: =AVERAGEIFS( traditional_ml_results_all!R:R, traditional_ml_results_all!$B:$B, $A8, traditional_ml_results_all!$C:$C, $B8, traditional_ml_results_all!$D:$D, $C8, traditional_ml_results_all!$E:$E, $D8, traditional_ml_results_all!$F:$F, $E8 ) -> 0.16584663 | Q8: =AVERAGEIFS( traditional_ml_results_all!S:S, traditional_ml_results_all!$B:$B, $A8, traditional_ml_results_all!$C:$C, $B8, traditional_ml_results_all!$D:$D, $C8, traditional_ml_results_all!$E:$E, $D8, traditional_ml_results_all!$F:$F, $E8 ) -> 0.17652515 | R8: =AVERAGEIFS( traditional_ml_results_all!T:T, traditional_ml_results_all!$B:$B, $A8, traditional_ml_results_all!$C:$C, $B8, traditional_ml_results_all!$D:$D, $C8, traditional_ml_results_all!$E:$E, $D8, traditional_ml_results_all!$F:$F, $E8 ) -> 0.10416667 | S8: =AVERAGEIFS( traditional_ml_results_all!U:U, traditional_ml_results_all!$B:$B, $A8, traditional_ml_results_all!$C:$C, $B8, traditional_ml_results_all!$D:$D, $C8, traditional_ml_results_all!$E:$E, $D8, traditional_ml_results_all!$F:$F, $E8 ) -> #DIV/0! | T8: =AVERAGEIFS( traditional_ml_results_all!V:V, traditional_ml_results_all!$B:$B, $A8, traditional_ml_results_all!$C:$C, $B8, traditional_ml_results_all!$D:$D, $C8, traditional_ml_results_all!$E:$E, $D8, traditional_ml_results_all!$F:$F, $E8 ) -> 1487.6667 | U8: =AVERAGEIFS( traditional_ml_results_all!W:W, traditional_ml_results_all!$B:$B, $A8, traditional_ml_results_all!$C:$C, $B8, traditional_ml_results_all!$D:$D, $C8, traditional_ml_results_all!$E:$E, $D8, traditional_ml_results_all!$F:$F, $E8 ) -> 0.66045745
A9: acdc | B9: combined | C9: sbert_max | D9: random_undersample | E9: feedforward_nn | F9: =AVERAGEIFS( traditional_ml_results_all!H:H, traditional_ml_results_all!$B:$B, $A9, traditional_ml_results_all!$C:$C, $B9, traditional_ml_results_all!$D:$D, $C9, traditional_ml_results_all!$E:$E, $D9, traditional_ml_results_all!$F:$F, $E9 ) -> 0.52431172 | G9: =AVERAGEIFS( traditional_ml_results_all!I:I, traditional_ml_results_all!$B:$B, $A9, traditional_ml_results_all!$C:$C, $B9, traditional_ml_results_all!$D:$D, $C9, traditional_ml_results_all!$E:$E, $D9, traditional_ml_results_all!$F:$F, $E9 ) -> 0.21658698 | H9: =AVERAGEIFS( traditional_ml_results_all!J:J, traditional_ml_results_all!$B:$B, $A9, traditional_ml_results_all!$C:$C, $B9, traditional_ml_results_all!$D:$D, $C9, traditional_ml_results_all!$E:$E, $D9, traditional_ml_results_all!$F:$F, $E9 ) -> 0.71644845 | I9: =AVERAGEIFS( traditional_ml_results_all!K:K, traditional_ml_results_all!$B:$B, $A9, traditional_ml_results_all!$C:$C, $B9, traditional_ml_results_all!$D:$D, $C9, traditional_ml_results_all!$E:$E, $D9, traditional_ml_results_all!$F:$F, $E9 ) -> 0.31564186 | J9: =AVERAGEIFS( traditional_ml_results_all!L:L, traditional_ml_results_all!$B:$B, $A9, traditional_ml_results_all!$C:$C, $B9, traditional_ml_results_all!$D:$D, $C9, traditional_ml_results_all!$E:$E, $D9, traditional_ml_results_all!$F:$F, $E9 ) -> 0.54564024 | K9: =AVERAGEIFS( traditional_ml_results_all!M:M, traditional_ml_results_all!$B:$B, $A9, traditional_ml_results_all!$C:$C, $B9, traditional_ml_results_all!$D:$D, $C9, traditional_ml_results_all!$E:$E, $D9, traditional_ml_results_all!$F:$F, $E9 ) -> 0.072976079 | L9: =AVERAGEIFS( traditional_ml_results_all!N:N, traditional_ml_results_all!$B:$B, $A9, traditional_ml_results_all!$C:$C, $B9, traditional_ml_results_all!$D:$D, $C9, traditional_ml_results_all!$E:$E, $D9, traditional_ml_results_all!$F:$F, $E9 ) -> 0.30055314 | M9: =AVERAGEIFS( traditional_ml_results_all!O:O, traditional_ml_results_all!$B:$B, $A9, traditional_ml_results_all!$C:$C, $B9, traditional_ml_results_all!$D:$D, $C9, traditional_ml_results_all!$E:$E, $D9, traditional_ml_results_all!$F:$F, $E9 ) -> 0.055121052 | N9: =AVERAGEIFS( traditional_ml_results_all!P:P, traditional_ml_results_all!$B:$B, $A9, traditional_ml_results_all!$C:$C, $B9, traditional_ml_results_all!$D:$D, $C9, traditional_ml_results_all!$E:$E, $D9, traditional_ml_results_all!$F:$F, $E9 ) -> 0.14169845 | O9: =AVERAGEIFS( traditional_ml_results_all!Q:Q, traditional_ml_results_all!$B:$B, $A9, traditional_ml_results_all!$C:$C, $B9, traditional_ml_results_all!$D:$D, $C9, traditional_ml_results_all!$E:$E, $D9, traditional_ml_results_all!$F:$F, $E9 ) -> 0.75563532 | P9: =AVERAGEIFS( traditional_ml_results_all!R:R, traditional_ml_results_all!$B:$B, $A9, traditional_ml_results_all!$C:$C, $B9, traditional_ml_results_all!$D:$D, $C9, traditional_ml_results_all!$E:$E, $D9, traditional_ml_results_all!$F:$F, $E9 ) -> 0.16584663 | Q9: =AVERAGEIFS( traditional_ml_results_all!S:S, traditional_ml_results_all!$B:$B, $A9, traditional_ml_results_all!$C:$C, $B9, traditional_ml_results_all!$D:$D, $C9, traditional_ml_results_all!$E:$E, $D9, traditional_ml_results_all!$F:$F, $E9 ) -> 0.17394341 | R9: =AVERAGEIFS( traditional_ml_results_all!T:T, traditional_ml_results_all!$B:$B, $A9, traditional_ml_results_all!$C:$C, $B9, traditional_ml_results_all!$D:$D, $C9, traditional_ml_results_all!$E:$E, $D9, traditional_ml_results_all!$F:$F, $E9 ) -> 0.10677083 | S9: =AVERAGEIFS( traditional_ml_results_all!U:U, traditional_ml_results_all!$B:$B, $A9, traditional_ml_results_all!$C:$C, $B9, traditional_ml_results_all!$D:$D, $C9, traditional_ml_results_all!$E:$E, $D9, traditional_ml_results_all!$F:$F, $E9 ) -> #DIV/0! | T9: =AVERAGEIFS( traditional_ml_results_all!V:V, traditional_ml_results_all!$B:$B, $A9, traditional_ml_results_all!$C:$C, $B9, traditional_ml_results_all!$D:$D, $C9, traditional_ml_results_all!$E:$E, $D9, traditional_ml_results_all!$F:$F, $E9 ) -> 1487.6667 | U9: =AVERAGEIFS( traditional_ml_results_all!W:W, traditional_ml_results_all!$B:$B, $A9, traditional_ml_results_all!$C:$C, $B9, traditional_ml_results_all!$D:$D, $C9, traditional_ml_results_all!$E:$E, $D9, traditional_ml_results_all!$F:$F, $E9 ) -> 0.75113225
A10: acdc | B10: description | C10: openai | D10: random_undersample | E10: feedforward_nn | F10: =AVERAGEIFS( traditional_ml_results_all!H:H, traditional_ml_results_all!$B:$B, $A10, traditional_ml_results_all!$C:$C, $B10, traditional_ml_results_all!$D:$D, $C10, traditional_ml_results_all!$E:$E, $D10, traditional_ml_results_all!$F:$F, $E10 ) -> 0.44545704 | G10: =AVERAGEIFS( traditional_ml_results_all!I:I, traditional_ml_results_all!$B:$B, $A10, traditional_ml_results_all!$C:$C, $B10, traditional_ml_results_all!$D:$D, $C10, traditional_ml_results_all!$E:$E, $D10, traditional_ml_results_all!$F:$F, $E10 ) -> 0.21453012 | H10: =AVERAGEIFS( traditional_ml_results_all!J:J, traditional_ml_results_all!$B:$B, $A10, traditional_ml_results_all!$C:$C, $B10, traditional_ml_results_all!$D:$D, $C10, traditional_ml_results_all!$E:$E, $D10, traditional_ml_results_all!$F:$F, $E10 ) -> 0.78268776 | I10: =AVERAGEIFS( traditional_ml_results_all!K:K, traditional_ml_results_all!$B:$B, $A10, traditional_ml_results_all!$C:$C, $B10, traditional_ml_results_all!$D:$D, $C10, traditional_ml_results_all!$E:$E, $D10, traditional_ml_results_all!$F:$F, $E10 ) -> 0.31072006 | J10: =AVERAGEIFS( traditional_ml_results_all!L:L, traditional_ml_results_all!$B:$B, $A10, traditional_ml_results_all!$C:$C, $B10, traditional_ml_results_all!$D:$D, $C10, traditional_ml_results_all!$E:$E, $D10, traditional_ml_results_all!$F:$F, $E10 ) -> 0.51548137 | K10: =AVERAGEIFS( traditional_ml_results_all!M:M, traditional_ml_results_all!$B:$B, $A10, traditional_ml_results_all!$C:$C, $B10, traditional_ml_results_all!$D:$D, $C10, traditional_ml_results_all!$E:$E, $D10, traditional_ml_results_all!$F:$F, $E10 ) -> 0.1314259 | L10: =AVERAGEIFS( traditional_ml_results_all!N:N, traditional_ml_results_all!$B:$B, $A10, traditional_ml_results_all!$C:$C, $B10, traditional_ml_results_all!$D:$D, $C10, traditional_ml_results_all!$E:$E, $D10, traditional_ml_results_all!$F:$F, $E10 ) -> 0.3225496 | M10: =AVERAGEIFS( traditional_ml_results_all!O:O, traditional_ml_results_all!$B:$B, $A10, traditional_ml_results_all!$C:$C, $B10, traditional_ml_results_all!$D:$D, $C10, traditional_ml_results_all!$E:$E, $D10, traditional_ml_results_all!$F:$F, $E10 ) -> 0.048386248 | N10: =AVERAGEIFS( traditional_ml_results_all!P:P, traditional_ml_results_all!$B:$B, $A10, traditional_ml_results_all!$C:$C, $B10, traditional_ml_results_all!$D:$D, $C10, traditional_ml_results_all!$E:$E, $D10, traditional_ml_results_all!$F:$F, $E10 ) -> 0.14169845 | O10: =AVERAGEIFS( traditional_ml_results_all!Q:Q, traditional_ml_results_all!$B:$B, $A10, traditional_ml_results_all!$C:$C, $B10, traditional_ml_results_all!$D:$D, $C10, traditional_ml_results_all!$E:$E, $D10, traditional_ml_results_all!$F:$F, $E10 ) -> 0.75563532 | P10: =AVERAGEIFS( traditional_ml_results_all!R:R, traditional_ml_results_all!$B:$B, $A10, traditional_ml_results_all!$C:$C, $B10, traditional_ml_results_all!$D:$D, $C10, traditional_ml_results_all!$E:$E, $D10, traditional_ml_results_all!$F:$F, $E10 ) -> 0.16584663 | Q10: =AVERAGEIFS( traditional_ml_results_all!S:S, traditional_ml_results_all!$B:$B, $A10, traditional_ml_results_all!$C:$C, $B10, traditional_ml_results_all!$D:$D, $C10, traditional_ml_results_all!$E:$E, $D10, traditional_ml_results_all!$F:$F, $E10 ) -> 0.16902161 | R10: =AVERAGEIFS( traditional_ml_results_all!T:T, traditional_ml_results_all!$B:$B, $A10, traditional_ml_results_all!$C:$C, $B10, traditional_ml_results_all!$D:$D, $C10, traditional_ml_results_all!$E:$E, $D10, traditional_ml_results_all!$F:$F, $E10 ) -> 0.11979167 | S10: =AVERAGEIFS( traditional_ml_results_all!U:U, traditional_ml_results_all!$B:$B, $A10, traditional_ml_results_all!$C:$C, $B10, traditional_ml_results_all!$D:$D, $C10, traditional_ml_results_all!$E:$E, $D10, traditional_ml_results_all!$F:$F, $E10 ) -> #DIV/0! | T10: =AVERAGEIFS( traditional_ml_results_all!V:V, traditional_ml_results_all!$B:$B, $A10, traditional_ml_results_all!$C:$C, $B10, traditional_ml_results_all!$D:$D, $C10, traditional_ml_results_all!$E:$E, $D10, traditional_ml_results_all!$F:$F, $E10 ) -> 1487.6667 | U10: =AVERAGEIFS( traditional_ml_results_all!W:W, traditional_ml_results_all!$B:$B, $A10, traditional_ml_results_all!$C:$C, $B10, traditional_ml_results_all!$D:$D, $C10, traditional_ml_results_all!$E:$E, $D10, traditional_ml_results_all!$F:$F, $E10 ) -> 2.3502533
A11: acdc | B11: combined | C11: openai | D11: random_undersample | E11: feedforward_nn | F11: =AVERAGEIFS( traditional_ml_results_all!H:H, traditional_ml_results_all!$B:$B, $A11, traditional_ml_results_all!$C:$C, $B11, traditional_ml_results_all!$D:$D, $C11, traditional_ml_results_all!$E:$E, $D11, traditional_ml_results_all!$F:$F, $E11 ) -> 0.35725483 | G11: =AVERAGEIFS( traditional_ml_results_all!I:I, traditional_ml_results_all!$B:$B, $A11, traditional_ml_results_all!$C:$C, $B11, traditional_ml_results_all!$D:$D, $C11, traditional_ml_results_all!$E:$E, $D11, traditional_ml_results_all!$F:$F, $E11 ) -> 0.19655834 | H11: =AVERAGEIFS( traditional_ml_results_all!J:J, traditional_ml_results_all!$B:$B, $A11, traditional_ml_results_all!$C:$C, $B11, traditional_ml_results_all!$D:$D, $C11, traditional_ml_results_all!$E:$E, $D11, traditional_ml_results_all!$F:$F, $E11 ) -> 0.88925259 | I11: =AVERAGEIFS( traditional_ml_results_all!K:K, traditional_ml_results_all!$B:$B, $A11, traditional_ml_results_all!$C:$C, $B11, traditional_ml_results_all!$D:$D, $C11, traditional_ml_results_all!$E:$E, $D11, traditional_ml_results_all!$F:$F, $E11 ) -> 0.30707406 | J11: =AVERAGEIFS( traditional_ml_results_all!L:L, traditional_ml_results_all!$B:$B, $A11, traditional_ml_results_all!$C:$C, $B11, traditional_ml_results_all!$D:$D, $C11, traditional_ml_results_all!$E:$E, $D11, traditional_ml_results_all!$F:$F, $E11 ) -> 0.50529252 | K11: =AVERAGEIFS( traditional_ml_results_all!M:M, traditional_ml_results_all!$B:$B, $A11, traditional_ml_results_all!$C:$C, $B11, traditional_ml_results_all!$D:$D, $C11, traditional_ml_results_all!$E:$E, $D11, traditional_ml_results_all!$F:$F, $E11 ) -> 0.11427054 | L11: =AVERAGEIFS( traditional_ml_results_all!N:N, traditional_ml_results_all!$B:$B, $A11, traditional_ml_results_all!$C:$C, $B11, traditional_ml_results_all!$D:$D, $C11, traditional_ml_results_all!$E:$E, $D11, traditional_ml_results_all!$F:$F, $E11 ) -> 0.31201931 | M11: =AVERAGEIFS( traditional_ml_results_all!O:O, traditional_ml_results_all!$B:$B, $A11, traditional_ml_results_all!$C:$C, $B11, traditional_ml_results_all!$D:$D, $C11, traditional_ml_results_all!$E:$E, $D11, traditional_ml_results_all!$F:$F, $E11 ) -> 0.049819598 | N11: =AVERAGEIFS( traditional_ml_results_all!P:P, traditional_ml_results_all!$B:$B, $A11, traditional_ml_results_all!$C:$C, $B11, traditional_ml_results_all!$D:$D, $C11, traditional_ml_results_all!$E:$E, $D11, traditional_ml_results_all!$F:$F, $E11 ) -> 0.14169845 | O11: =AVERAGEIFS( traditional_ml_results_all!Q:Q, traditional_ml_results_all!$B:$B, $A11, traditional_ml_results_all!$C:$C, $B11, traditional_ml_results_all!$D:$D, $C11, traditional_ml_results_all!$E:$E, $D11, traditional_ml_results_all!$F:$F, $E11 ) -> 0.75563532 | P11: =AVERAGEIFS( traditional_ml_results_all!R:R, traditional_ml_results_all!$B:$B, $A11, traditional_ml_results_all!$C:$C, $B11, traditional_ml_results_all!$D:$D, $C11, traditional_ml_results_all!$E:$E, $D11, traditional_ml_results_all!$F:$F, $E11 ) -> 0.16584663 | Q11: =AVERAGEIFS( traditional_ml_results_all!S:S, traditional_ml_results_all!$B:$B, $A11, traditional_ml_results_all!$C:$C, $B11, traditional_ml_results_all!$D:$D, $C11, traditional_ml_results_all!$E:$E, $D11, traditional_ml_results_all!$F:$F, $E11 ) -> 0.16537561 | R11: =AVERAGEIFS( traditional_ml_results_all!T:T, traditional_ml_results_all!$B:$B, $A11, traditional_ml_results_all!$C:$C, $B11, traditional_ml_results_all!$D:$D, $C11, traditional_ml_results_all!$E:$E, $D11, traditional_ml_results_all!$F:$F, $E11 ) -> 0.10416667 | S11: =AVERAGEIFS( traditional_ml_results_all!U:U, traditional_ml_results_all!$B:$B, $A11, traditional_ml_results_all!$C:$C, $B11, traditional_ml_results_all!$D:$D, $C11, traditional_ml_results_all!$E:$E, $D11, traditional_ml_results_all!$F:$F, $E11 ) -> #DIV/0! | T11: =AVERAGEIFS( traditional_ml_results_all!V:V, traditional_ml_results_all!$B:$B, $A11, traditional_ml_results_all!$C:$C, $B11, traditional_ml_results_all!$D:$D, $C11, traditional_ml_results_all!$E:$E, $D11, traditional_ml_results_all!$F:$F, $E11 ) -> 1487.6667 | U11: =AVERAGEIFS( traditional_ml_results_all!W:W, traditional_ml_results_all!$B:$B, $A11, traditional_ml_results_all!$C:$C, $B11, traditional_ml_results_all!$D:$D, $C11, traditional_ml_results_all!$E:$E, $D11, traditional_ml_results_all!$F:$F, $E11 ) -> 2.0621323
A12: acdc | B12: combined_unfiltered | C12: sbert_max | D12: random_undersample | E12: feedforward_nn | F12: =AVERAGEIFS( traditional_ml_results_all!H:H, traditional_ml_results_all!$B:$B, $A12, traditional_ml_results_all!$C:$C, $B12, traditional_ml_results_all!$D:$D, $C12, traditional_ml_results_all!$E:$E, $D12, traditional_ml_results_all!$F:$F, $E12 ) -> 0.58835886 | G12: =AVERAGEIFS( traditional_ml_results_all!I:I, traditional_ml_results_all!$B:$B, $A12, traditional_ml_results_all!$C:$C, $B12, traditional_ml_results_all!$D:$D, $C12, traditional_ml_results_all!$E:$E, $D12, traditional_ml_results_all!$F:$F, $E12 ) -> 0.2177005 | H12: =AVERAGEIFS( traditional_ml_results_all!J:J, traditional_ml_results_all!$B:$B, $A12, traditional_ml_results_all!$C:$C, $B12, traditional_ml_results_all!$D:$D, $C12, traditional_ml_results_all!$E:$E, $D12, traditional_ml_results_all!$F:$F, $E12 ) -> 0.59697218 | I12: =AVERAGEIFS( traditional_ml_results_all!K:K, traditional_ml_results_all!$B:$B, $A12, traditional_ml_results_all!$C:$C, $B12, traditional_ml_results_all!$D:$D, $C12, traditional_ml_results_all!$E:$E, $D12, traditional_ml_results_all!$F:$F, $E12 ) -> 0.30110023 | J12: =AVERAGEIFS( traditional_ml_results_all!L:L, traditional_ml_results_all!$B:$B, $A12, traditional_ml_results_all!$C:$C, $B12, traditional_ml_results_all!$D:$D, $C12, traditional_ml_results_all!$E:$E, $D12, traditional_ml_results_all!$F:$F, $E12 ) -> 0.51103571 | K12: =AVERAGEIFS( traditional_ml_results_all!M:M, traditional_ml_results_all!$B:$B, $A12, traditional_ml_results_all!$C:$C, $B12, traditional_ml_results_all!$D:$D, $C12, traditional_ml_results_all!$E:$E, $D12, traditional_ml_results_all!$F:$F, $E12 ) -> 0.087473811 | L12: =AVERAGEIFS( traditional_ml_results_all!N:N, traditional_ml_results_all!$B:$B, $A12, traditional_ml_results_all!$C:$C, $B12, traditional_ml_results_all!$D:$D, $C12, traditional_ml_results_all!$E:$E, $D12, traditional_ml_results_all!$F:$F, $E12 ) -> 0.30918721 | M12: =AVERAGEIFS( traditional_ml_results_all!O:O, traditional_ml_results_all!$B:$B, $A12, traditional_ml_results_all!$C:$C, $B12, traditional_ml_results_all!$D:$D, $C12, traditional_ml_results_all!$E:$E, $D12, traditional_ml_results_all!$F:$F, $E12 ) -> 0.049916592 | N12: =AVERAGEIFS( traditional_ml_results_all!P:P, traditional_ml_results_all!$B:$B, $A12, traditional_ml_results_all!$C:$C, $B12, traditional_ml_results_all!$D:$D, $C12, traditional_ml_results_all!$E:$E, $D12, traditional_ml_results_all!$F:$F, $E12 ) -> 0.14169845 | O12: =AVERAGEIFS( traditional_ml_results_all!Q:Q, traditional_ml_results_all!$B:$B, $A12, traditional_ml_results_all!$C:$C, $B12, traditional_ml_results_all!$D:$D, $C12, traditional_ml_results_all!$E:$E, $D12, traditional_ml_results_all!$F:$F, $E12 ) -> 0.75563532 | P12: =AVERAGEIFS( traditional_ml_results_all!R:R, traditional_ml_results_all!$B:$B, $A12, traditional_ml_results_all!$C:$C, $B12, traditional_ml_results_all!$D:$D, $C12, traditional_ml_results_all!$E:$E, $D12, traditional_ml_results_all!$F:$F, $E12 ) -> 0.16584663 | Q12: =AVERAGEIFS( traditional_ml_results_all!S:S, traditional_ml_results_all!$B:$B, $A12, traditional_ml_results_all!$C:$C, $B12, traditional_ml_results_all!$D:$D, $C12, traditional_ml_results_all!$E:$E, $D12, traditional_ml_results_all!$F:$F, $E12 ) -> 0.15940178 | R12: =AVERAGEIFS( traditional_ml_results_all!T:T, traditional_ml_results_all!$B:$B, $A12, traditional_ml_results_all!$C:$C, $B12, traditional_ml_results_all!$D:$D, $C12, traditional_ml_results_all!$E:$E, $D12, traditional_ml_results_all!$F:$F, $E12 ) -> 0.10416667 | S12: =AVERAGEIFS( traditional_ml_results_all!U:U, traditional_ml_results_all!$B:$B, $A12, traditional_ml_results_all!$C:$C, $B12, traditional_ml_results_all!$D:$D, $C12, traditional_ml_results_all!$E:$E, $D12, traditional_ml_results_all!$F:$F, $E12 ) -> #DIV/0! | T12: =AVERAGEIFS( traditional_ml_results_all!V:V, traditional_ml_results_all!$B:$B, $A12, traditional_ml_results_all!$C:$C, $B12, traditional_ml_results_all!$D:$D, $C12, traditional_ml_results_all!$E:$E, $D12, traditional_ml_results_all!$F:$F, $E12 ) -> 1487.6667 | U12: =AVERAGEIFS( traditional_ml_results_all!W:W, traditional_ml_results_all!$B:$B, $A12, traditional_ml_results_all!$C:$C, $B12, traditional_ml_results_all!$D:$D, $C12, traditional_ml_results_all!$E:$E, $D12, traditional_ml_results_all!$F:$F, $E12 ) -> 0.77358619
A13: acdc | B13: combined_unfiltered | C13: openai | D13: random_undersample | E13: feedforward_nn | F13: =AVERAGEIFS( traditional_ml_results_all!H:H, traditional_ml_results_all!$B:$B, $A13, traditional_ml_results_all!$C:$C, $B13, traditional_ml_results_all!$D:$D, $C13, traditional_ml_results_all!$E:$E, $D13, traditional_ml_results_all!$F:$F, $E13 ) -> 0.44527692 | G13: =AVERAGEIFS( traditional_ml_results_all!I:I, traditional_ml_results_all!$B:$B, $A13, traditional_ml_results_all!$C:$C, $B13, traditional_ml_results_all!$D:$D, $C13, traditional_ml_results_all!$E:$E, $D13, traditional_ml_results_all!$F:$F, $E13 ) -> 0.20419552 | H13: =AVERAGEIFS( traditional_ml_results_all!J:J, traditional_ml_results_all!$B:$B, $A13, traditional_ml_results_all!$C:$C, $B13, traditional_ml_results_all!$D:$D, $C13, traditional_ml_results_all!$E:$E, $D13, traditional_ml_results_all!$F:$F, $E13 ) -> 0.77850518 | I13: =AVERAGEIFS( traditional_ml_results_all!K:K, traditional_ml_results_all!$B:$B, $A13, traditional_ml_results_all!$C:$C, $B13, traditional_ml_results_all!$D:$D, $C13, traditional_ml_results_all!$E:$E, $D13, traditional_ml_results_all!$F:$F, $E13 ) -> 0.30050945 | J13: =AVERAGEIFS( traditional_ml_results_all!L:L, traditional_ml_results_all!$B:$B, $A13, traditional_ml_results_all!$C:$C, $B13, traditional_ml_results_all!$D:$D, $C13, traditional_ml_results_all!$E:$E, $D13, traditional_ml_results_all!$F:$F, $E13 ) -> 0.55578362 | K13: =AVERAGEIFS( traditional_ml_results_all!M:M, traditional_ml_results_all!$B:$B, $A13, traditional_ml_results_all!$C:$C, $B13, traditional_ml_results_all!$D:$D, $C13, traditional_ml_results_all!$E:$E, $D13, traditional_ml_results_all!$F:$F, $E13 ) -> 0.10951483 | L13: =AVERAGEIFS( traditional_ml_results_all!N:N, traditional_ml_results_all!$B:$B, $A13, traditional_ml_results_all!$C:$C, $B13, traditional_ml_results_all!$D:$D, $C13, traditional_ml_results_all!$E:$E, $D13, traditional_ml_results_all!$F:$F, $E13 ) -> 0.32905603 | M13: =AVERAGEIFS( traditional_ml_results_all!O:O, traditional_ml_results_all!$B:$B, $A13, traditional_ml_results_all!$C:$C, $B13, traditional_ml_results_all!$D:$D, $C13, traditional_ml_results_all!$E:$E, $D13, traditional_ml_results_all!$F:$F, $E13 ) -> 0.055805123 | N13: =AVERAGEIFS( traditional_ml_results_all!P:P, traditional_ml_results_all!$B:$B, $A13, traditional_ml_results_all!$C:$C, $B13, traditional_ml_results_all!$D:$D, $C13, traditional_ml_results_all!$E:$E, $D13, traditional_ml_results_all!$F:$F, $E13 ) -> 0.14169845 | O13: =AVERAGEIFS( traditional_ml_results_all!Q:Q, traditional_ml_results_all!$B:$B, $A13, traditional_ml_results_all!$C:$C, $B13, traditional_ml_results_all!$D:$D, $C13, traditional_ml_results_all!$E:$E, $D13, traditional_ml_results_all!$F:$F, $E13 ) -> 0.75563532 | P13: =AVERAGEIFS( traditional_ml_results_all!R:R, traditional_ml_results_all!$B:$B, $A13, traditional_ml_results_all!$C:$C, $B13, traditional_ml_results_all!$D:$D, $C13, traditional_ml_results_all!$E:$E, $D13, traditional_ml_results_all!$F:$F, $E13 ) -> 0.16584663 | Q13: =AVERAGEIFS( traditional_ml_results_all!S:S, traditional_ml_results_all!$B:$B, $A13, traditional_ml_results_all!$C:$C, $B13, traditional_ml_results_all!$D:$D, $C13, traditional_ml_results_all!$E:$E, $D13, traditional_ml_results_all!$F:$F, $E13 ) -> 0.158811 | R13: =AVERAGEIFS( traditional_ml_results_all!T:T, traditional_ml_results_all!$B:$B, $A13, traditional_ml_results_all!$C:$C, $B13, traditional_ml_results_all!$D:$D, $C13, traditional_ml_results_all!$E:$E, $D13, traditional_ml_results_all!$F:$F, $E13 ) -> 0.1015625 | S13: =AVERAGEIFS( traditional_ml_results_all!U:U, traditional_ml_results_all!$B:$B, $A13, traditional_ml_results_all!$C:$C, $B13, traditional_ml_results_all!$D:$D, $C13, traditional_ml_results_all!$E:$E, $D13, traditional_ml_results_all!$F:$F, $E13 ) -> #DIV/0! | T13: =AVERAGEIFS( traditional_ml_results_all!V:V, traditional_ml_results_all!$B:$B, $A13, traditional_ml_results_all!$C:$C, $B13, traditional_ml_results_all!$D:$D, $C13, traditional_ml_results_all!$E:$E, $D13, traditional_ml_results_all!$F:$F, $E13 ) -> 1487.6667 | U13: =AVERAGEIFS( traditional_ml_results_all!W:W, traditional_ml_results_all!$B:$B, $A13, traditional_ml_results_all!$C:$C, $B13, traditional_ml_results_all!$D:$D, $C13, traditional_ml_results_all!$E:$E, $D13, traditional_ml_results_all!$F:$F, $E13 ) -> 2.4276818
